Workbook

Sheet รวมงบทรัพย์สินทั้งหมด
A1: งบทรัพย์สินเทศบาลนครลำปาง
A2: หน่วยงาน ส่วนการโยธา สำนักช่าง
A3: ณ วันที่ 30 กันยายน 2567 (e-laas)
A4: ประเภททรัพย์สิน | C4: รหัส | D4: ครุภัณฑ์ | F4: ครุภัณฑ์ต่ำกว่าเกณฑ์ | H4: หมายเหตุ | I4: จำนวนเงิน
D5: จำนวนรายการ | E5: จำนวนเงินที่ได้มา | F5: จำนวนรายการ | G5: จำนวนเงินที่ได้มา
A6: ก | B6: อสังหาริมทรัพย์
A7: 1 | B7: ที่ดิน | C7: . 001 | D7: 1 | E7: ='16.ที่ดินและสิ่งก่อสร้าง'!G8 -> 5337885 | F7: - | G7: -
A8: 2 | B8: อาคารและโรงเรือน
B9: 2.1 อาคารสำนักงาน | C9: 005 | D9: 6 | E9: ='16.ที่ดินและสิ่งก่อสร้าง'!G17 -> 5838015.4
B10: 2.2 อาคารเครื่องชั่ง | C10: 021 | D10: =[1]ที่ดินและสิ่งก่อสร้าง!A22 -> 6 | E10: ='16.ที่ดินและสิ่งก่อสร้าง'!G25 -> 12456000
B11: 2.3 อาคารบ้านพัก | C11: 090 | D11: =[1]ที่ดินและสิ่งก่อสร้าง!A27 -> 1 | E11: ='16.ที่ดินและสิ่งก่อสร้าง'!G31 -> 2767434.8
A12: 3 | B12: สิ่งก่อสร้างอื่น
B13: 3.1 สิ่งปลูกสร้าง
B14: 3.1.1 ลานกีฬา | C14: 014 | D14: 1 | E14: ='16.ที่ดินและสิ่งก่อสร้าง'!G35 -> 6817490.8
B15: 3.1.2 อาคารเพื่อประโยชน์อื่น | C15: 072 | D15: 7 | E15: ='16.ที่ดินและสิ่งก่อสร้าง'!G44 -> 2450103.5
B16: 3.1.3 อาคารห้องน้ำ - ส้วม | C16: 187 | D16: 3 | E16: ='16.ที่ดินและสิ่งก่อสร้าง'!G50 -> 2490808.5
B17: 3.14 อื่นๆ
B18: 3.14.1 เสาธง | C18: 183 | D18: 1 | E18: ='16.ที่ดินและสิ่งก่อสร้าง'!G53 -> 20000
B19: 3.14.2 ป้อมยาม | C19: 184 | D19: 3 | E19: ='16.ที่ดินและสิ่งก่อสร้าง'!G58 -> 421648
B20: 3.14.3 โครงการปรับปรุงสวนสาธารณะสวนเขลางค์นคร | C20: 191 | D20: 1 | E20: ='16.ที่ดินและสิ่งก่อสร้าง'!G60 -> 8700000
B21: 3.14.4 บ่อบาดาลระบบน้ำ | C21: 256 | D21: 1 | E21: ='16.ที่ดินและสิ่งก่อสร้าง'!G65 -> 120000
B22: 3.14.5 ป้ายโครงการ | C22: 273 | D22: 1 | E22: =[1]ที่ดินและสิ่งก่อสร้าง!G64 -> 30000
B23: 3.14.6 บ่อฝังกลบ-รั้วบ่อขยะ | C23: 281 | D23: 3 | E23: ='16.ที่ดินและสิ่งก่อสร้าง'!G74 -> 6584000
B24: 3.14.7 ลานจอดรถ | C24: 283 | D24: 1 | E24: ='16.ที่ดินและสิ่งก่อสร้าง'!G35 -> 6817490.8
B25: 3.14.8 ระบบไฟฟ้า | C25: 110 | D25: 1 | E25: ='16.ที่ดินและสิ่งก่อสร้าง'!G82 -> 2500000
B27: 3.14.9 ค่าปรับปรุงศาลาริมน้ำ | C27: - | D27: 1 | E27: 848408
B28: สวนสาธาณะเขลางค์นคร
B29: 3.14.10 ค่าปรับปรุงตกแต่งภูมิทัศน์ | C29: - | D29: 1 | E29: 2174850
B30: บริเวณศาลหลักเมือง
B32: รวมอสังหาริมทรัพย์ | D32: =SUM(D7:D31) -> 39 | E32: =SUM(E7:E31) -> 66374135
A39: ข | B39: สังหาริมทรัพย์
A40: 1 | B40: ครุภัณฑ์สำนักงาน
B41: ปั๊มน้ำ | C41: 55 | D41: 8 | E41: ='1.ครุภัณฑ์สำนักงาน (รวมทุกงาน)'!G15 -> 88810 | F41: - | G41: -
B42: เต้นท์ | C42: 87 | D42: ='1.ครุภัณฑ์สำนักงาน (รวมทุกงาน)'!A66 -> 50 | E42: ='1.ครุภัณฑ์สำนักงาน (รวมทุกงาน)'!G67 -> 833000 | F42: - | G42: -
B43: โต๊ะ | C43: 400 | D43: ='1.ครุภัณฑ์สำนักงาน (รวมทุกงาน)'!A853 -> 785 | E43: ='1.ครุภัณฑ์สำนักงาน (รวมทุกงาน)'!G854 -> 857760.1 | F43: ='14.ครุภัณฑ์ต่ำกว่าเกณฑ์'!A166 -> 160 | G43: ='14.ครุภัณฑ์ต่ำกว่าเกณฑ์'!H167 -> 144100
B44: เก้าอี้ | C44: 401 | D44: ='1.ครุภัณฑ์สำนักงาน (รวมทุกงาน)'!A1497 -> 642 | E44: ='1.ครุภัณฑ์สำนักงาน (รวมทุกงาน)'!G1498 -> 296347.6 | F44: ='14.ครุภัณฑ์ต่ำกว่าเกณฑ์'!A361 -> 193 | G44: ='14.ครุภัณฑ์ต่ำกว่าเกณฑ์'!H362 -> 76040
B45: ม้านั่ง | C45: 402 | D45: ='1.ครุภัณฑ์สำนักงาน (รวมทุกงาน)'!A1581 -> 82 | E45: ='1.ครุภัณฑ์สำนักงาน (รวมทุกงาน)'!G1582 -> 594030 | F45: - | G45: -
B46: ชุดรับแขก | C46: 403 | D46: ='1.ครุภัณฑ์สำนักงาน (รวมทุกงาน)'!A1587 -> 4 | E46: ='1.ครุภัณฑ์สำนักงาน (รวมทุกงาน)'!G1588 -> 89400 | F46: - | G46: -
B47: ชั้นวางของ | C47: 404 | D47: - | E47: - | F47: ='14.ครุภัณฑ์ต่ำกว่าเกณฑ์'!A364 -> 1 | G47: ='14.ครุภัณฑ์ต่ำกว่าเกณฑ์'!H365 -> 1000
B48: โพเดียม, แท่นกล่าวรายงาน | C48: 405 | D48: ='1.ครุภัณฑ์สำนักงาน (รวมทุกงาน)'!A1593 -> 4 | E48: ='1.ครุภัณฑ์สำนักงาน (รวมทุกงาน)'!G1594 -> 83772 | F48: - | G48: -
...

Sheet 1.ครุภัณฑ์สำนักงาน (รวมทุกงาน)
A1: ทะเบียนรายงานผลการตรวจนับครุภัณฑ์ ประจำปีงบประมาณ 2567 | P1: จำหน่าย
A2: ส่วนการโยธา สำนักช่าง
A3: 1.ครุภัณฑ์สำนักงาน
A4: ลำดับที่ | B4: รายการ | C4: หมายเลขครุภัณฑ์ | F4: วันเดือนปี | G4: ราคาที่ได้ | H4: สถานที่ใช้งาน | I4: สภาพครุภัณฑ์ | O4: หมายเหตุ
F5: ที่ได้มา | I5: ใช้ได้ | J5: ชำรุด | K5: เสื่อมสภาพ | L5: สูญหาย | M5: เก็บไว้นาน | N5: หมดความจำเป็น
A6: 055 | B6: (ปั๊มน้ำ)
A7: 1 | B7: ปั๊มน้ำอัตโนมัติแรงดันคงที่ขนาด 150 วัตต์ | C7: 055 | D7: 66 | E7: 0281 | F7: 7 ก.ย 66 | G7: 6420 | H7: ส่วนการาโยธา/งานสวนสาธารณะ/สวนเขื่อนยาง | I7: / | Q7: /
A8: 2 | B8: ปั๊มน้ำอัตโนมัติแรงดันคงที่ขนาด 150 วัตต์ | C8: 055 | D8: 66 | E8: 0282 | F8: 7 ก.ย 66 | G8: 6420 | H8: ส่วนการาโยธา/งานสวนสาธารณะ/สวนเขื่อนยาง | I8: / | Q8: /
A9: 3 | B9: ปั๊มน้ำอัตโนมัติแรงดันคงที่ขนาด 150 วัตต์ | C9: 055 | D9: 66 | E9: 0283 | F9: 7 ก.ย 66 | G9: 6420 | H9: ส่วนการาโยธา/งานสวนสาธารณะ/สวนเขื่อนยาง | I9: / | Q9: /
A10: 4 | B10: ปั๊มน้ำหอยโข่งขนาด 2HP, 220V, ท่อ 2นิ้วแรงดัน 500ลิตร/นาที | C10: 055 | D10: 66 | E10: 0284 | F10: 7 ก.ย 66 | G10: 11770 | H10: ส่วนการาโยธา/งานสวนสาธารณะ/สวนเขื่อนยาง | I10: / | Q10: /
A11: 5 | B11: ปั๊มน้ำหอยโข่งขนาด 2HP, 220V, ท่อ 2นิ้วแรงดัน 500ลิตร/นาที | C11: 055 | D11: 66 | E11: 0285 | F11: 7 ก.ย 66 | G11: 11770 | H11: ส่วนการาโยธา/งานสวนสาธารณะ/สวนเขื่อนยาง | I11: / | Q11: /
A12: 6 | B12: ปั๊มน้ำหอยโข่งขนาด 3HP, 380V, ท่อ 3นิ้วแรงดัน1000ลิตร/นาที | C12: 055 | D12: 66 | E12: 0286 | F12: 7 ก.ย 66 | G12: 12840 | H12: ส่วนการาโยธา/งานสวนสาธารณะ/สวนเขื่อนยาง | I12: / | Q12: /
A13: 7 | B13: ปั๊มน้ำหอยโข่งขนาด 5HP, 380V, ท่อ 3นิ้วแรงดัน1200ลิตร/นาที | C13: 055 | D13: 66 | E13: 0287 | F13: 7 ก.ย 66 | G13: 16585 | H13: ส่วนการาโยธา/งานสวนสาธารณะ/สวนเขื่อนยาง | I13: / | Q13: /
A14: 8 | B14: ปั๊มน้ำหอยโข่งขนาด 5HP, 380V, ท่อ 3นิ้วแรงดัน1200ลิตร/นาที | C14: 055 | D14: 66 | E14: 0288 | F14: 7 ก.ย 66 | G14: 16585 | H14: ส่วนการาโยธา/งานสวนสาธารณะ/สวนเขื่อนยาง | I14: / | Q14: /
G15: =SUM(G7:G14) -> 88810
A16: 087 | B16: (เต้นท์)
A17: 1 | B17: โครงเต้นท์พร้อมผ้าใบ | C17: 087 | D17: 59 | E17: 0126 | F17: 7 เม.ย. 59 | G17: 21900 | H17: ส่วนการโยธา / งานบำรุงรักษาอาคารและสถานที่ | I17: / | O17: โรงพัสดุฯ | Q17: /
A18: 2 | B18: โครงเต้นท์พร้อมผ้าใบ | C18: 087 | D18: 59 | E18: 0127 | F18: 7 เม.ย. 59 | G18: 21900 | H18: ส่วนการโยธา / งานบำรุงรักษาอาคารและสถานที่ | I18: / | O18: โรงพัสดุฯ | Q18: /
A19: 3 | B19: โครงเต้นท์พร้อมผ้าใบ | C19: 087 | D19: 59 | E19: 0128 | F19: 7 เม.ย. 59 | G19: 21900 | H19: ส่วนการโยธา / งานบำรุงรักษาอาคารและสถานที่ | I19: / | O19: โรงพัสดุฯ | Q19: /
A20: 4 | B20: โครงเต้นท์พร้อมผ้าใบ | C20: 087 | D20: 59 | E20: 0129 | F20: 7 เม.ย. 59 | G20: 21900 | H20: ส่วนการโยธา / งานบำรุงรักษาอาคารและสถานที่ | I20: / | O20: โรงพัสดุฯ | Q20: /
A21: 5 | B21: โครงเต้นท์พร้อมผ้าใบ | C21: 087 | D21: 59 | E21: 0130 | F21: 7 เม.ย. 59 | G21: 21900 | H21: ส่วนการโยธา / งานบำรุงรักษาอาคารและสถานที่ | I21: / | O21: โรงพัสดุฯ | Q21: /
A22: 6 | B22: โครงเต้นท์พร้อมผ้าใบ | C22: 087 | D22: 59 | E22: 0131 | F22: 7 เม.ย. 59 | G22: 21900 | H22: ส่วนการโยธา / งานบำรุงรักษาอาคารและสถานที่ | I22: / | O22: โรงพัสดุฯ | Q22: /
A23: 7 | B23: โครงเต้นท์พร้อมผ้าใบ | C23: 087 | D23: 59 | E23: 0132 | F23: 7 เม.ย. 59 | G23: 21900 | H23: ส่วนการโยธา / งานบำรุงรักษาอาคารและสถานที่ | I23: / | O23: โรงพัสดุฯ | Q23: /
A24: 8 | B24: โครงเต้นท์พร้อมผ้าใบ | C24: 087 | D24: 59 | E24: 0133 | F24: 7 เม.ย. 59 | G24: 21900 | H24: ส่วนการโยธา / งานบำรุงรักษาอาคารและสถานที่ | I24: / | O24: โรงพัสดุฯ | Q24: /
A25: 9 | B25: โครงเต้นท์พร้อมผ้าใบ | C25: 087 | D25: 59 | E25: 0134 | F25: 7 เม.ย. 59 | G25: 21900 | H25: ส่วนการโยธา / งานบำรุงรักษาอาคารและสถานที่ | I25: / | O25: โรงพัสดุฯ | Q25: /
A26: 10 | B26: โครงเต้นท์พร้อมผ้าใบ | C26: 087 | D26: 59 | E26: 0135 | F26: 7 เม.ย. 59 | G26: 21900 | H26: ส่วนการโยธา / งานบำรุงรักษาอาคารและสถานที่ | I26: / | O26: โรงพัสดุฯ | Q26: /
A27: 11 | B27: ผ้าใบเต็นท์ขนาด 4x8 เมตร สีขาว | C27: 087 | D27: 62 | E27: 0136 | F27: 14 มี.ค.62 | G27: 8700 | H27: ส่วนการโยธา / งานบำรุงรักษาอาคารและสถานที่ | I27: / | O27: โรงพัสดุฯ | Q27: /
A28: 12 | B28: ผ้าใบเต็นท์ขนาด 4x8 เมตร สีขาว | C28: 088 | D28: 63 | E28: 0137 | F28: 14 มี.ค.62 | G28: 8700 | H28: ส่วนการโยธา / งานบำรุงรักษาอาคารและสถานที่ | I28: / | O28: โรงพัสดุฯ | Q28: /
... A66: 50 | B66: ผ้าใบเต็นท์ขนาด 4x8 เมตร สีขาว พร้อมสกรีนโลโก้ เทศบาลนครลำปาง | C66: 087 | D66: 66 | E66: 0175 | F66: 6 ม.ค.66 | G66: 22000 | H66: ส่วนการโยธา / งานบำรุงรักษาอาคารและสถานที่ | I66: / | O66: โรงพัสดุฯ | Q66: /
G67: =SUM(G17:G66) -> 833000
A68: 400 | B68: (โต๊ะ)
A69: 1 | B69: โต๊ะ | C69: 400 | D69: 26 | E69: 0713 | F69: 46132 | G69: 4500 | H69: ส่วนการโยธา/งานธุรการ | K69: / | O69: ขอจำหน่าย
A70: 2 | B70: โต๊ะพิมพ์ดีด | C70: 400 | D70: 31 | E70: 1765 | F70: 11504 | G70: 1200 | H70: ส่วนการโยธา/งานธุรการ | I70: / | O70: ตึกสาธารณูปโภค | Q70: /
A71: 3 | B71: โต๊ะทำงานไม้อัดสัก | C71: 400 | D71: 32 | E71: 1877 | F71: 11984 | G71: 800 | H71: ส่วนการโยธา/งานธุรการ (ช่างสุขาฯ เดิม) | K71: / | O71: ขอจำหน่าย
A72: 4 | B72: โต๊ะทำงานไม้อัดสัก | C72: 400 | D72: 32 | E72: 1888 | F72: 11984 | G72: 900 | H72: ส่วนการโยธา/ฝ่ายช่างสุขาภิบาล/งานวิเคราะห์คุณภาพน้ำ | O72: วิชุดา
A73: 5 | B73: โต๊ะประชุม ผิวพื้นและขากรุไม้อัดสัก | C73: 400 | D73: 38 | E73: 2834 | F73: 14158 | G73: 12915 | H73: ส่วนการโยธา/งานเครื่องจักรกล/ ศูนย์เครื่องจักรฯ | I73: / | O73: พิมทิพย์ | Q73: /
A74: 6 | B74: โต๊ะประชุม | C74: 400 | D74: 38 | E74: 2836 | F74: 14158 | G74: 12915 | H74: ส่วนการโยธา/งานสวนสาธารณะ/สาธารณะ สวน ท.7 | I74: / | O74: สวน ท.7 | Q74: /
A75: 7 | B75: โต๊ะประชุม | C75: 400 | D75: 38 | E75: 2837 | F75: 14158 | G75: 12915 | H75: ส่วนการโยธา/งานธุรการ | I75: / | O75: ตึกสุขาภิบาล | Q75: /
A76: 8 | B76: โต๊ะประชุม | C76: 400 | D76: 38 | E76: 2842 | F76: 14158 | G76: 12915 | H76: ส่วนการโยธา/งานธุรการ | K76: /
A77: 9 | B77: โต๊ะทำงานเหล็ก | C77: 400 | D77: 43 | E77: 3752 | F77: 15751 | G77: 4400 | H77: ส่วนการโยธา/งานธุรการ/(ช่างสุขาฯ เดิม) | K77: / | O77: ขอจำหน่าย
...

Sheet 2.ครุภัณฑ์ยานพาหนะฯ (รวมทุกงาน)
A1: ทะเบียนรายงานผลการตรวจนับครุภัณฑ์ ประจำปีงบประมาณ 2567 | N1: จำหน่าย
A3: 2. ครุภัณฑ์ยานพาหนะและขนส่ง
A4: ลำดับที่ | B4: รายการ | C4: หมายเลขครุภัณฑ์ | D4: วันเดือนปี | E4: ราคาที่ได้ | F4: สถานที่ใช้งาน | G4: สภาพครุภัณฑ์ | M4: หมายเหตุ
D5: ที่ได้มา | G5: ใช้ได้ | H5: ชำรุด | I5: เสื่อมสภาพ | J5: สูญหาย | K5: เก็บไว้นาน | L5: หมดความจำเป็น
A6: 001 | B6: (รถตู้)
A7: 1 | B7: รถตู้ ยี่ห้อ มิตซูบิชิ รุ่น แอล300 (นก.587) | C7: 001-28-0003 | D7: 2 เม.ย.28 | E7: 306000 | F7: Carpool 1 | H7: / | M7: ขอจำหน่าย
A8: 2 | B8: รถตรวจการณ์ ยี่ห้อ แลนด์โรเวอร์ รุ่น Discouvery (กค-589) | C8: 001-40-0007 | D8: 14759 | E8: 1297000 | F8: Carpool 2 | G8: / | M8: พิมทิพย์
A9: 3 | B9: รถตู้ ยี่ห้อ โตโยต้า รุ่น คอมมูเตอร์ สีเทา (นก 2277) | C9: 001-49-0008 | D9: 17939 | E9: 1150000 | F9: Carpool 1 | G9: / | M9: พิมทิพย์
A10: 4 | B10: รถตู้ ยี่ห้อ นิสสัน รุ่น เออแวน สีบรอนซ์เงิน (นข 2892) | C10: 001-49-0009 | D10: 31 พ.ค.49 | E10: 979000 | F10: Carpool 1 | G10: / | M10: พิมทิพย์
A11: 5 | B11: รถตรวจการณ์ ยี่ห้อ อีซูซุ รุ่น MU7 สีดำ-เทา (กก-9546) | C11: 001-52-0010 | D11: 19086 | E11: 1192000 | F11: Carpool 1 | G11: / | M11: พิมทิพย์
A12: 6 | B12: รถตู้ ยี่ห้อโตโยต้า รุ่น คอมมูเตอร์ สีขาว(นข-5828) | C12: 001-58-0013 | D12: 21194 | E12: 1293000 | F12: Carpool 1 | G12: / | M12: พิมทิพย์
A13: 7 | B13: รถตู้ 12 ที่นั่ง ยี่ห้อนิสสัน รุ่น NV 350 URVAN (นข-6898) | C13: 001-62-0014 | D13: 22921 | E13: 1235000 | F13: Carpool 1 | G13: / | M13: พิมทิพย์
E14: =SUM(E7:E13) -> 7452000
A15: 002 | B15: (รถกระบะ)
A16: 1 | B16: รถยนต์บรรทุก | C16: 002-29-0018 | D16: 10638 | E16: 294500 | F16: ส่วนการโยธา/งานสวนสาธาณะ | G16: /
A17: 2 | B17: รถยนต์ปิคอัพสองตอน | C17: 002-29-0020 | D17: 10754 | E17: 225000 | F17: งานบำรุงรักษาทางและสะพาน | I17: / | M17: ขอจำหน่าย | N17: 1
A18: 3 | B18: รถกระบะ 4 ประตู | C18: 002-31-0021 | D18: 11572 | E18: 590000 | F18: Capool 2 | G18: / | M18: พิมทิพย์
A19: 4 | B19: รถยนต์บรรทุก | C19: 002-34-0024 | D19: 12587 | E19: 1497000 | F19: งานบำรุงรักษาทางและสะพาน | G19: /
A20: 5 | B20: รถบรรทุกกระบะ 6 ล้อ | C20: 002-34-0025 | D20: 12548 | E20: 465000 | F20: Capool 1 | G20: / | M20: พิมทิพย์
A21: 6 | B21: รถกระบะวากอน | C21: 002-34-0039 | D21: 12744 | E21: 574000 | F21: Capool 1 | G21: / | M21: พิมทิพย์
A22: 7 | B22: รถกระบะ 4 ประตู | C22: 002-35-0027 | D22: 12912 | E22: 577000 | F22: Capool 1 | G22: / | M22: พิมทิพย์
A23: 8 | B23: รถบรรทุกกระบะสำเร็จรูป | C23: 002-35-0028 | D23: 12912 | E23: 347000 | F23: งานบำรุงรักษาทางและสะพาน | G23: / | M23: โอนให้งานลาดยางงบ 62
A24: 9 | B24: รถยนต์กระบะ | C24: 002-37-0030 | D24: 13688 | E24: 530000 | F24: งานบำรุงรักษาอาคารและสถานที่ | G24: / | M24: กรกิจ
A25: 10 | B25: กระบะ 4 ประตู | C25: 002-39-0034 | D25: 14534 | E25: 501000 | F25: Capool 1 | G25: / | M25: พิมทิพย์
A26: 11 | B26: รถกระบะแค็บ | C26: 002-40-0038 | D26: 14652 | E26: 375300 | F26: Capool 1 | G26: / | M26: พิมทิพย์
A27: 12 | B27: รถกระบะ 4 ประตู | C27: 002-40-0040 | D27: 14744 | E27: 519000 | F27: Capool 1 | G27: / | M27: พิมทิพย์
A28: 13 | B28: รถยนต์บรรทุกกระบะ | C28: 002-41-0041 | D28: 15326 | E28: 450000 | F28: งานบำรุงรักษาอาคารและสถานที่ | G28: / | M28: อัศวิน
A29: 14 | B29: รถยนต์ ยี่ห้อ TOYOTA ทะเบียน บท5886 ลำปาง | C29: 002-41-0042 | D29: 15213 | E29: 347500 | F29: ศูนย์เครื่องจักรกล | G29: / | M29: พิมทิพย์
A30: 15 | B30: กระบะแค๊ป | C30: 002-41-0043 | D30: 15249 | E30: 390000 | F30: Capool 2 | G30: / | M30: พิมทิพย์
A31: 16 | B31: กระบะแค๊ป | C31: 002-41-0044 | D31: 15249 | E31: 390000 | F31: Capool 1 | G31: / | M31: พิมทิพย์
... A44: 29 | B44: รถกระบะ 4 ประตู | C44: 002-52-0063 | D44: 19114 | E44: 615950 | F44: Capool 1 | G44: / | M44: พิมทิพย์
A45: 30 | B45: รถกระบะ 4 ประตู | C45: 002-55-0064 | D45: 20402 | E45: 623525.33 | F45: Capool 1 | G45: /
A46: 31 | B46: รถยนต์บรรทุก (ดีเซล) กระบะเหล็ก | C46: 002-67-0065 | D46: 19 ก.ย 67 | E46: 1220000 | F46: ส่วนการโยธา / งานสวนสาธารณะ | G46: /
E47: =SUM(E16:E46) -> 16549970
A48: 006 | B48: (รถบรรทุกน้ำ)
A49: 1 | B49: รถบรรทุกน้ำ ยี่ห้อ HINO สีแดง (ลป. 81-1716) | C49: 006-22-0004 | D49: 14 พ.ค. 22 | E49: 339500 | F49: ส่วนการโยธา / งานสวนสาธารณะ | G49: /
A50: 2 | B50: รถบรรทุกน้ำ ยี่ห้ออีซูซุ สีแดง (ลป.81-1885) | C50: 006-25-0006 | D50: 24 ส.ค. 25 | E50: 430611 | F50: ส่วนการโยธา / งานสวนสาธารณะ | H50: /
A51: 3 | B51: รถบรรทุกน้ำ ยี่ห้ออีซูซุ สีแดง (ลป.81-1715) | C51: 006-25-0007 | D51: 17 ก.ย. 25 | E51: 430611 | F51: ส่วนการโยธา / งานสวนสาธารณะ | G51: /
A52: 4 | B52: รถบรรทุกน้ำ ยี่ห้อ HINO สีแดง | C52: 006-34-0008 | D52: 31 ม.ค.34 | E52: 1497000 | F52: ส่วนการโยธา /งานบำรุงรักษาและซ่อมแซม | G52: / | M52: บ่อขยะ
A53: 5 | B53: รถบรรทุกน้ำ ยี่ห้ออีซูซุ บรรจุน้ำ 12,000 บาท (ลป บท 4615) | C53: 006-41-0012 | D53: 23 มี.ค.41 | E53: 1980000 | F53: ส่วนการโยธา / งานสวนสาธารณะ | G53: / | M53: โอนมาจากดับเพลิง
...

Sheet 3. ครุภัณฑ์การเกษตร(รวมทุกงาน)
A1: ทะเบียนรายงานผลการตรวจนับครุภัณฑ์ ประจำปีงบประมาณ 2567 | P1: จำหน่าย
A2: ส่วนการโยธา สำนักช่าง
A3: 3. ครุภัณฑ์การเกษตร
A4: ลำดับที่ | B4: รายการ | C4: หมายเลขครุภัณฑ์ | F4: วันเดือนปี | G4: ราคาที่ได้ | H4: สถานที่ใช้งาน | I4: สภาพครุภัณฑ์ | O4: หมายเหตุ
F5: ที่ได้มา | I5: ใช้ได้ | J5: ชำรุด | K5: เสื่อมสภาพ | L5: สูญหาย | M5: เก็บไว้นาน | N5: หมดความจำเป็น
A6: 055 | B6: (เครื่องสูบน้ำ เครื่องปั๊มน้ำ)
A7: 1 | B7: เครื่องสูบน้ำ | C7: 055 | D7: 34 | E7: 0021 | F7: 24 พ.ค.34 | G7: 14000 | H7: ส่วนการโยธา/สวนสาธารณะ/เขื่อนยาง | J7: /
A8: 2 | B8: เครื่องปั๊มน้ำ | C8: 055 | D8: 35 | E8: 0028 | F8: 1 ก.ย. 35 | G8: 20500 | H8: ส่วนการโยธา/งานสวนสาธารณะ | J8: /
A9: 3 | B9: เครื่องปั๊มน้ำ | C9: 055 | D9: 36 | E9: 0023 | F9: 20 ม.ค. 36 | G9: 9000 | H9: ส่วนการโยธา/งานบำรุงรักษาและซ่อมแซม/บ่อหมัก | I9: / | O9: บ่อหมัก
A10: 4 | B10: เครื่องสูบน้ำ | C10: 055 | D10: 38 | E10: 0037 | F10: 29 ก.ย. 38 | G10: 25000 | H10: ส่วนการโยธา/งานสวนสาธารณะ | J10: /
A11: 5 | B11: เครื่องสูบน้ำ | C11: 055 | D11: 38 | E11: 0038 | F11: 29 ก.ย. 38 | G11: 25000 | H11: ส่วนการโยธา/สวนสาธารณะ/เขื่อนยาง | J11: /
A12: 6 | B12: เครื่องสูบน้ำ | C12: 055 | D12: 42 | E12: 0057 | F12: 12 มี.ค. 42 | G12: 8800 | H12: ส่วนการโยธา/งานสวนสาธารณะ | I12: /
A13: 7 | B13: เครื่องสูบน้ำ | C13: 055 | D13: 42 | E13: 0058 | F13: 12 มี.ค. 42 | G13: 8800 | H13: ส่วนการโยธา/งานสวนสาธารณะ | I13: /
A14: 8 | B14: เครื่องสูบน้ำ | C14: 055 | D14: 44 | E14: 0075 | F14: 25 เม.ย. 44 | G14: 3300 | H14: ส่วนการโยธา/สวนสาธารณะ/เขื่อนยาง | I14: /
A15: 9 | B15: เครื่องสูบน้ำ | C15: 055 | D15: 45 | E15: 0084 | F15: 5 มิ.ย. 45 | G15: 38000 | H15: ส่วนการโยธา/งานบำรุงรักษาและซ่อมแซม/บ่อหมัก | I15: / | O15: บ่อหมัก
A16: 10 | B16: เครื่องสูบน้ำ | C16: 055 | D16: 45 | E16: 0085 | F16: 5 มิ.ย. 45 | G16: 8800 | H16: ส่วนการโยธา/งานบำรุงรักษาและซ่อมแซม/บ่อหมัก | I16: / | O16: บ่อหมัก
A17: 11 | B17: เครื่องสูบน้ำ | C17: 055 | D17: 47 | E17: 0113 | F17: 28 เม.ย. 47 | G17: 11000 | H17: ส่วนการโยธา/งานสวนสาธารณะ | I17: /
A18: 12 | B18: เครื่องสูบน้ำ | C18: 055 | D18: 47 | E18: 0114 | F18: 28 เม.ย. 47 | G18: 11000 | H18: ส่วนการโยธา/งานสวนสาธารณะ | I18: /
A19: 13 | B19: เครื่องสูบน้ำหอยโข่ง | C19: 055 | D19: 48 | E19: 0116 | F19: 31 ส.ค. 48 | G19: 87000 | H19: ส่วนการโยธา/งานบำรุงรักษาและซ่อมแซม/บ่อหมัก | I19: / | O19: บ่อหมัก
A20: 14 | B20: ปั๊มหอยโข่ง | C20: 055 | D20: 48 | E20: 0117 | F20: 26 ก.ย. 48 | G20: 5000 | H20: ส่วนการโยธา/งานสวนสาธารณะ/เรือนเพาะชำเคนเน็ต | I20: /
A21: 15 | B21: เครื่องสูบน้ำแบบหอยโข่ง | C21: 055 | D21: 49 | E21: 0129 | F21: 2 มี.ค. 49 | G21: 340000 | H21: ส่วนการโยธา/งานบำรุงรักษาและซ่อมแซม/บ่อหมัก | I21: / | O21: บ่อหมัก
A22: 16 | B22: เครื่องสูบน้ำ | C22: 055 | D22: 50 | E22: 0132 | F22: 3 พ.ค. 50 | G22: 18000 | H22: ส่วนการโยธา/งานบำรุงรักษาและซ่อมแซม/บ่อหมัก | I22: / | O22: บ่อหมัก
A23: 17 | B23: เครื่องสูบน้ำ | C23: 055 | D23: 50 | E23: 0133 | F23: 3 พ.ค. 50 | G23: 18000 | H23: ส่วนการโยธา/งานบำรุงรักษาและซ่อมแซม/บ่อหมัก | I23: / | O23: บ่อหมัก
A24: 18 | B24: เครื่องสูบน้ำ | C24: 055 | D24: 50 | E24: 0135 | F24: 28 ธ.ค. 50 | G24: 32500 | H24: ใช้ที่ระบบประปาถังสูง | I24: / | O24: ใช้ที่ระบบประปาถังสูง
A25: 19 | B25: เครื่องสูบน้ำหอยโข่ง | C25: 055 | D25: 50 | E25: 0136 | F25: 28 ธ.ค. 50 | G25: 27000 | H25: ใช้ที่ระบบประปาถังสูง | I25: / | O25: ใช้ที่ระบบประปาถังสูง
A26: 20 | B26: เครื่องสูบน้ำหอยโข่ง | C26: 055 | D26: 50 | E26: 0137 | F26: 28 ธ.ค. 50 | G26: 27000 | H26: ใช้ที่ระบบประปาถังสูง | I26: / | O26: บ่อหมัก
A27: 21 | B27: เครื่องสูบน้ำ | C27: 055 | D27: 52 | E27: 0138 | F27: 14 พ.ย. 52 | G27: 49200 | H27: ส่วนการโยธา/งานสวนสาธารณะ | J27: /
A28: 22 | B28: เครื่องสูบน้ำหมุนเวียน | C28: 055 | D28: 52 | E28: 0139 | F28: 24 มิ.ย. 52 | G28: 44100 | H28: ส่วนการโยธา/งานสวนสาธารณะ/ข่วงนคร | I28: /
A29: 23 | B29: เครื่องสูบน้ำหมุนเวียน | C29: 055 | D29: 52 | E29: 0140 | F29: 24 มิ.ย. 52 | G29: 21000 | H29: ส่วนการโยธา/งานสวนสาธารณะ/ข่วงนคร | I29: /
A30: 24 | B30: เครื่องสูบน้ำแบบจุ่ม | C30: 055 | D30: 52 | E30: 0141 | F30: 24 มิ.ย. 52 | G30: 17000 | H30: ส่วนการโยธา/งานสวนสาธารณะ/ข่วงนคร | I30: /
A31: 25 | B31: เครื่องสูบน้ำแบบจุ่ม | C31: 055 | D31: 52 | E31: 0142 | F31: 24 มิ.ย. 52 | G31: 17000 | H31: ส่วนการโยธา/งานสวนสาธารณะ/ข่วงนคร | I31: /
A32: 26 | B32: เครื่องสูบน้ำแบบจุ่ม | C32: 055 | D32: 52 | E32: 0143 | F32: 24 มิ.ย. 52 | G32: 17000 | H32: ส่วนการโยธา/งานสวนสาธารณะ/ข่วงนคร | I32: /
A33: 27 | B33: เครื่องสูบน้ำแบบจุ่ม | C33: 055 | D33: 52 | E33: 0144 | F33: 24 มิ.ย. 52 | G33: 17000 | H33: ส่วนการโยธา/งานสวนสาธารณะ/ข่วงนคร | I33: /
A34: 28 | B34: เครื่องสูบน้ำแบบจุ่ม | C34: 055 | D34: 52 | E34: 0145 | F34: 24 มิ.ย. 52 | G34: 17000 | H34: ส่วนการโยธา/งานสวนสาธารณะ/ข่วงนคร | I34: /
A35: 29 | B35: เครื่องสูบน้ำแบบจุ่ม | C35: 055 | D35: 52 | E35: 0146 | F35: 24 มิ.ย. 52 | G35: 17000 | H35: ส่วนการโยธา/งานสวนสาธารณะ/ข่วงนคร | I35: /
A36: 30 | B36: เครื่องสูบน้ำแบบจุ่ม | C36: 055 | D36: 52 | E36: 0147 | F36: 24 มิ.ย. 52 | G36: 17000 | H36: ส่วนการโยธา/งานสวนสาธารณะ/ข่วงนคร | I36: /
A37: 31 | B37: เครื่องสูบน้ำรดน้ำต้นไม้ | C37: 055 | D37: 52 | E37: 0148 | F37: 24 มิ.ย. 52 | G37: 36000 | H37: ส่วนการโยธา/งานสวนสาธารณะ/ข่วงนคร | I37: /
A38: 32 | B38: เครื่องสูบน้ำหมุนเวียน | C38: 055 | D38: 52 | E38: 0149 | F38: 24 มิ.ย. 52 | G38: 19500 | H38: ส่วนการโยธา/งานสวนสาธารณะ/สวนห้าแยก | I38: /
A39: 33 | B39: เครื่องสูบน้ำหมุนเวียน | C39: 055 | D39: 52 | E39: 0150 | F39: 24 มิ.ย. 52 | G39: 44100 | H39: ส่วนการโยธา/งานสวนสาธารณะ/สวนห้าแยก | I39: /
... A58: 52 | B58: เครื่องสูบน้ำ(แบบจุ่ม) | C58: 055 | D58: 53 | E58: 0169 | F58: 29 มี.ค. 53 | G58: 49220 | H58: ส่วนการโยธา/งานสวนสาธารณะ | I58: /
...

Sheet 4.ครุภัณฑ์ก่อสร้าง
A1: ทะเบียนรายงานผลการตรวจนับครุภัณฑ์ ประจำปีงบประมาณ 2567 | P1: จำหน่าย
A2: ส่วนการโยธา สำนักช่าง
A3: 4. ครุภัณฑ์ก่อสร้าง
A4: ลำดับที่ | B4: รายการ | C4: หมายเลขครุภัณฑ์ | F4: วันเดือนปี ที่ได้มา | G4: ราคาที่ได้ | H4: สถานที่ใช้งาน | I4: สภาพครุภัณฑ์ | O4: หมายเหตุ
I5: ใช้ได้ | J5: ชำรุด | K5: เสื่อมสภาพ | L5: สูญหาย | M5: เก็บไว้นาน | N5: หมดความจำเป็น
A6: 005 | B6: (รถเข็น)
A7: 1 | B7: รถเข็น ชนิด 3 ล้อ ขนาด 10 ปิ๊บ สีน้ำเงิน | C7: 005-63-0109 | F7: 23087 | G7: 2000 | H7: ส่วนการโยธา / ฝ่ายสวนสาธารณะ (เรือ่นเพาะชำ) | I7: /
A8: 2 | B8: รถเข็น ชนิด 3 ล้อ ขนาด 10 ปิ๊บ สีน้ำเงิน | C8: 005-63-0110 | F8: 23087 | G8: 2000 | H8: ส่วนการโยธา / ฝ่ายสวนสาธารณะ (เรือ่นเพาะชำ) | I8: /
A9: 3 | B9: รถเข็น ชนิด 3 ล้อ ขนาด 10 ปิ๊บ สีน้ำเงิน | C9: 005-63-0111 | F9: 23087 | G9: 2000 | H9: ส่วนการโยธา / ฝ่ายสวนสาธารณะ (เรือ่นเพาะชำ) | I9: /
A10: 4 | B10: รถเข็น ชนิด 3 ล้อ ขนาด 10 ปิ๊บ สีน้ำเงิน | C10: 005-63-0112 | F10: 23087 | G10: 2000 | H10: ส่วนการโยธา / ฝ่ายสวนสาธารณะ (เรือ่นเพาะชำ) | I10: /
A11: 5 | B11: รถเข็น ชนิด 3 ล้อ ขนาด 10 ปิ๊บ สีน้ำเงิน | C11: 005-63-0113 | F11: 23087 | G11: 2000 | H11: ส่วนการโยธา / ฝ่ายสวนสาธารณะ (เรือ่นเพาะชำ) | I11: /
G12: =SUM(G7:G11) -> 10000
A13: 015 | B13: (รถเกลี่ยดิน รถเกรด รถบด)
A14: 1 | B14: รถเกลี่ยดิน ยี่ห้อมิตซูบิชิ สีเหลือง ลป.ต.1145 | C14: 015-39-0002 | F14: 17 มิ.ย. 39 | G14: 2694000 | H14: ส่วนการโยธา / งานบำรุงรักษาทางและสะพาน | I14: /
G15: =SUM(G14:G14) -> 2694000
A16: 018 | B16: (รถตักดินล้อยาง รถขุดดิน รถตักหน้าขุดหลัง)
A17: 1 | B17: รถตักล้อยาง ยี่ห้อฟูรูกาว่า สีเหลือง ลป.ต.0293 | C17: 018-30-0001 | F17: 18 มิ.ย. 30 | G17: 1397000 | H17: ส่วนการโยธา / งานบำรุงรักษาทางและสะพาน | I17: /
A18: 2 | B18: รถขุดตีนตะขาบ ยี่ห้อแคตเตอร์ฟิลล่าร์ สีเหลือง ลป.ต.0002 | C18: 018-32-0002 | F18: 28 เม.ย. 32 | G18: 1994000 | H18: ส่วนการโยธา / งานบำรุงรักษาทางและสะพาน | I18: /
A19: 3 | B19: รถขุดตีนตะขาบ ยี่ห้อแคตเตอร์ฟิลล่าร์ สีเหลือง ลป.ต 0017 | C19: 018-34-0003 | F19: 11 เม.ย. 34 | G19: 2340000 | H19: ส่วนการโยธา /งานบำรุงรักษาและซ่อมแซม | I19: /
A20: 4 | B20: รถขุดตักดิน ยี่ห้อแคตเตอร์ฟิลล่าร์ สีเหลือง ลป.ต.1202 | C20: 018-40-0005 | F20: 17 ก.พ. 40 | G20: 2097000 | H20: ส่วนการโยธา / งานบำรุงรักษาทางและสะพาน | I20: /
A21: 5 | B21: รถขุดตีนตะขาบ ยี่ห้อแคตเตอร์ฟิลล่าร์ สีเหลือง-ดำ ลป.ตค 101 | C21: 018-41-0006 | F21: 15 ก.ค. 41 | G21: 3780000 | H21: ส่วนการโยธา / งานบำรุงรักษาทางและสะพาน | I21: /
A22: 6 | B22: รถขุดตีนตะชาบ ขนาด 150 แรงม้า รถขุดไฮโดลิค ยี่ห้อ JCB | C22: 018-59-0007 | F22: 15 มี.ค. 59 | G22: 4490000 | H22: ส่วนการโยธา / งานบำรุงรักษาทางและสะพาน | I22: /
B23: รุ่น JS200sc สีเหลือง ลป.ต.ค 1441
A24: 7 | B24: รถขุดตีนตะขาบ ขนาด 150 แรงม้า รถขุดไฮโดลิค ยี่ห้อ JCB | C24: 018-59-0008 | F24: 15 มี.ค.59 | G24: 4490000 | H24: ส่วนการโยธา /งานบำรุงรักษาและซ่อมแซม | I24: /
B25: รุ่น JS200sc สีเหลือง ลป.ต.ค 1442
A26: 8 | B26: รถตักหน้าขุดหลัง LOVOL ขับเคลื่อน 4 ล้อ ทะเบียน ตค-2124 | C26: 018-61-0009 | F26: 30 ส.ค.61 | G26: 2480000 | H26: ส่วนการโยธา /งานบำรุงรักษาและซ่อมแซม | I26: /
G27: =SUM(G17:G26) -> 23068000
A28: 019 | B28: (รถแทรกเตอร์)
A29: 1 | B29: รถแทรกเตอร์ตีนตะขาบ ยี่ห้อคัตเตอร์ฟิลล่า สีเหลือง ลป.ต 1016 | C29: 019-34-0002 | F29: 28 พ.ย. 34 | G29: 3900000 | H29: ส่วนการโยธา / งานบำรุงรักษาทางและสะพาน | K29: / | O29: ขอจำหน่าย
A30: 2 | B30: รถแทรกเตอร์ตีนตะขาบ ยี่ห้อคัตเตอร์ฟิลล่า สีเหลือง ลป.ต 1051 | C30: 019-36-0003 | F30: 14 พ.ค. 36 | G30: 2790000 | H30: ส่วนการโยธา /งานบำรุงรักษาและซ่อมแซม | I30: /
G31: =SUM(G29:G30) -> 6690000
A32: 020 | B32: (รถบด)
A33: 1 | B33: รถบดเซดติลามเยอร์ เครื่องดีเซล 8-10 ตัน | C33: 020-04-0002 | F33: 28 ก.พ. 04 | G33: 185000 | H33: ส่วนการโยธา / งานบำรุงรักษาทางและสะพาน | K33: /
A34: 2 | B34: รถบดแบบสั่นสะเทือน ยี่ห้อไดน่าแพค สีเหลือง ลป.ถ.0026 | C34: 020-34-0004 | F34: 17 เม.ย. 34 | G34: 2098000 | H34: ส่วนการโยธา / งานบำรุงรักษาทางและสะพาน | I34: /
A35: 3 | B35: รถบดล้อยาง ยี่ห้อไดน่าแพค สีเหลือง ลป.ถ.0038 | C35: 020-37-0005 | F35: 12 พ.ค. 37 | G35: 2090000 | H35: ส่วนการโยธา / งานบำรุงรักษาทางและสะพาน | I35: /
A36: 4 | B36: รถบดถนนล้อเหล็กเรียบ 2 ล้อยี่ห้อ DYNAPACสีเหลือง ลป.ถ 0062 | C36: 020-40-0006 | F36: 27 มี.ค. 40 | G36: 1500000 | H36: ส่วนการโยธา / งานบำรุงรักษาทางและสะพาน | I36: /
A37: 5 | B37: รดบด (รถไม่ได้ใช้แล้วเก็บอนุรักษ์ไว้) | C37: 020-98-0001 | F37: 26 ธค.98 | G37: 168000 | H37: ส่วนการโยธา / งานบำรุงรักษาทางและสะพาน | N37: /
G38: =SUM(G33:G37) -> 6041000
A39: 023 | B39: (ล้อเลื่อน เกวียน ล้อเข็น)
A40: 1 | B40: รถเข็นชนิดล้อคู่ ตัวถังทำด้วยเหล็กหนา | C40: 023-45-0419 | F40: 22 มี.ค. 45 | G40: 1200 | H40: ส่วนการโยธา /งานบำรุงรักษาและซ่อมแซม | I40: / | O40: บ่อหมัก
...

Sheet 5. ครุภัณฑ์ไฟฟ้าฯ
A1: ทะเบียนรายงานผลการตรวจนับครุภัณฑ์ ประจำปีงบประมาณ 2567 | P1: จำหน่าย
A2: ส่วนการโยธา สำนักช่าง
A3: 5.ครุภัณฑ์ไฟฟ้าและวิทยุ
A4: ลำดับที่ | B4: รายการ | C4: หมายเลขครุภัณฑ์ | F4: วันเดือนปี ที่ได้มา | G4: ราคาที่ได้ | H4: สถานที่ใช้งาน | I4: สภาพครุภัณฑ์ | O4: หมายเหตุ
I5: ใช้ได้ | J5: ชำรุด | K5: เสื่อมสภาพ | L5: สูญหาย | M5: เก็บไว้นาน | N5: หมดความจำเป็น
A6: 082 | B6: (โคมไฟฟ้าสาธารณะ, โคมไฟฟ้า, ไฟราว)
A7: 1 | B7: โคมไฟฟ้า ขนาด 2X40W | C7: 082 | D7: 31 | E7: 0016 | F7: 8 ก.ย. 31 | G7: 990 | H7: ส่วนการโยธา/งานไฟฟ้าสาธารณะ | K7: / | O7: ขอจำหน่าย
A8: 2 | B8: โคมไฟฟ้า ขนาด 2X40W | C8: 082 | D8: 31 | E8: 0017 | F8: 8 ก.ย. 31 | G8: 990 | H8: ส่วนการโยธา/งานไฟฟ้าสาธารณะ | K8: / | O8: ขอจำหน่าย
A9: 3 | B9: โคมไฟฟ้า ขนาด 2X40W | C9: 082 | D9: 31 | E9: 0018 | F9: 8 ก.ย. 31 | G9: 990 | H9: ส่วนการโยธา/งานไฟฟ้าสาธารณะ | K9: / | O9: ขอจำหน่าย
A10: 4 | B10: โคมไฟฟ้า ขนาด 2X40W | C10: 082 | D10: 31 | E10: 0019 | F10: 8 ก.ย. 31 | G10: 990 | H10: ส่วนการโยธา/งานไฟฟ้าสาธารณะ | K10: / | O10: ขอจำหน่าย
A11: 5 | B11: โคมไฟฟ้า ขนาด 2X40W | C11: 082 | D11: 31 | E11: 0020 | F11: 8 ก.ย. 31 | G11: 990 | H11: ส่วนการโยธา/งานไฟฟ้าสาธารณะ | K11: / | O11: ขอจำหน่าย
A12: 6 | B12: โคมไฟฟ้า ขนาด 2X40W | C12: 082 | D12: 31 | E12: 0021 | F12: 8 ก.ย. 31 | G12: 990 | H12: ส่วนการโยธา/งานไฟฟ้าสาธารณะ | K12: / | O12: ขอจำหน่าย
A13: 7 | B13: โคมไฟฟ้า ขนาด 2X40W | C13: 082 | D13: 31 | E13: 0022 | F13: 8 ก.ย. 31 | G13: 990 | H13: ส่วนการโยธา/งานไฟฟ้าสาธารณะ | K13: / | O13: ขอจำหน่าย
A14: 8 | B14: โคมไฟฟ้า ขนาด 2X40W | C14: 082 | D14: 31 | E14: 0023 | F14: 8 ก.ย. 31 | G14: 990 | H14: ส่วนการโยธา/งานไฟฟ้าสาธารณะ | K14: / | O14: ขอจำหน่าย
A15: 9 | B15: โคมไฟฟ้า ขนาด 2X40W | C15: 082 | D15: 31 | E15: 0024 | F15: 8 ก.ย. 31 | G15: 990 | H15: ส่วนการโยธา/งานไฟฟ้าสาธารณะ | K15: / | O15: ขอจำหน่าย
A16: 10 | B16: โคมไฟฟ้า ขนาด 2X40W | C16: 082 | D16: 31 | E16: 0025 | F16: 8 ก.ย. 31 | G16: 990 | H16: ส่วนการโยธา/งานไฟฟ้าสาธารณะ | K16: / | O16: ขอจำหน่าย
A17: 11 | B17: โคมไฟฟ้า ขนาด 2X40W | C17: 082 | D17: 31 | E17: 0026 | F17: 8 ก.ย. 31 | G17: 990 | H17: ส่วนการโยธา/งานไฟฟ้าสาธารณะ | K17: / | O17: ขอจำหน่าย
A18: 12 | B18: โคมไฟฟ้า ขนาด 2X40W | C18: 082 | D18: 31 | E18: 0027 | F18: 8 ก.ย. 31 | G18: 990 | H18: ส่วนการโยธา/งานไฟฟ้าสาธารณะ | K18: / | O18: ขอจำหน่าย
... A206: 200 | B206: โคมไฟฟ้า ขนาด 2X40W | C206: 082 | D206: 31 | E206: 0215 | F206: 8 ก.ย. 31 | G206: 990 | H206: ส่วนการโยธา/งานไฟฟ้าสาธารณะ | K206: / | O206: ขอจำหน่าย
A207: 201 | B207: โคมไฟฟ้าอลูมิเนียมเหล็กหล่อ ขนาด 2X20W | C207: 082 | D207: 35 | E207: 0226 | F207: 9 ก.ค. 35 | G207: 990 | H207: ส่วนการโยธา/งานไฟฟ้าสาธารณะ | K207: / | O207: ขอจำหน่าย
A208: 202 | B208: โคมไฟฟ้าอลูมิเนียมเหล็กหล่อ ขนาด 2X20W | C208: 082 | D208: 35 | E208: 0227 | F208: 9 ก.ค. 35 | G208: 990 | H208: ส่วนการโยธา/งานไฟฟ้าสาธารณะ | K208: / | O208: ขอจำหน่าย
A209: 203 | B209: โคมไฟฟ้าอลูมิเนียมเหล็กหล่อ ขนาด 2X20W | C209: 082 | D209: 35 | E209: 0228 | F209: 9 ก.ค. 35 | G209: 990 | H209: ส่วนการโยธา/งานไฟฟ้าสาธารณะ | K209: / | O209: ขอจำหน่าย
A210: 204 | B210: โคมไฟฟ้าอลูมิเนียมเหล็กหล่อ ขนาด 2X20W | C210: 082 | D210: 35 | E210: 0229 | F210: 9 ก.ค. 35 | G210: 990 | H210: ส่วนการโยธา/งานไฟฟ้าสาธารณะ | K210: / | O210: ขอจำหน่าย
A211: 205 | B211: โคมไฟฟ้าอลูมิเนียมเหล็กหล่อ ขนาด 2X20W | C211: 082 | D211: 35 | E211: 0230 | F211: 9 ก.ค. 35 | G211: 990 | H211: ส่วนการโยธา/งานไฟฟ้าสาธารณะ | K211: / | O211: ขอจำหน่าย
A212: 206 | B212: โคมไฟฟ้าอลูมิเนียมเหล็กหล่อ ขนาด 2X20W | C212: 082 | D212: 35 | E212: 0231 | F212: 9 ก.ค. 35 | G212: 990 | H212: ส่วนการโยธา/งานไฟฟ้าสาธารณะ | K212: / | O212: ขอจำหน่าย
A213: 207 | B213: โคมไฟฟ้าอลูมิเนียมเหล็กหล่อ ขนาด 2X20W | C213: 082 | D213: 35 | E213: 0232 | F213: 9 ก.ค. 35 | G213: 990 | H213: ส่วนการโยธา/งานไฟฟ้าสาธารณะ | K213: / | O213: ขอจำหน่าย
A214: 208 | B214: โคมไฟฟ้าอลูมิเนียมเหล็กหล่อ ขนาด 2X20W | C214: 082 | D214: 35 | E214: 0233 | F214: 9 ก.ค. 35 | G214: 990 | H214: ส่วนการโยธา/งานไฟฟ้าสาธารณะ | K214: / | O214: ขอจำหน่าย
A215: 209 | B215: โคมไฟฟ้าอลูมิเนียมเหล็กหล่อ ขนาด 2X20W | C215: 082 | D215: 35 | E215: 0234 | F215: 9 ก.ค. 35 | G215: 990 | H215: ส่วนการโยธา/งานไฟฟ้าสาธารณะ | K215: / | O215: ขอจำหน่าย
A216: 210 | B216: โคมไฟฟ้าอลูมิเนียมเหล็กหล่อ ขนาด 2X20W | C216: 082 | D216: 35 | E216: 0235 | F216: 9 ก.ค. 35 | G216: 990 | H216: ส่วนการโยธา/งานไฟฟ้าสาธารณะ | K216: / | O216: ขอจำหน่าย
A217: 211 | B217: โคมไฟฟ้าอลูมิเนียมเหล็กหล่อ ขนาด 2X20W | C217: 082 | D217: 35 | E217: 0236 | F217: 9 ก.ค. 35 | G217: 990 | H217: ส่วนการโยธา/งานไฟฟ้าสาธารณะ | K217: / | O217: ขอจำหน่าย
A218: 212 | B218: โคมไฟฟ้าอลูมิเนียมเหล็กหล่อ ขนาด 2X20W | C218: 082 | D218: 35 | E218: 0237 | F218: 9 ก.ค. 35 | G218: 990 | H218: ส่วนการโยธา/งานไฟฟ้าสาธารณะ | K218: / | O218: ขอจำหน่าย
... A908: 902 | B908: โคมไฟฟ้า เนชั่นแนล 250W | C908: 082 | D908: 47 | E908: 0939 | F908: 6 ม.ค. 47 | G908: 6634 | H908: ส่วนการโยธา/งานไฟฟ้าสาธารณะ | K908: / | O908: ขอจำหน่าย
A909: 903 | B909: โคมไฟฟ้าพร้อมกับขาโคมขาจับและอุปกร์ เนชั่นแนล 250 W | C909: 082 | D909: 49 | E909: 0940 | F909: 4 พ.ค. 49 | G909: 8410 | H909: ส่วนการโยธา/งานไฟฟ้าสาธารณะ | I909: / | O909: ถ.ทิพย์ช้าง
A910: 904 | B910: โคมไฟฟ้าพร้อมกับขาโคมขาจับและอุปกร์ เนชั่นแนล 250 W | C910: 082 | D910: 49 | E910: 0941 | F910: 4 พ.ค. 49 | G910: 8410 | H910: ส่วนการโยธา/งานไฟฟ้าสาธารณะ | I910: / | O910: ถ.ทิพย์ช้าง
A911: 905 | B911: โคมไฟฟ้าพร้อมกับขาโคมขาจับและอุปกร์ เนชั่นแนล 250 W | C911: 082 | D911: 49 | E911: 0942 | F911: 4 พ.ค. 49 | G911: 8410 | H911: ส่วนการโยธา/งานไฟฟ้าสาธารณะ | I911: / | O911: ถ.ทิพย์ช้าง
A912: 906 | B912: โคมไฟฟ้าพร้อมกับขาโคมขาจับและอุปกร์ เนชั่นแนล 250 W | C912: 082 | D912: 49 | E912: 0943 | F912: 4 พ.ค. 49 | G912: 8410 | H912: ส่วนการโยธา/งานไฟฟ้าสาธารณะ | I912: / | O912: ถ.ทิพย์ช้าง
A913: 907 | B913: โคมไฟฟ้าพร้อมกับขาโคมขาจับและอุปกร์ เนชั่นแนล 250 W | C913: 082 | D913: 49 | E913: 0944 | F913: 4 พ.ค. 49 | G913: 8410 | H913: ส่วนการโยธา/งานไฟฟ้าสาธารณะ | I913: / | O913: ถ.ทิพย์ช้าง
A914: 908 | B914: โคมไฟฟ้าพร้อมกับขาโคมขาจับและอุปกร์ เนชั่นแนล 250 W | C914: 082 | D914: 49 | E914: 0945 | F914: 4 พ.ค. 49 | G914: 8410 | H914: ส่วนการโยธา/งานไฟฟ้าสาธารณะ | I914: / | O914: ถ.ทิพย์ช้าง
A915: 909 | B915: โคมไฟฟ้าพร้อมกับขาโคมขาจับและอุปกร์ เนชั่นแนล 250 W | C915: 082 | D915: 49 | E915: 0946 | F915: 4 พ.ค. 49 | G915: 8410 | H915: ส่วนการโยธา/งานไฟฟ้าสาธารณะ | I915: / | O915: ถ.ทิพย์ช้าง
A916: 910 | B916: โคมไฟฟ้าพร้อมกับขาโคมขาจับและอุปกร์ เนชั่นแนล 250 W | C916: 082 | D916: 49 | E916: 0947 | F916: 4 พ.ค. 49 | G916: 8410 | H916: ส่วนการโยธา/งานไฟฟ้าสาธารณะ | I916: / | O916: ถ.ทิพย์ช้าง
...

Sheet 6. ครุภัณฑ์โฆษณาและเผยแพร่
A1: ทะเบียนรายงานผลการตรวจนับครุภัณฑ์ ประจำปีงบประมาณ 2567
A2: ส่วนการโยธา สำนักช่าง
A3: 6. ครุภัณฑ์โฆษณาและเผยแพร่
A4: ลำดับที่ | B4: รายการ | C4: หมายเลขครุภัณฑ์ | F4: วันเดือนปี | G4: ราคาที่ได้ | H4: สถานที่ใช้งาน | I4: สภาพครุภัณฑ์ | O4: หมายเหตุ
F5: ที่ได้มา | I5: ใช้ได้ | J5: ชำรุด | K5: เสื่อมสภาพ | L5: สูญหาย | M5: เก็บไว้นาน | N5: หมดความจำเป็น
A6: 444 | B6: (จอมอเตอร์)
A7: 1 | B7: จอมอเตอร์ไฟฟ้า 150" เนื้อ MW สัดส่วน 4:3 ซ่อนบนฝ้า | C7: 444 | D7: 62 | E7: 0034 | F7: 5 ก.ย.62 | G7: 21400 | H7: ส่วนการโยธา / ฝ่ายสวนสาธารณะ/ สวนเวียงละกอน | I7: / | R7: /
A8: 2 | B8: จอมอเตอร์ไฟฟ้า 150" เนื้อ MW สัดส่วน 4:3 ซ่อนบนฝ้า | C8: 444 | D8: 62 | E8: 0035 | F8: 5 ก.ย.62 | G8: 21400 | H8: ส่วนการโยธา / ฝ่ายสวนสาธารณะ/ สวนเวียงละกอน | I8: / | R8: /
G9: =SUM(G7:G8) -> 42800
A10: 447 | B10: (โปรเจคเตอร์)
A11: 1 | B11: โปรเจ็คเตอร์หลอด LCD 3000ANSI ความละเอียด 1280x80 พร้อมอุปกรณ์และขาแขวน 43x95 ซม. | C11: 447 | D11: 62 | E11: 0037 | F11: 5 ก.ย.62 | G11: 50584.25 | H11: ส่วนการโยธา /ฝ่ายสวนสาธารณะ/ สวนเวียงละกอน | I11: / | R11: /
A12: 2 | B12: โปรเจ็คเตอร์หลอด LCD 3000ANSI ความละเอียด 1280x80 พร้อมอุปกรณ์และขาแขวน 43x95 ซม. | C12: 447 | D12: 62 | E12: 0038 | F12: 5 ก.ย.62 | G12: 50584.25 | H12: ส่วนการโยธา /ฝ่ายสวนสาธารณะ/ สวนเวียงละกอน | I12: / | R12: /
G13: =SUM(G11:G12) -> 101168.5
A14: 454 | B14: (กล้องวงจรปิด)
A15: 1 | B15: กล้องโทรทัศน์วงจรปิดชนิดเครือข่าย แบบมุมมองคงที่สำหรับติดตั้งภาย | C15: 454 | D15: 64 | E15: 0169 | F15: 21 ก.ย.64 | G15: 16000 | H15: ส่วนการโยธา / งานกำจัดขยะมูลฝอย | I15: / | O15: อาคารบ่อขยะ | R15: /
B16: ในอาคาร ยี่ห้อ Hikvision รุ่น HVS-2CD2721Go-l
A17: 2 | B17: กล้องโทรทัศน์วงจรปิดชนิดเครือข่าย แบบมุมมองคงที่สำหรับติดตั้งภาย | C17: 454 | D17: 64 | E17: 0170 | F17: 21 ก.ย.64 | G17: 16000 | H17: ส่วนการโยธา / งานกำจัดขยะมูลฝอย | I17: / | O17: อาคารบ่อขยะ | R17: /
B18: ในอาคาร ยี่ห้อ Hikvision รุ่น HVS-2CD2721Go-l
A19: 3 | B19: กล้องโทรทัศน์วงจรปิดชนิดเครือข่าย แบบมุมมองคงที่สำหรับติดตั้งภาย | C19: 454 | D19: 64 | E19: 0171 | F19: 21 ก.ย.64 | G19: 16000 | H19: ส่วนการโยธา / งานกำจัดขยะมูลฝอย | I19: / | O19: อาคารบ่อขยะ | R19: /
B20: ในอาคาร ยี่ห้อ Hikvision รุ่น HVS-2CD2721Go-l
A21: 4 | B21: กล้องโทรทัศน์วงจรปิดชนิดเครือข่าย แบบมุมมองคงที่สำหรับติดตั้งภาย | C21: 454 | D21: 64 | E21: 0172 | F21: 21 ก.ย.64 | G21: 16000 | H21: ส่วนการโยธา / งานกำจัดขยะมูลฝอย | I21: / | O21: อาคารบ่อขยะ | R21: /
B22: ในอาคาร ยี่ห้อ Hikvision รุ่น HVS-2CD2721Go-l
A23: 5 | B23: กล้องโทรทัศน์วงจรปิดชนิดเครือข่าย แบบมุมมองคงที่สำหรับติดตั้งภาย | C23: 454 | D23: 64 | E23: 0173 | F23: 21 ก.ย.64 | G23: 16000 | H23: ส่วนการโยธา / งานกำจัดขยะมูลฝอย | I23: / | O23: อาคารบ่อขยะ | R23: /
B24: ในอาคาร ยี่ห้อ Hikvision รุ่น HVS-2CD2721Go-l
A25: 6 | B25: อุปกรณ์บันทึกภาพผ่านเครือข่าย แบบ 8 ช่อง ยี่ห้อ Hikvision รุ่น | C25: 454 | D25: 64 | E25: 0174 | F25: 21 ก.ย.64 | G25: 21000 | H25: ส่วนการโยธา / งานกำจัดขยะมูลฝอย | I25: / | O25: อาคารบ่อขยะ | R25: /
B26: DS-7608NI-K2
A27: 7 | B27: อุปกรณ์กระจายสัญญาณแบบ PoE (PoE 2 Switch) ขนาด 8 ช่อง | C27: 454 | D27: 64 | E27: 0175 | F27: 21 ก.ย.64 | G27: 8000 | H27: ส่วนการโยธา / งานกำจัดขยะมูลฝอย | I27: / | O27: อาคารบ่อขยะ | R27: /
B28: ยี่ห้อ D-Link รุ่น DGS-1210-10P
G29: =SUM(G15:G28) -> 109000
A30: 456 | B30: (เครื่องรับโทรทัศน์)
A31: 1 | B31: โทรทัศน์สีขนาด 25 นิ้ว | C31: 456 | D31: 47 | E31: 0057 | F31: 16 มี.ค.47 | G31: 15000 | H31: ส่วนการโยธา / งานกำจัดขยะมูลฝอย | J31: / | O31: ขอจำหน่าย | P31: 1 | S31: /
A32: 2 | B32: จอทีวี Aconatic ขนาด 43 นิ้ว | C32: 456 | D32: 66 | E32: 0157 | F32: 24162 | G32: 19795 | H32: ส่วนการโยธา /ฝ่ายสวนสาธารณะ/ สวนเวียงละกอน | I32: / | R32: /
G33: =SUM(G30:G32) -> 34795 | R33: =COUNTA(R7:R32) -> 12 | S33: =COUNTA(S7:S32) -> 1 | T33: =COUNTA(T7:T32) -> 0 | U33: =COUNTA(U7:U32) -> 0 | V33: =COUNTA(V7:V32) -> 0 | W33: =COUNTA(W7:W32) -> 0
G34: =G9+G13+G33+G29 -> 287763.5
B36: (ลงชื่อ) ประธานกรรมการ | G36: (ลงชื่อ) | J36: กรรมการ
B37: (นางสาวสุทธินี พูลสวัสดิ์) | H37: (นายอนุพงษ์ คำฟู)
B38: นักวิชาการสุขาภิบาลปฏิบัติการ | H38: วิศวกรสุขาภิบาลปฏิบัติการ
B40: (ลงชื่อ) กรรมการและเลขานุการ
B41: (นายสิทธิพล ธรรมสาร)
B42: นายช่างเครื่องกลชำนาญงาน
...

Sheet 7.ครุภัณฑ์วิทยาศาสตร์ฯ
A1: ทะเบียนรายงานผลการตรวจนับครุภัณฑ์ ประจำปีงบประมาณ 2567
A2: ส่วนการโยธา สำนักช่าง
A3: 7. ครุภัณฑ์วิทยาศาสาตร์การแพทย์
A4: ลำดับที่ | B4: รายการ | C4: หมายเลขครุภัณฑ์ | F4: วันเดือนปี | G4: ราคาที่ได้ | H4: สถานที่ใช้งาน | I4: สภาพครุภัณฑ์ | O4: หมายเหตุ
F5: ที่ได้มา | I5: ใช้ได้ | J5: ชำรุด | K5: เสื่อมสภาพ | L5: สูญหาย | M5: เก็บไว้นาน | N5: หมดความจำเป็น
A6: 201 | B6: (กล้องจุลทรรศน์)
A7: 1 | B7: กล้องจุลทรรศน์ | C7: 201 | D7: 24 | E7: 0002 | F7: 10 มี.ค. 24 | G7: 19500 | H7: ส่วนการโยธา / งานวิเคราะห์คุณภาพน้ำ | I7: / | O7: ตึกช่างสุขาภิบาล | R7: /
A8: 2 | B8: กล้องจุลทรรศน์ | C8: 201 | D8: 67 | E8: 0008 | G8: 145000 | H8: งานแบบแผนและก่อสร้าง/ฝ่ายช่างสุขาภิบาล/ส่วนการโยธา | O8: อจน.
G9: =SUM(G7:G8) -> 164500
A10: 227 | B10: (เครื่องตรวจคุณภาพน้ำ)
A11: 1 | B11: เครื่องตรวจสอบคุณภาพน้ำ เครื่องวัดปริมาณ O2 ที่ละลายในน้ำและวัด | C11: 227 | D11: 44 | E11: 0001 | F11: 5 เม.ย. 44 | G11: 61820 | H11: ส่วนการโยธา / งานวิเคราะห์คุณภาพน้ำ | J11: / | O11: โรงจัดการคุณภาพน้ำ | P11: 1 | S11: /
B12: ค่าความเป็นกรด - ด่าง แบบพกพา (SER NA 00270016 , SER RN 01050118)
A13: 2 | B13: เครื่องตรวจวัดคุณภาพน้ำอัตโนมัติ ยี่ห้อ Commandorสีขาว แบบตู้สถานี | C13: 227 | D13: 52 | E13: 0002 | F13: 8 เม.ย. 52 | G13: 300000 | H13: ส่วนการโยธา / งานวิเคราะห์คุณภาพน้ำ/สุรชาติ | J13: / | O13: ถ.วังขวา | P13: 2 | S13: /
B14: รุ่น Data logger CT-10 | O14: (ตรงข้ามวัดสิงห์ชัย)
G15: =SUM(G11:G13) -> 361820
A16: 289 | B16: (เครื่องชั่ง)
A17: 1 | B17: เครื่องชั่งชนิดละเอียด | C17: 289 | D17: 67 | E17: 0064 | G17: 85000 | H17: งานแบบแผนและก่อสร้าง/ฝ่ายช่างสุขาภิบาล/ส่วนการโยธา | I17: / | O17: อจน. | R17: /
A18: 2 | B18: เครื่องชั่งชนิดหยาบ | C18: 289 | D18: 67 | E18: 0065 | G18: 45000 | H18: งานแบบแผนและก่อสร้าง/ฝ่ายช่างสุขาภิบาล/ส่วนการโยธา | I18: / | O18: อจน. | R18: /
G19: =SUM(G17:G18) -> 130000
A20: 298 | B20: (เครื่องวัดอุณหภูมิ)
A21: 1 | B21: เครื่องวัดอุณหภูมิระบบินฟาเรดทางหน้าผาก | C21: 298 | D21: 64 | E21: 0053 | F21: 29 ม.ค.64 | G21: 2195 | H21: ฝ่ายสวนสาธารณะ/โรงพัสดุ | I21: / | R21: /
A22: 2 | B22: เครื่องวัดอุณหภูมิระบบินฟาเรดทางหน้าผาก | C22: 298 | D22: 64 | E22: 0054 | F22: 29 ม.ค.64 | G22: 2195 | H22: ฝ่ายสวนสาธารณะ/โรงพัสดุ | I22: / | R22: /
A23: 3 | B23: เครื่องวัดอุณหภูมิระบบินฟาเรดทางหน้าผาก | C23: 298 | D23: 64 | E23: 0055 | F23: 29 ม.ค.64 | G23: 2195 | H23: ฝ่ายสวนสาธารณะ/สวนเขลางค์ | I23: / | R23: /
A24: 4 | B24: เครื่องวัดอุณหภูมิอินฟราเรด ชนิดมีขาตั้ง ใช้พลังงานไฟฟ้า | C24: 298 | D24: 64 | E24: 0074 | F24: 30 ธ.ค.65 | G24: 1720 | H24: ส่วนการโยธา | I24: / | O24: ตู้ธุรการ | R24: /
A25: 5 | B25: เครื่องวัดอุณหภูมิอินฟราเรด ชนิดมีขาตั้ง ใช้พลังงานไฟฟ้า | C25: 298 | D25: 64 | E25: 0075 | F25: 30 ธ.ค.65 | G25: 1720 | H25: ส่วนการโยธา | I25: / | O25: ตู้ธุรการ | R25: /
G26: =SUM(G21:G25) -> 10025
A27: 299 | B27: (ครุภัณฑ์วิทยาศาสตร์และการแพทย์)
A28: 1 | B28: อ่างน้ำควบคุมอุณหภูมิ | C28: 299 | D28: 67 | E28: 0001 | G28: 90000 | H28: งานแบบแผนและก่อสร้าง/ฝ่ายช่างสุขาภิบาล/ส่วนการโยธา | I28: / | O28: อจน. | R28: /
G29: =G28 -> 90000 | R29: =COUNTA(R7:R28) -> 9 | S29: =COUNTA(S7:S28) -> 2 | T29: =COUNTA(T7:T28) -> 0 | U29: =COUNTA(U7:U28) -> 0 | V29: =COUNTA(V7:V28) -> 0 | W29: =COUNTA(W7:W28) -> 0
G30: =G9+G15+G26 -> 536345
B32: (ลงชื่อ) ประธานกรรมการ | G32: (ลงชื่อ) | J32: กรรมการ
B33: (นางสาวสุทธินี พูลสวัสดิ์) | H33: (นายอนุพงษ์ คำฟู)
B34: นักวิชาการสุขาภิบาลปฏิบัติการ | H34: วิศวกรสุขาภิบาลปฏิบัติการ
B36: (ลงชื่อ) กรรมการและเลขานุการ
B37: (นายสิทธิพล ธรรมสาร)
B38: นายช่างเครื่องกลชำนาญงาน
B40: งานสวนสาธารณะ | F40: =[8]ฝ่ายสวนสาธารณะ!G11 -> 6585
B41: ฝ่ายช่างสุขาภิบาล | F41: ='[8]สุขาภิบาล งานวิเคราะห์คุณภาพน้ำ'!G15 -> 381320
B42: งานธุรการ | F42: =[8]งานธุการ!G10 -> 3440
F43: =SUM(F40:F42) -> 391345

Sheet 8.ครุภัณฑ์งานบ้านฯ
A1: ทะเบียนรายงานผลการตรวจนับครุภัณฑ์ ประจำปีงบประมาณ 2567
A2: ส่วนการโยธา สำนักช่าง
A3: 8.ครุภัณฑ์งานบ้านงานครัว
A4: ลำดับที่ | B4: รายการ | C4: หมายเลขครุภัณฑ์ | F4: วันเดือนปี | G4: ราคาที่ได้ | H4: สถานที่ใช้งาน | I4: สภาพครุภัณฑ์ | O4: หมายเหตุ
F5: ที่ได้มา | I5: ใช้ได้ | J5: ชำรุด | K5: เสื่อมสภาพ | L5: สูญหาย | M5: เก็บไว้นาน | N5: หมดความจำเป็น
A6: 434 | B6: (ม่านม้วน)
A7: 1 | B7: ม่านม้วนขนาด 1.0x2.05 ซม. สีขาว | C7: 434 | D7: 62 | E7: 0069 | F7: 6 ก.ย.62 | G7: 5125 | H7: ฝ่ายสวนสาธารณะ /สวนเขลางค์ | I7: / | O7: อาคารสุขาภิบาล (เดิม) | R7: /
A8: 2 | B8: ม่านม้วนขนาด 1.0x2.05 ซม. สีขาว | C8: 434 | D8: 62 | E8: 0070 | F8: 6 ก.ย.62 | G8: 5125 | H8: ฝ่ายสวนสาธารณะ /สวนเขลางค์ | I8: / | O8: อาคารสุขาภิบาล (เดิม) | R8: /
A9: 3 | B9: ม่านม้วนขนาด 1.0x2.05 ซม. สีขาว | C9: 434 | D9: 62 | E9: 0071 | F9: 6 ก.ย.62 | G9: 5125 | H9: ฝ่ายสวนสาธารณะ /สวนเขลางค์ | I9: / | O9: อาคารสุขาภิบาล (เดิม) | R9: /
A10: 4 | B10: ม่านม้วนขนาด 1.35x1.35 ซม. สีขาว | C10: 434 | D10: 62 | E10: 0072 | F10: 6 ก.ย.62 | G10: 4556.25 | H10: ฝ่ายสวนสาธารณะ /สวนเขลางค์ | I10: / | O10: อาคารสุขาภิบาล (เดิม) | R10: /
G11: =SUM(G7:G10) -> 19931.25
A12: 439 | B12: ( เครื่องทำน้ำเย็น)
A13: 1 | B13: เครื่องทำน้ำเย็น แบบใช้ขวด | C13: 439 | D13: 40 | E13: 0050 | F13: 27 พ.ย.40 | G13: 3300 | H13: ผ่ายสวนสาธารณะ/โรงพัสดุ | I13: / | R13: /
A14: 2 | B14: เครื่องทำน้ำเย็นแบบใช้ขวด ยี่ห้อ STANDARD | C14: 439 | D14: 44 | E14: 0053 | F14: 22 มี.ค.65 | G14: 3200 | H14: ส่วนการโยธา /งานไฟฟ้าสาธารณะ | I14: / | R14: /
A15: 3 | B15: เครื่องทำน้ำเย็น | C15: 439 | D15: 46 | E15: 0068 | F15: 18 เม.ย.46 | G15: 3200 | H15: ส่วนการโยธา /งานธุรการ | K15: / | O15: ขอจำหน่าย | Q15: 1 | T15: /
A16: 4 | B16: เครื่องทำน้ำเย็น | C16: 439 | D16: 47 | E16: 0073 | F16: 16 มี.ค.47 | G16: 3700 | H16: ส่วนการโยธา /งานธุรการ | K16: / | O16: ขอจำหน่าย | Q16: 2 | T16: /
A17: 5 | B17: เครื่องทำน้ำเย็นแบบใช้ขวด | C17: 439 | D17: 46 | E17: 0066 | F17: 18 เม.ย.46 | G17: 3200 | H17: ส่วนการโยธา/งานบำรุงรักษาทางและสะพาน | I17: / | O17: โอนจากส่วนควบคุมอาคารและผังเมือง สำนักช่าง | P17: รับ ยธ ที่ 565/66 ลว.4 ส.ค.66 | R17: /
G18: =SUM(G13:G17) -> 16600
A19: 441 | B19: (เครื่องตัดหญ้า)
A20: 1 | B20: เครื่องตัดหญ้าข้อแข็ง | C20: 441 | D20: 48 | E20: 0096 | F20: 29 ส.ค. 48 | G20: 9000 | H20: ส่วนการโยธา / งานกำจัดขยะมูลฝอย | J20: / | O20: ขอจำหน่าย | Q20: 1 | S20: /
A21: 2 | B21: เครื่องตัดหญ้าแบบล้อจักรยาน | C21: 441 | D21: 48 | E21: 0098 | F21: 29 ส.ค. 48 | G21: 9700 | H21: ส่วนการโยธา / งานกำจัดขยะมูลฝอย | J21: / | O21: ขอจำหน่าย | Q21: 2 | S21: /
A22: 3 | B22: เครื่องตัดหญ้าแบบสะพาย ยี่ห้อ ฮอนด้า รุ่น UMK435 | C22: 441 | D22: 50 | E22: 0111 | F22: 3 พ.ค. 50 | G22: 9000 | H22: ส่วนการโยธา / งานบำรุงรักษาและซ่อมแซม | I22: / | O22: บ่อหมัก | R22: /
A23: 4 | B23: เครื่องตัดหญ้าแบบสะพาย ยี่ห้อ ฮอนด้า รุ่น UMK435 | C23: 441 | D23: 50 | E23: 0112 | F23: 3 พ.ค. 50 | G23: 9000 | H23: ส่วนการโยธา / งานบำรุงรักษาและซ่อมแซม | I23: / | O23: บ่อหมัก | R23: /
A24: 5 | B24: เครื่องตัดหญ้า ชนิดเข็น 2 ล้อ ยี่ห้อฮอนด้า รุ่น GX160T | C24: 441 | D24: 50 | E24: 0113 | F24: 3 พ.ค. 50 | G24: 9700 | H24: ส่วนการโยธา / งานบำรุงรักษาและซ่อมแซม | I24: / | O24: บ่อหมัก | R24: /
A25: 6 | B25: เครื่องตัดหญ้าแบบสะพาย | C25: 441 | D25: 50 | E25: 0114 | F25: 3 พ.ค. 50 | G25: 9700 | H25: ส่วนการโยธา / งานบำรุงรักษาและซ่อมแซม | I25: / | O25: บ่อหมัก | R25: /
A26: 7 | B26: เครื่องตัดหญ้า 4 ล้อ ยี่ห้อ HONDA | C26: 441 | D26: 50 | E26: 0115 | F26: 3 พ.ค. 50 | G26: 12000 | H26: ส่วนการโยธา / งานบำรุงรักษาและซ่อมแซม | I26: / | O26: บ่อหมัก | R26: /
A27: 8 | B27: เครื่องตัดหญ้าข้อแข็ง แบบสะพาย ยี่ห้อ Honda UMK435T รุ่น GX35 | C27: 441 | D27: 62 | E27: 0152 | F27: 7 ม.ค.62 | G27: 8600 | H27: ฝ่ายสวนสาธารณะ/โรงพัสดุ/ห้องพัสดุ 2 | I27: / | R27: /
A28: 9 | B28: เครื่องตัดหญ้าแบบข้อแข็ง ยี่ห้อ HONDA รุ่น UMK435 | C28: 441 | D28: 64 | E28: 0166 | F28: 14 ก.ย.64 | G28: 9300 | H28: ฝ่ายสวนสาธารณะ/ใช้งานชุดตัดหญ้า | I28: / | R28: /
A29: 10 | B29: เครื่องตัดหญ้าแบบข้อแข็ง ยี่ห้อ HONDA รุ่น UMK435 | C29: 441 | D29: 64 | E29: 0167 | F29: 14 ก.ย.64 | G29: 9300 | H29: ฝ่ายสวนสาธารณะ/ใช้งานชุดตัดหญ้า | I29: / | R29: /
A30: 11 | B30: เครื่องตัดหญ้าแบบข้อแข็ง ยี่ห้อ HONDA รุ่น UMK435 | C30: 441 | D30: 64 | E30: 0168 | F30: 14 ก.ย.64 | G30: 9300 | H30: ฝ่ายสวนสาธารณะ/ใช้งานชุดตัดหญ้า | I30: / | R30: /
A31: 12 | B31: เครื่องตัดหญ้าแบบข้อแข็ง ยี่ห้อ HONDA รุ่น UMK435 | C31: 441 | D31: 64 | E31: 0169 | F31: 14 ก.ย.64 | G31: 9300 | H31: ฝ่ายสวนสาธารณะ/ใช้งานชุดตัดหญ้า | I31: / | R31: /
A32: 13 | B32: เครื่องตัดหญ้าแบบข้อแข็ง ยี่ห้อ HONDA รุ่น UMK435 | C32: 441 | D32: 64 | E32: 0170 | F32: 14 ก.ย.64 | G32: 9300 | H32: ฝ่ายสวนสาธารณะ/ใช้งานชุดตัดหญ้า | I32: / | R32: /
A33: 14 | B33: เครื่องตัดหญ้าแบบข้อแข็ง ยี่ห้อ HONDA รุ่น UMK435 | C33: 441 | D33: 64 | E33: 0171 | F33: 14 ก.ย.64 | G33: 9300 | H33: ฝ่ายสวนสาธารณะ/ใช้งานชุดตัดหญ้า | I33: / | R33: /
A34: 15 | B34: เครื่องตัดหญ้าแบบข้ออ่อน ยี่ห้อ HONDA รุ่น UMR435 | C34: 441 | D34: 64 | E34: 0172 | F34: 14 ก.ย.64 | G34: 10800 | H34: ฝ่ายสวนสาธารณะ/ใช้งานสวนภิรมย์ธาร | I34: / | R34: /
A35: 16 | B35: เครื่องตัดหญ้าแบบข้ออ่อน ยี่ห้อ HONDA รุ่น UMR435 | C35: 441 | D35: 64 | E35: 0173 | F35: 14 ก.ย.64 | G35: 10800 | H35: ฝ่ายสวนสาธารณะ/ใช้งานชุดตัดหญ้า | I35: / | R35: /
A36: 17 | B36: เครื่องตัดหญ้าแบบข้ออ่อน ยี่ห้อ HONDA รุ่น UMR435 | C36: 441 | D36: 64 | E36: 0174 | F36: 14 ก.ย.64 | G36: 10800 | H36: ฝ่ายสวนสาธารณะ/ใช้งานชุดตัดหญ้า | I36: / | R36: /
A37: 18 | B37: เครื่องตัดหญ้าแบบข้ออ่อน ยี่ห้อ HONDA รุ่น UMR435 | C37: 441 | D37: 64 | E37: 0175 | F37: 14 ก.ย.64 | G37: 10800 | H37: ฝ่ายสวนสาธารณะ/ใช้งานชุดตัดหญ้า | I37: / | R37: /
A38: 19 | B38: เครื่องตัดหญ้าแบบข้ออ่อน ยี่ห้อ HONDA รุ่น UMR435 | C38: 441 | D38: 64 | E38: 0176 | F38: 14 ก.ย.64 | G38: 10800 | H38: ฝ่ายสวนสาธารณะ/ใช้งานชุดตัดหญ้า | I38: / | R38: /
... A44: 25 | B44: เครื่องตัดหญ้าแบบล้อจักรยาน ยี่ห้อ HONDA รุ่น GX160 | C44: 441 | D44: 64 | E44: 0182 | F44: 14 ก.ย.64 | G44: 12000 | H44: ฝ่ายสวนสาธารณะ/ใช้งานชุดตัดหญ้า | I44: / | R44: /
A45: 26 | B45: เครื่องตัดหญ้าแบบข้อแข็ง | C45: 441 | D45: 67 | E45: 0203 | F45: 24560 | G45: 8800 | H45: งานกำจัดมูลฝอยและสื่งปฏิกูล/ฝ่ายช่างสุขาภิบาล/ส่วนการโยธา | I45: / | O45: บ่อขยะ | R45: /
...

Sheet 9.ครุภัณฑ์โรงงาน
A1: ทะเบียนรายงานผลการตรวจนับครุภัณฑ์ ประจำปีงบประมาณ 2567
A2: ส่วนการโยธา สำนักช่าง
A3: 9.ครุภัณฑ์โรงงาน
A4: ลำดับที่ | B4: รายการ | C4: หมายเลขครุภัณฑ์ | F4: วันเดือนปี | G4: ราคาที่ได้ | H4: สถานที่ใช้งาน | I4: สภาพครุภัณฑ์ | O4: หมายเหตุ
F5: ที่ได้มา | I5: ใช้ได้ | J5: ชำรุด | K5: เสื่อมสภาพ | L5: สูญหาย | M5: เก็บไว้นาน | N5: หมดความจำเป็น
A6: 059 | B6: (สว่าน สว่านไฟฟ้า)
A7: 1 | B7: สว่านไฟฟ้าเจาะเหล็ก ใช้ดอกสว่าน ขนาด 1/2" ยี่ห้อ MAKITA 1 ตัว | C7: 059 | D7: 43 | E7: 0027 | F7: 7 มี.ค.43 | G7: 2700 | H7: ส่วนการโยธา / ศูนย์เครื่องจักรฯ | I7: / | S7: /
A8: 2 | B8: สว่านกระแทกไร้สาย 2 ระบบ ชนิดปรับแรง | C8: 059 | D8: 59 | E8: 0034 | F8: 9 มี.ค. 59 | G8: 22500 | H8: ส่วนการโยธา / งานบำรุงรักษาอาคารและสถานที่ | I8: / | O8: ช่างอรุณ | S8: /
A9: 3 | B9: สว่านไฟฟ้า ยี่ห้อมากีต้า รุ่น HR4013 กำลังไฟ 1100 | C9: 059 | D9: 62 | E9: 0035 | F9: 13 ธ.ค.61 | G9: 24000 | H9: ส่วนการโยธา / งานบำรุงรักษาและซ่อมแซม | I9: / | S9: /
G10: =SUM(G7:G9) -> 49200
A11: 060 | B11: (ตู้เชื่อมไฟฟ้า)
A12: 1 | B12: แก๊สอซิเทลีน สำเร็จพร้อมเกย์อัด พร้อมอุปกรณ์รวม 7 รายการ 1 ชุด | C12: 060 | D12: 31 | E12: 0002 | F12: 23 ธ.ค.32 | G12: 6920 | H12: ส่วนการโยธา / ศูนย์เครื่องจักรฯ | I12: / | S12: /
A13: 2 | B13: เครื่องเชื่อมเหล็ก 500 แอมป์ ยี่ห้อ พลัง | C13: 060 | D13: 40 | E13: 0012 | F13: 22 พ.ค.40 | G13: 22000 | H13: ส่วนการโยธา / งานบำรุงรักษาอาคารและสถานที่ | I13: / | O13: ห้องเชื่อมเหล็ก | S13: /
A14: 3 | B14: เครื่องเชื่อมไฟฟ้า ยี่ห้อ พลัง(โรงงาน) | C14: 060 | D14: 43 | E14: 0013 | F14: 17 ก.พ. 43 | G14: 21500 | H14: ส่วนการโยธา / งานบำรุงรักษาและซ่อมแซม | I14: / | O14: บ่อหมัก | S14: /
A15: 4 | B15: ตู้เชื่อมไฟฟ้า ขนาด 200 แอมป์ ยี่ห้อ WELPRD สีแดง(โรงงาน) | C15: 060 | D15: 51 | E15: 0014 | F15: 3 ม.ค. 51 | G15: 21500 | H15: ส่วนการโยธา / งานบำรุงรักษาและซ่อมแซม | I15: / | O15: บ่อหมัก | S15: /
A16: 5 | B16: ชุดเชิ่อมและตัดแก๊ส (โรงงาน) | C16: 060 | D16: 55 | E16: 0015 | F16: 25 ก.ค. 55 | G16: 17500 | H16: ส่วนการโยธา / งานบำรุงรักษาและซ่อมแซม | I16: / | O16: บ่อหมัก | S16: /
A17: 6 | B17: ชุดตัดเชิ่อมแก๊ส ยี่ห้อ TANAKA | C17: 060 | D17: 59 | E17: 0016 | F17: 1 เม.ย. 59 | G17: 39400 | H17: ส่วนการโยธา / งานบำรุงรักษาอาคารและสถานที่ | I17: / | O17: ห้องเชื่อมเหล็ก | S17: /
A18: 7 | B18: ตู้เชื่อมไฟฟ้า ระบบอินเวสเตอร์ ยี่ห้อ POWELL | C18: 060 | D18: 60 | E18: 0017 | F18: 30 มี.ค. 60 | G18: 23500 | H18: ส่วนการโยธา / งานบำรุงรักษาอาคารและสถานที่ | I18: / | O18: ห้องเชื่อมเหล็ก | S18: /
A19: 8 | B19: เครื่องเชื่อมไฟฟ้า Longwell ระบบอินเวอร์เตอร์ MMA 170 | C19: 060 | D19: 66 | E19: 0018 | F19: 23 ธ.ค.65 | G19: 10200 | H19: ส่วนการโยธา / งานบำรุงรักษาอาคารและสถานที่ | I19: / | O19: ของงานไฟฟ้าสาธารณะ | S19: /
G20: =SUM(G12:G19) -> 162520
A21: 067 | B21: (เครื่องไสไม้ไฟฟ้า)
A22: 1 | B22: กบไฟฟ้า 5 นิ้ว ยี่ห้อมาร์กีต้า | C22: 067 | D22: 45 | E22: 0016 | F22: 8 ก.ค. 45 | G22: 6300 | H22: ส่วนการโยธา / งานบำรุงรักษาและซ่อมแซม | I22: / | O22: บ่อหมัก | S22: /
G23: =SUM(G22:G22) -> 6300
A24: 068 | B24: (เลื่อย หินเจีย เครื่องเจีย)
A25: 1 | B25: เครื่องเจียร/ตัดแบบมือถือ 7 นิ้ว ยี่ห้อมากีต้า รุ่น LP 1500 | C25: 068 | D25: 45 | E25: 0021 | F25: 1 เม.ย. 45 | G25: 5100 | H25: ส่วนการโยธา / งานบำรุงรักษาและซ่อมแซม | I25: / | O25: บ่อหมัก | S25: /
A26: 2 | B26: เลื่อยกล ยี่ห้อ ฮีโร่ | C26: 068 | D26: 45 | E26: 0022 | F26: 1 เม.ย. 45 | G26: 14500 | H26: ส่วนการโยธา / งานบำรุงรักษาและซ่อมแซม | I26: / | O26: บ่อหมัก | S26: /
A27: 3 | B27: เลื่อยวงเดือนไฟฟ้า 9 นิ้ว ยี่ห้อมากีต้า รุ่น 5900 | C27: 068 | D27: 47 | E27: 0023 | F27: 2 เม.ย. 47 | G27: 6800 | H27: ส่วนการโยธา / งานบำรุงรักษาและซ่อมแซม | I27: / | O27: บ่อหมัก | S27: /
A28: 4 | B28: เลื่อยฉลุไฟฟ้า ขับด้วยมอเตอร์ไฟฟ้า ยี่ห้อมากีต้า รุ่น 4300 | C28: 068 | D28: 47 | E28: 0024 | F28: 2 เม.ย. 47 | G28: 4900 | H28: ส่วนการโยธา / งานบำรุงรักษาและซ่อมแซม | I28: / | O28: บ่อหมัก | S28: /
A29: 5 | B29: เครื่องเจียร/ตัด 4 นิ้ว 570 วัตต์ ยี่ห้อมากีต้า รุ่น 9500 NB | C29: 068 | D29: 52 | E29: 0025 | F29: 17 ก.พ. 52 | G29: 3300 | H29: ส่วนการโยธา /งานบำรุงรักษาและซ่อมแซม | I29: / | O29: บ่อหมัก | S29: /
A30: 6 | B30: เลื่อยยนต์ 25" ยี่ห้อ STIHLS สี่ส้ม-ขาว | C30: 068 | D30: 56 | E30: 0030 | F30: 9 ธ.ค. 56 | G30: 49000 | H30: ส่วนการโยธา / งานสวนสาธารณะ | I30: / | S30: /
G31: =SUM(G25:G30) -> 83600
A32: 074 | B32: (เครื่องอัดจารบี)
A33: 1 | B33: ถังอัดจารบีแบบใช้ความดันลมพร้อมหัวฉีด ขนาดความจุ20 ลิตร ยี่ห้อ RAASM 1 ชุด | C33: 074 | D33: 45 | E33: 0004 | F33: 4 ก.ย.45 | G33: 25680 | H33: ส่วนการโยธา / ศูนย์เครื่องจักรฯ | I33: / | S33: /
A34: 2 | B34: ถังเติมน้ำมันเฟืองท้ายมีเกจ์วัดแบบมีโยก ยี่ห้อ ACTELL รุ่น HO-32 (1 ถัง) | C34: 074 | D34: 45 | E34: 0005 | F34: 6 ก.ย.45 | G34: 13500 | H34: ส่วนการโยธา / ศูนย์เครื่องจักรฯ | I34: / | S34: /
G35: =SUM(G33:G34) -> 39180
A36: 075 | B36: (แม่แรง แท่นไฮโดรลิค)
A37: 1 | B37: แม่แรงตะเข้ ขนาดยกน้ำหนักได้ 5 ตัน | C37: 075-30-0003 | F37: 27 มี.ค.30 | G37: 19500 | H37: ส่วนการโยธา / ศูนย์เครื่องจักรฯ | I37: / | S37: /
A38: 2 | B38: แม่แรงอัดไฮโดรลิคยกเกียร์ จำนวน 1 ชุด | C38: 075-33-0004 | F38: 15 พ.ค.33 | G38: 22000 | H38: ส่วนการโยธา / ศูนย์เครื่องจักรฯ | I38: / | O38: แก้ไขราคาเพิ่มเติมจากกองคลัง | S38: /
A39: 3 | B39: ชุดแท่นอัดไฮโดรลิค ขนาด 1 1/2 ตัน จำนวน 1ชุด | C39: 075-33-0005 | F39: 15 พ.ค.33 | G39: 33000 | H39: ส่วนการโยธา / ศูนย์เครื่องจักรฯ | I39: / | O39: แก้ไขราคาเพิ่มเติมจากกองคลัง | S39: /
A40: 4 | B40: แม่แรงไฮโดรลิค ชนิดจระเข้ ขนาด 10 ตัน 1 ตัว | C40: 075-35-0006 | F40: 11 มี.ค.35 | G40: 28400 | H40: ส่วนการโยธา / ศูนย์เครื่องจักรฯ | I40: / | S40: /
...

Sheet 10.ครุภัณฑ์กีฬา
A1: ทะเบียนรายงานผลการตรวจนับครุภัณฑ์ ประจำปีงบประมาณ 2567
A2: ส่วนการโยธา สำนักช่าง
A3: 10.ครุภัณฑ์กีฬา
A4: ลำดับที่ | B4: รายการ | C4: หมายเลขครุภัณฑ์ | F4: วันเดือนปี | G4: ราคาที่ได้ | H4: สถานที่ใช้งาน | I4: สภาพครุภัณฑ์ | O4: หมายเหตุ
F5: ที่ได้มา | I5: ใช้ได้ | J5: ชำรุด | K5: เสื่อมสภาพ | L5: สูญหาย | M5: เก็บไว้นาน | N5: หมดความจำเป็น
A6: 806 | B6: ( กีฬา)
A7: 1 | B7: บาร์เดี่ยว | C7: 806 | D7: 55 | E7: 0001 | F7: 23 ก.ค. 55 | G7: 14000 | H7: ส่วนการโยธา /ฝ่ายสวนสาธารณะ(สนามเด็กเล่นสวนประตูเวียง) | I7: / | R7: /
A8: 2 | B8: บาร์เดี่ยว 3 ระดับ | C8: 806 | D8: 55 | E8: 0002 | F8: 23 ก.ค. 55 | G8: 27000 | H8: ส่วนการโยธา /ฝ่ายสวนสาธารณะ(สนามเด็กเล่นสวนประตูเวียง) | I8: / | R8: /
A9: 3 | B9: วิดพื้น | C9: 806 | D9: 55 | E9: 0003 | F9: 23 ก.ค. 55 | G9: 9000 | H9: ส่วนการโยธา /ฝ่ายสวนสาธารณะ(สนามเด็กเล่นสวนประตูเวียง) | I9: / | R9: /
A10: 4 | B10: กระโดดข้าม | C10: 806 | D10: 55 | E10: 0004 | F10: 23 ก.ค. 55 | G10: 25000 | H10: ส่วนการโยธา /ฝ่ายสวนสาธารณะ(สนามเด็กเล่นสวนประตูเวียง) | I10: / | R10: /
A11: 5 | B11: ห้อยโหน | C11: 806 | D11: 55 | E11: 0005 | F11: 23 ก.ค. 55 | G11: 72000 | H11: ส่วนการโยธา /ฝ่ายสวนสาธารณะ(สนามเด็กเล่นสวนประตูเวียง) | I11: / | R11: /
A12: 6 | B12: ฝึกกำลังแขน | C12: 806 | D12: 55 | E12: 0006 | F12: 23 ก.ค. 55 | G12: 35000 | H12: ส่วนการโยธา /ฝ่ายสวนสาธารณะ(สนามเด็กเล่นสวนประตูเวียง) | I12: / | R12: /
A13: 7 | B13: ก้าวกระโดด | C13: 806 | D13: 55 | E13: 0007 | F13: 23 ก.ค. 55 | G13: 37000 | H13: ส่วนการโยธา /ฝ่ายสวนสาธารณะ(สนามเด็กเล่นสวนประตูเวียง) | I13: / | R13: /
A14: 8 | B14: บาร์คู่ | C14: 806 | D14: 55 | E14: 0008 | F14: 23 ก.ค. 55 | G14: 18000 | H14: ส่วนการโยธา /ฝ่ายสวนสาธารณะ(สนามเด็กเล่นสวนประตูเวียง) | I14: / | R14: /
A15: 9 | B15: ชุดสะพานระวิง | C15: 806 | D15: 55 | E15: 0009 | F15: 23 ก.ค. 55 | G15: 170000 | H15: ส่วนการโยธา /ฝ่ายสวนสาธารณะ(สนามเด็กเล่นสวนประตูเวียง) | I15: / | R15: /
A16: 10 | B16: ชิงช้า | C16: 806 | D16: 55 | E16: 0012 | F16: 23 ก.ค. 55 | G16: 44000 | H16: ส่วนการโยธา /ฝ่ายสวนสาธารณะ(สนามเด็กเล่นสวนประตูเวียง) | I16: / | R16: /
A17: 11 | B17: คานทรงตัว | C17: 806 | D17: 55 | E17: 0015 | F17: 23 ก.ค. 55 | G17: 8000 | H17: ส่วนการโยธา /ฝ่ายสวนสาธารณะ(สนามเด็กเล่นสวนประตูเวียง) | I17: / | R17: /
A18: 12 | B18: เครื่องจักรยานปั่นเอน ซ้าย-ขวา | C18: 806 | D18: 63 | E18: 0074 | F18: 2 ต.ค.62 | G18: 7950 | H18: ส่วนการโยธา /ฝ่ายสวนสาธารณะ(สวนเขลางค์) | I18: / | R18: /
... A43: 37 | B43: ซิทอัพคู่ | C43: 806 | D43: 63 | E43: 0099 | F43: 2 ต.ค.62 | G43: 12450 | H43: ส่วนการโยธา /ฝ่ายสวนสาธารณะ(สวนเขลางค์) | I43: / | R43: /
G44: =SUM(G7:G43) -> 708909
A45: 807 | B45: (เครื่องออกกำลังกาย(บริหารกล้ามเนื้อ)
A46: 1 | B46: เครื่องนวดหลังคลายกล้ามเนื้อ | C46: 807 | D46: 51 | E46: 0047 | F46: 11 เม.ย.51 | G46: 165000 | H46: ฝ่ายสวนสาธารณะ (สวนสาธารณะเขลางค์) | I46: / | O46: ฝั่งอาคารวัฒนธรรม | R46: /
A47: 2 | B47: เครื่องนั่งปั่นจักรยานอบอุ่นร่างกายท่อนล่าง | C47: 807 | D47: 51 | E47: 0048 | F47: 11 เม.ย.51 | G47: 200000 | H47: ฝ่ายสวนสาธารณะ (สวนสาธารณะเขลางค์) | I47: / | O47: ฝั่งอาคารวัฒนธรรม | R47: /
A48: 3 | B48: เครื่องบริหารหัวไหล่และหน้าอก | C48: 807 | D48: 51 | E48: 0049 | F48: 11 เม.ย.51 | G48: 200000 | H48: ฝ่ายสวนสาธารณะ (สวนสาธารณะเขลางค์) | I48: / | O48: ฝั่งอาคารวัฒนธรรม | R48: /
A49: 4 | B49: เครื่องบิดเอว | C49: 807 | D49: 51 | E49: 0050 | F49: 11 เม.ย.51 | G49: 163000 | H49: ฝ่ายสวนสาธารณะ (สวนสาธารณะเขลางค์) | I49: / | O49: ฝั่งอาคารวัฒนธรรม | R49: /
A50: 5 | B50: เครื่องจักรยานก้าวเดิน | C50: 807 | D50: 51 | E50: 0051 | F50: 11 เม.ย.51 | G50: 200000 | H50: ฝ่ายสวนสาธารณะ (สวนสาธารณะเขลางค์) | I50: / | O50: ฝั่งอาคารวัฒนธรรม | R50: /
A51: 6 | B51: เครื่องบริหารนวดเท้า | C51: 807 | D51: 51 | E51: 0052 | F51: 11 เม.ย.51 | G51: 180000 | H51: ฝ่ายสวนสาธารณะ (สวนสาธารณะเขลางค์) | I51: / | O51: ฝั่งอาคารวัฒนธรรม | R51: /
A52: 7 | B52: เครื่องบริหารแขนและหัวไหล่อบอุ่นร่างกายท่อนบน | C52: 807 | D52: 51 | E52: 0053 | F52: 11 เม.ย.51 | G52: 200000 | H52: ฝ่ายสวนสาธารณะ (สวนสาธารณะเขลางค์) | I52: / | O52: ฝั่งอาคารวัฒนธรรม | R52: /
A53: 8 | B53: เครื่องล้อหมุนบริหารหัวไหล่ | C53: 807 | D53: 51 | E53: 0054 | F53: 11 เม.ย.51 | G53: 190000 | H53: ฝ่ายสวนสาธารณะ (สวนสาธารณะเขลางค์) | I53: / | O53: ฝั่งอาคารวัฒนธรรม | R53: /
A54: 9 | B54: เครื่องบาร์โหนทรงตัว | C54: 807 | D54: 51 | E54: 0055 | F54: 11 เม.ย.51 | G54: 190000 | H54: ฝ่ายสวนสาธารณะ (สวนสาธารณะเขลางค์) | I54: / | O54: ฝั่งอาคารวัฒนธรรม | R54: /
A55: 10 | B55: เครื่องกระดานซิทอัพ | C55: 807 | D55: 51 | E55: 0056 | F55: 11 เม.ย.51 | G55: 160000 | H55: ฝ่ายสวนสาธารณะ (สวนสาธารณะเขลางค์) | I55: / | O55: ฝั่งอาคารวัฒนธรรม | R55: /
A56: 11 | B56: เครื่องฝึกก้าวเดิน | C56: 807 | D56: 51 | E56: 0057 | F56: 11 เม.ย.51 | G56: 150000 | H56: ฝ่ายสวนสาธารณะ (สวนสาธารณะเขลางค์) | I56: / | O56: ฝั่งอาคารวัฒนธรรม | R56: /
A57: 12 | B57: ชุดฝึกก้าวเดิน | C57: 807 | D57: 51 | E57: 0058 | F57: 11 เม.ย.51 | G57: 200000 | H57: ฝ่ายสวนสาธารณะ (สวนสาธารณะเขลางค์) | I57: / | O57: ฝั่งอาคารวัฒนธรรม | R57: /
... A60: 15 | B60: ชุดจักรยานก้าวเดิน | C60: 807 | D60: 51 | E60: 0061 | F60: 11 เม.ย.51 | G60: 200000 | H60: ฝ่ายสวนสาธารณะ (สวนสาธารณะเขลางค์) | I60: / | O60: ฝั่งอาคารวัฒนธรรม | R60: /
A61: 16 | B61: อุปกรณ์ล้อหมุนบริหารไหล่ | C61: 807 | D61: 55 | E61: 0020 | F61: 23 ก.ค. 55 | G61: 47000 | H61: ฝ่ายสวนสาธารณะ(สนามเด็กเล่นสวนประตูเวียง) | I61: / | R61: /
A62: 17 | B62: อุปกรณ์บริหารไหล่และหน้าอก | C62: 807 | D62: 55 | E62: 0021 | F62: 23 ก.ค. 55 | G62: 48000 | H62: ฝ่ายสวนสาธารณะ(สนามเด็กเล่นสวนประตูเวียง) | I62: / | R62: /
A63: 18 | B63: อุปกรณ์จักรยานเดินก้าว | C63: 807 | D63: 55 | E63: 0022 | F63: 23 ก.ค. 55 | G63: 48000 | H63: ฝ่ายสวนสาธารณะ(สนามเด็กเล่นสวนประตูเวียง) | I63: / | R63: /
A64: 19 | B64: อุปกรณ์นวดหลังและขา | C64: 807 | D64: 55 | E64: 0023 | F64: 23 ก.ค. 55 | G64: 38000 | H64: ฝ่ายสวนสาธารณะ(สนามเด็กเล่นสวนประตูเวียง) | I64: / | R64: /
A65: 20 | B65: อุปกรณ์โหนตัว | C65: 807 | D65: 55 | E65: 0024 | F65: 23 ก.ค. 55 | G65: 29000 | H65: ฝ่ายสวนสาธารณะ(สนามเด็กเล่นสวนประตูเวียง) | I65: / | R65: /
A66: 21 | B66: อุปกรณ์บริหารเอว | C66: 807 | D66: 55 | E66: 0025 | F66: 23 ก.ค. 55 | G66: 52000 | H66: ฝ่ายสวนสาธารณะ(สนามเด็กเล่นสวนประตูเวียง) | I66: / | R66: /
...

Sheet 11.ครุภัณฑ์สำรวจ
A1: ทะเบียนรายงานผลการตรวจนับครุภัณฑ์ ประจำปีงบประมาณ 2567
A2: ส่วนการโยธา สำนักช่าง
A3: 11.ครุภัณฑ์สำรวจ
A4: ลำดับที่ | B4: รายการ | C4: หมายเลขครุภัณฑ์ | F4: วันเดือนปี | G4: ราคาที่ได้ | H4: สถานที่ใช้งาน | I4: สภาพครุภัณฑ์ | O4: หมายเหตุ
F5: ที่ได้มา | I5: ใช้ได้ | J5: ชำรุด | K5: เสื่อมสภาพ | L5: สูญหาย | M5: เก็บไว้นาน | N5: หมดความจำเป็น
A6: 051 | B6: (ไม้สตาฟฟ์)
A7: 1 | B7: ไม้สต๊าฟ ยี่ห้อนิคอน (ของแถม) | C7: 051 | D7: 43 | E7: 0003 | F7: 17 ก.พ. 43 | G7: 5000 | H7: ส่วนการโยธา / งานบำรุงรักษาและซ่อมแซม | I7: / | O7: อนุพงษ์ | Q7: /
G8: =SUM(G7) -> 5000
A9: 078 | B9: (กล้องระดับ)
A10: 1 | B10: กล้องระดับยี่ห้อนิคอน อัตโนมัติพร้อมขาตั้ง เลขเครื่อง 211085 | C10: 078 | D10: 43 | E10: 0003 | F10: 17 ก.พ. 43 | G10: 24000 | H10: ส่วนการโยธา / งานบำรุงรักษาและซ่อมแซม | I10: / | O10: อนุพงษ์ | Q10: /
A11: 2 | B11: กล้องระดับอัตโนมัติ (กำลังขยาย 32 เท่า) | C11: 078 | D11: 64 | E11: 0007 | F11: 3 มี.ค.64 | G11: 27900 | H11: ส่วนการโยธา / งานบำรุงรักษาและซ่อมแซม | I11: / | O11: อนุพงษ์ | Q11: /
A12: 3 | B12: กล้องระดับ ขนาดกำลังขยาย 30 เท่า ยี่ห้อ TOPCON รุ่น AT-B2 | C12: 078 | D12: 64 | E12: 0008 | F12: 19 ส.ค.64 | G12: 30600 | H12: ส่วนการโยธา / งานบำรุงรักษาและซ่อมแซม | I12: / | O12: อนุพงษ์ | Q12: /
G13: =SUM(G10:G12) -> 82500
A14: 079 | B14: (เครื่องหาพิกัด)
A15: 1 | B15: เครื่องหาพิกัดด้วยสัญญาณดาวเทียมแบบพกพา | C15: 079 | D15: 64 | E15: 0007 | F15: 19 ส.ค.64 | G15: 24500 | H15: ส่วนการโยธา / งานบำรุงรักษาและซ่อมแซม | I15: / | O15: อนุพงษ์ | Q15: /
A16: 2 | B16: เครื่องหาพิกัดด้วยสัญญาณดาวเทียมแบบพกพา | C16: 079 | D16: 64 | E16: 0008 | F16: 19 ส.ค.64 | G16: 24500 | H16: ส่วนการโยธา / งานบำรุงรักษาและซ่อมแซม | I16: / | O16: อนุพงษ์ | Q16: /
G17: =SUM(G15:G16) -> 49000
G18: =G17+G13+G8 -> 136500 | Q18: =COUNTA(Q7:Q17) -> 6 | R18: =COUNTA(R7:R17) -> 0 | S18: =COUNTA(S7:S17) -> 0 | T18: =COUNTA(T7:T17) -> 0 | U18: =COUNTA(U7:U17) -> 0 | V18: =COUNTA(V7:V17) -> 0
B20: (ลงชื่อ) ประธานกรรมการ | G20: (ลงชื่อ) | J20: กรรมการ
B21: (นางสาวสุทธินี พูลสวัสดิ์) | H21: (นายอนุพงษ์ คำฟู)
B22: นักวิชาการสุขาภิบาลปฏิบัติการ | H22: วิศวกรสุขาภิบาลปฏิบัติการ
B24: (ลงชื่อ) กรรมการและเลขานุการ
B25: (นายสิทธิพล ธรรมสาร)
B26: นายช่างเครื่องกลชำนาญงาน

Sheet 12.ครุภัณฑ์คอมฯ
A1: ทะเบียนรายงานผลการตรวจนับครุภัณฑ์ ประจำปีงบประมาณ 2567
A2: ส่วนการโยธา สำนักช่าง
A3: 12.ครุภัณฑ์คอมพิวเตอร์
A4: ลำดับที่ | B4: รายการ | C4: หมายเลขครุภัณฑ์ | F4: วันเดือนปี | G4: ราคาที่ได้ | H4: สถานที่ใช้งาน | I4: สภาพครุภัณฑ์ | O4: หมายเหตุ
F5: ที่ได้มา | I5: ใช้ได้ | J5: ชำรุด | K5: เสื่อมสภาพ | L5: สูญหาย | M5: เก็บไว้นาน | N5: หมดความจำเป็น
A6: 416 | B6: (เครื่องคอมพิวเตอร์)
A7: 1 | B7: เครื่องคอมพิวเตอร์ ยี่ห้อ WINWAY พร้อมเครื่องปรินเตอร์ ยี่ห้อ SHARP รุ่น AJ-6010 1 ชุด | C7: 416-45-0118 | F7: 24 มิ.ย.45 | G7: 51885 | H7: ส่วนโยธา/งานธุรการ | I7: / | O7: จิราภรณ์ | R7: /
A8: 2 | B8: เครื่องคอมพิวเตอร์ ยี่ห้อ Powell พร้อมเครื่องปริ้นเตอร์ | C8: 416-47-0221 | F8: 21 พ.ค.47 | G8: 47754.1 | H8: ส่วนการโยธา/งานบำบัดน้ำเสีย | I8: / | O8: วิชุดา (ปริ้นชำรุด) | P8: โอน จากงานธุรการวันที่ 3 พ.ย.64 | R8: /
A9: 3 | B9: เครื่องคอมพิวเตอร์ POWELL รุ่น P 4300 CF | C9: 416-47-0222 | F9: 21 พ.ค.47 | G9: 0 | H9: ส่วนโยธา/งานธุรการ | I9: / | O9: ขอจำหน่าย | P9: * ยอดเงินเอามาตัดกับการจำหน่ายจอภาพ 15 สค.61 | R9: /
A10: 4 | B10: เครื่องคอมพิวเตอร์ 1 ชุด | C10: 416-48-0324 | F10: 25 ม.ค. 48 | G10: 27000 | H10: ส่วนการโยธา / งานกำจัดขยะมูลฝอย | I10: / | O10: ธนัญญา | R10: /
A11: 5 | B11: เครื่องคอมฯ CPU HP (ลูกข่าย) | C11: 416-51-0389 | F11: 29 พ.ค.51 | G11: 23400 | H11: ส่วนโยธา/งานธุรการ | I11: / | O11: มธุสร (จ้างเหมา) | R11: /
