Workbook

Sheet ครุภัณฑ์ใหม่2567
A1: ลำดับ | B1: รหัสสินทรัพย์ | C1: *ชนิดสินทรัพย์ | D1: รายละเอียดสินทรัพย์ | E1: *วันที่ได้มา (วว/ดด/ปปปป) | H1: *ราคาสินทรัพย์ (ราคาทุน) (บาท) | I1: *ได้มาโดย | J1: สถานที่ตั้ง | K1: งานที่รับผิดชอบ | L1: หมายเหตุ
C2: ครุภัณฑ์สำนักงาน
C3: เครืองทำลายเอกสาร (470)
A4: 1 | B4: 470-66-0020 | C4: ครุภัณฑ์สำนักงาน | D4: เครืองทำลายเอกสาร ยี่ห้อ IDEAL รุ่น 3104 | E4: 27 | F4: 12 | G4: 2566 | H4: 60000 | I4: ซื้อ/จ้าง | J4: สำนักปลัดเทศบาล | K4: งานบริหารทั่วไป
J5: 60000
C6: เครืองปรับอากาศ (420)
A7: 1 | B7: 420-67-0485 | C7: ครุภัณฑ์สำนักงาน | D7: เครื่องปรับอากาศ แบบติดผนัง Midia 24,000 BTU | E7: 19 | F7: 3 | G7: 2567 | H7: 24900 | I7: รับบริจาค | J7: สำนักปลัดเทศบาล (งานเลขา) | K7: งานบริหารทั่วไป
A8: 2 | B8: 420-67-0489 | C8: ครุภัณฑ์สำนักงาน | D8: เครื่องปรับอากาศแบบติดผนัง Midia 30,000 BTU | E8: 11 | F8: 7 | G8: 2567 | H8: 46900 | I8: ซื้อ/จ้าง | J8: สำนักปลัดเทศบาล | K8: งานบริหารทั่วไป | L8: 52003/1404
A9: 3 | B9: 420-66-0468 | C9: ครุภัณฑ์สำนักงาน | D9: เครื่องปรับอากาศแบบแยกส่วน ขนาด 30,000 BTU | E9: 18 | F9: 12 | G9: 2566 | H9: 47200 | I9: ซื้อ/จ้าง | J9: สำนักปลัดเทศบาล | K9: งานบริหารทั่วไป | L9: 52003/100
A10: 4 | B10: 420-66-0467 | C10: ครุภัณฑ์สำนักงาน | D10: เครื่องปรับอากาศแบบแยกส่วน ขนาด 18,000 BTU | E10: 18 | F10: 12 | G10: 2566 | H10: 33500 | I10: ซื้อ/จ้าง | J10: สำนักปลัดเทศบาล | K10: งานบริหารทั่วไป | L10: 52003/100
A11: 5 | B11: 420-66-0463 | C11: ครุภัณฑ์สำนักงาน | D11: เครื่องปรับอากาศแบบแยกส่วนขนาด 36,167 BTU | E11: 15 | F11: 11 | G11: 2566 | H11: 53600 | I11: ซื้อ/จ้าง | J11: สำนักปลัดเทศบาล | K11: งานบริหารทั่วไป | L11: 52003/119
A12: 6 | B12: 420-66-0464 | C12: ครุภัณฑ์สำนักงาน | D12: เครื่องปรับอากาศแบบแยกส่วนขนาด 30,026 BTU | E12: 15 | F12: 11 | G12: 2566 | H12: 47200 | I12: ซื้อ/จ้าง | J12: สำนักปลัดเทศบาล | K12: งานบริหารทั่วไป | L12: 52003/118
J13: 253300
C14: ตู้ (406)
A15: 1 | B15: 406-66-1398 | C15: ครุภัณฑ์สำนักงาน | D15: ตู้ไม้บานเปิด 6 บานประตู 180x40x165 ซม. | E15: 17 | F15: 12 | G15: 2566 | H15: 27000 | I15: ซื้อ/จ้าง | J15: สำนักปลัดเทศบาล (ห้องรองกิตติธัช) | K15: งานบริหารทั่วไป | L15: 52003/127
A16: 2 | B16: 406-66-1398 | C16: ครุภัณฑ์สำนักงาน | D16: ตู้เก็บเอกสารสำนักงานชนิดรางเลื่อน ยี่ห้อ TAIYO ครุภัณฑ์มากับโครงการปรับปรุง อาคาร B ตลาดเทศบาล 4 เพื่อเป็นอาคารเก็บพัสดุกลาง สัญญาจ้างก่อสร้าง เลขที่ 17/2566 ลว.17 ก.ค. 2566 มูลค่าก่อสร้างจำวนเงินทั้งสิ้น 2,484,000 บาท | E16: 15 | F16: 11 | G16: 2566 | H16: 101650 | I16: ซื้อ/จ้าง | J16: สำนักปลัด (ฝ่ายทะเบียนราษฯ) | K16: งานบริหารทั่วไป
A17: 3 | B17: 406-66-1398 | C17: ครุภัณฑ์สำนักงาน | D17: ตู้เก็บเอกสารสำนักงานชนิดรางเลื่อน ยี่ห้อ TAIYO ครุภัณฑ์มากับโครงการปรับปรุง อาคาร B ตลาดเทศบาล 4 เพื่อเป็นอาคารเก็บพัสดุกลาง สัญญาจ้างก่อสร้าง เลขที่ 17/2566 ลว.17 ก.ค. 2566 มูลค่าก่อสร้างจำวนเงินทั้งสิ้น 2,484,000 บาท | E17: 15 | F17: 11 | G17: 2566 | H17: 101650 | I17: ซื้อ/จ้าง | J17: สำนักปลัด (ฝ่ายทะเบียนราษฯ) | K17: งานบริหารทั่วไป
J18: 230300
C19: โต๊ะ (400)
A20: 1 | B20: 400-66-6966 | C20: ครุภัณฑ์สำนักงาน | D20: โต๊ะทำงานผู้บริหารแบบตัวแอล ขนาด 180x160x75 ซม. ทำจากไม้พาร์ติเคิล แผ่นพื้นบนโต๊ะเคลือบลามีน มีลิ้นชักด้านข้าง 9 ลิ้นชัก | E20: 10 | F20: 10 | G20: 2566 | H20: 14000 | I20: ซื้อ/จ้าง | J20: สำนักปลัด (ห้องรองกิตติธัช) | K20: งานบริหารทั่วไป | L20: 52003/127
J21: 14000
C22: ชุดรับแขก (403)
A23: 1 | B23: 403-66-0202 | C23: ครุภัณฑ์สำนักงาน | D23: ชุดรับแขก โครงไม้เบาะหนัง ประกอบด้วย โซฟา 1 ที่นั่ง 80x84x84 ซม. 1ตัว โซฟา 2 ที่นั่ง 145x84x84 ซม. 2ตัว โต๊ะกลางหน้ากระจก 110x55x40 จำนวน 1 ตัว | E23: 10 | F23: 10 | G23: 2566 | H23: 34500 | I23: ซื้อ/จ้าง | J23: สำนักปลัด (ห้องรองกิตติธัช) ชั้น 4 | K23: งานบริหารทั่วไป | L23: 52003/127
J24: 34500
J25: =SUM(J4:J24) -> 592100
C26: ครุภัณฑ์ยานพาหนะและขนส่ง
C27: รถบรรทุก (006)
A28: 1 | B28: 006-67-0018 | C28: ครุภัณฑ์ยานพาหนะและขนส่ง | D28: รถบรรทุกดีเซลขนาด 6 ตัน 6ล้อ ปริมาตรกรบอกสูบ 7684 ซีซี แบบบรรทุกน้ำ 6,000 ลิตร | E28: 19 | F28: 9 | G28: 2567 | H28: 2100000 | I28: ซื้อ/จ้าง | J28: สำนักปลัดเทศบาล | K28: งานป้องกันและบรรเทาสาธารณภัย
J29: 2100000
C30: เรือท้องแบน (029)
A31: 1 | B31: 029-66-0002 | C31: ครุภัณฑ์ยานพาหนะและขนส่ง | D31: เรือท้องแบน อลูมิเนียม ขนาด 16 ฟุต พร้อมเครื่องยนต์ | E31: 25 | F31: 9 | G31: 2566 | H31: 480000 | I31: ซื้อ/จ้าง | J31: สำนักปลัด | K31: งานป้องกันและบรรเทาสาธารณภัย
J32: 480000
J33: =SUM(J28:J32) -> 2580000
C34: ครุภัณฑ์โรงงาน
C35: สว่านไฟฟ้า (059)
A36: 1 | B36: 059-67-00374 | C36: ครุภัณฑ์โรงงาน | D36: สว่านไฟฟ้าไร้สาย ยี่ห้อ Makita สามารถปรับได้ 3 โหมด ความเร็วรอบตัวเปล่า (rpm) สูง 0-1, 900 ต่ำ 0-500. แรงบิดส่งสูงสุด (torque) Hard/Soft : 50/27 นิวตันเมตร (ของแท้) - สว่านไฟฟ้าไร้สาย จำนวน 1 เครื่อง - แบตเตอรี่ลิเธียม ขนาด 18V /6.0Ah จำนวน 2 ก้อน | E36: 10 | F36: 1 | G36: 2567 | H36: 14980 | I36: ซื้อ/จ้าง | J36: สำนักปลัด | K36: งานบริหารทั่วไป | L36: 52003/102
J37: 14980
C38: ครุภัณฑ์คอมพิวเตอร์
C39: เครื่องพิมพ์ (416)
A40: 1 | B40: 416-67-2442 | C40: ครุภัณฑ์คอมพิวเตอร์ | D40: เครื่องพิมพ์ Multifunction เลเซอร์ หรือ LED cannon | E40: 1 | F40: 7 | G40: 2567 | H40: 16000 | I40: ซื้อ/จ้าง | J40: สำนักปลัดเทศบาล | K40: งานบริหารทั่วไป | L40: 52003/1301 | M40: หมายเหตุเลขเดิม 416-67-2505
...

Sheet ตัดจำหน่าย2567
A1: รายละเอียดชำรุด/เสื่อมสภาพ/หมดความจำเป็น สำนักปลัดเทศบาล
A2: ณ กันยายน 2566
A4: ลำดับ | B4: รายการ | C4: รหัสครุภัณฑ์ | D4: วัน เดือน ปี | E4: ราคาที่ได้มา | F4: สภาพครุภัณฑ์
A5: ที่ | D5: ที่ได้มา | F5: สถานที่ใช้งาน | G5: ใช้ได้ | H5: ชำรุด | I5: เสื่อม | J5: สูญหาย | K5: เก็บ | L5: หมดความ | M5: หมายเหตุ
I6: สภาพ | K6: ไว้นาน | L6: จำเป็น
B7: ครุภัณฑ์สำนักงาน
B8: โต๊ะ (400)
A9: 1 | B9: ชุดโต๊ะประชุม(ต่อโค้ง)#3 | C9: 400-30-1910 | D9: 230344 | E9: 3824 | F9: ฝ่ายประสานงาน อปท. | H9: ∕ | M9: ไม่มีมูลค่า
A10: 2 | B10: ชุดโต๊ะประชุม(ต่อโค้ง)#4 | C10: 400-30-1911 | D10: 230340 | E10: 3824 | F10: ฝ่ายประสานงาน อปท. | H10: ∕ | M10: ไม่มีมูลค่า
A11: 3 | B11: โต๊ะประชุม | C11: 400-62-6583 | D11: 241872 | E11: 3380 | F11: ฝ่ายบริหารงานทั่วไป | H11: ∕ | M11: 1478.75
B13: เก้าอี้ (401)
A14: 4 | B14: เก้าอี้ฟังบรรยายมีแป้นรองเขียน | C14: 401-30-1151 | D14: 230340 | E14: 3000 | F14: ฝ่ายประสานงาน อปท. | H14: ∕ | M14: ไม่มีมูลค่า
A15: 5 | B15: เก้าอี้ฟังบรรยายมีแป้นรองเขียน | C15: 401-30-1152 | D15: 230340 | E15: 3000 | F15: ฝ่ายประสานงาน อปท. | H15: ∕ | M15: ไม่มีมูลค่า
A16: 6 | B16: เก้าอี้ฟังบรรยายมีแป้นรองเขียน | C16: 401-30-1153 | D16: 230340 | E16: 3000 | F16: ฝ่ายประสานงาน อปท. | H16: ∕ | M16: ไม่มีมูลค่า
A17: 7 | B17: เก้าอี้ฟังบรรยายมีแป้นรองเขียน | C17: 401-30-1154 | D17: 230340 | E17: 3000 | F17: ฝ่ายประสานงาน อปท. | H17: ∕ | M17: ไม่มีมูลค่า
A18: 8 | B18: เก้าอี้ฟังบรรยายมีแป้นรองเขียน | C18: 401-30-1155 | D18: 230340 | E18: 3000 | F18: ฝ่ายประสานงาน อปท. | H18: ∕ | M18: ไม่มีมูลค่า
A19: 9 | B19: เก้าอี้ฟังบรรยายมีแป้นรองเขียน | C19: 401-30-1156 | D19: 230340 | E19: 3000 | F19: ฝ่ายประสานงาน อปท. | H19: ∕ | M19: ไม่มีมูลค่า
A20: 10 | B20: เก้าอี้ฟังบรรยายมีแป้นรองเขียน | C20: 401-30-1157 | D20: 230340 | E20: 3000 | F20: ฝ่ายประสานงาน อปท. | H20: ∕ | M20: ไม่มีมูลค่า
A21: 11 | B21: เก้าอี้ฟังบรรยายมีแป้นรองเขียน | C21: 401-30-1159 | D21: 230340 | E21: 3000 | F21: ฝ่ายประสานงาน อปท. | H21: ∕ | M21: ไม่มีมูลค่า
A22: 12 | B22: เก้าอี้คณะผู้บริหารเทศบาล | C22: 401-30-1184 | D22: 230340 | E22: 1400 | F22: ฝ่ายประสานงาน อปท. | H22: ∕ | M22: ไม่มีมูลค่า
A23: 13 | B23: เก้าอี้คณะผู้บริหารเทศบาล | C23: 401-30-1187 | D23: 230135 | E23: 1400 | F23: ฝ่ายประสานงาน อปท. | H23: ∕ | M23: ไม่มีมูลค่า
A24: 14 | B24: เก้าอี้เบาะนวมขาเหล็กชุบเก้าอี้แบบมีที่วางแขน | C24: 401-37-1739 | D24: 232692 | E24: 900 | F24: งานป้องกัน | H24: ∕ | M24: ไม่มีมูลค่า
A25: 15 | B25: เก้าอี้ผู้บริหารเบาะหนังปนฝ้าย | C25: 401-40-2867 | D25: 233998 | E25: 2580 | F25: ฝ่ายประสานงาน อปท. | H25: ∕ | M25: ไม่มีมูลค่า
... A35: 25 | B35: เก้าอี้ประชุม(สีเขียว)#9 | C35: 401-53-7912 | D35: 238574 | E35: 2200 | F35: ฝ่ายประสานงาน อปท. | H35: ∕ | M35: ไม่มีมูลค่า
B37: เครื่องพิมพ์ดีด (414)
A38: 26 | B38: เครื่องพิมพ์ดีด (หน่วย 1) | C38: 414-35-0067 | D38: 232381 | E38: 8600 | F38: งานป้องกันฯ | J38: ∕ | M38: ไม่สามารถประเมินได้
A39: 27 | B39: เครื่องพิมพ์ดีด | C39: 401-53-7912 | D39: 238574 | E39: 2200 | F39: งานป้องกันฯ | J39: ∕ | M39: ไม่สามารถประเมินได้
B41: เครื่องปรับอากาศ (420)
A42: 28 | B42: เครื่องปรับอากาศ | C42: 420-35-0044 | D42: 232150 | E42: 90000 | F42: งานป้องกันฯ | H42: ∕ | M42: ไม่มีมูลค่า
A43: 29 | B43: เครื่องปรับอากาศแบบแยกส่วน | C43: 420-40-0096 | D43: 234093 | E43: 45000 | F43: งานป้องกันฯ | H43: ∕ | M43: ไม่มีมูลค่า
A44: 30 | B44: เครื่องปรับอากาศแบบแยกส่วน | C44: 420-40-0097 | D44: 234093 | E44: 45000 | F44: งานป้องกันฯ | H44: ∕ | M44: ไม่มีมูลค่า
A45: 31 | B45: เครื่องปรับอากาศ | C45: 420-40-0166 | D45: 233804 | E45: 27000 | F45: ฝ่ายบริหารงานทั่วไป | H45: ∕ | M45: ไม่มีมูลค่า
B47: พัดลมดูดอากาศ(432)
A48: 32 | B48: พัดลมดูดอากาศ | C48: 432-53-0741 | D48: 19625 | E48: 1250 | F48: ฝ่ายประสานงาน อปท. | H48: ∕ | M48: จำหน่ายพร้อมการปรับปรุงห้อง
A49: 33 | B49: พัดลมดูดอากาศ | C49: 432-53-0742 | D49: 19625 | E49: 1250 | F49: ฝ่ายประสานงาน อปท. | H49: ∕ | M49: จำหน่ายพร้อมการปรับปรุงห้อง
B51: ครุภัณฑ์ยานพาหนะและขนส่ง
A52: 34 | B52: รถยนต์ดับเพลิง ยี่ห้ออีซูซุ ชนิดมีถังน้ำ ในตัว 6 ล้อ 145 แรงม้า เครื่องยนต์ ดีเซล หมายเลขเครื่องยนต์ 6BB1-219563 หมายเลขตัวถังรถ 3406314 (ลป น 7016) #10 | C52: 004-37-0012 | D52: 228459 | E52: 1109836 | F52: งานป้องกันฯ | M52: ไม่สามารถประเมินราคาได้
A53: 35 | B53: รถยนต์ดับเพลิง ยี่ห้ออีซูซุ ชนิดมีถังน้ำ ในตัว 6 ล้อ 160 แรงม้า เครื่องยนต์ ดีเซล หมายเลขเครื่องยนต์ 6D14-722751 หมายเลขตัวถังรถ FK415F-A31059 (ลป น 7740) #15 | C53: 004-35-0010 | D53: 232258 | E53: 1142774 | F53: งานป้องกันฯ | M53: ไม่สามารถประเมินราคาได้
A54: 36 | B54: รถยนต์ดับเพลิง ยี่หเอมิตซูบิชิ ชนิดมีถังน้ำในตัว 6 ล้อ 160 แรงม้า จุน้ำ 2,000 ลิตร เครื่องยนต์ดีเซล แบบ FK415FFREDH1 เลขเครื่อง 6D14-735088 เลขตัวถัง FK415F-A3247 6สูบ สีแดง พร้อมอุปกรณ์ เลขทะเบียน ลป ผ 5981 | C54: 004-37-0012 | D54: 233018 | E54: 1142774 | F54: งานป้องกันฯ | M54: ไม่สามารถประเมินราคาได้
A55: 37 | B55: รถจักรยานยนต์สายตรวจ KAWASAKI ทะเบียน กษน 46 ลป | C55: 024-43-0069 | D55: 235060 | E55: 86000 | F55: งานเทศกิจ | H55: ∕ | M55: ไม่สามารถประเมินราคาได้
...

Sheet โอน2567
A1: รายละเอียดครุภัณฑ์ของสำนักปลัดเทศบาล (รับโอน)
A4: ลำดับที่ | B4: เลขที่หนังสือ | C4: รายการ | D4: หมวดครุภัณฑ์ | E4: รหัสครุภัณฑ์ | F4: วัน | G4: เดือน | H4: ปี | I4: ราคาที่ได้มา | J4: หน่วยงาน | K4: ได้มาจาก | L4: แหล่งที่มา
A5: 1 | B5: ลป52004/531 | C5: เครื่องปรับอากาศแบบแยกส่วน ชนิดตั้งพื้นหรือแขวนขนาด 31,124 บีทียู | D5: ครุภัณฑ์สำนักงาน | E5: 420-58-0202 | F5: 28 | G5: ก.ย. | H5: 2558 | I5: 36400 | J5: สำนักปลัดเทศบาล | K5: ส่วนการโยธา สำนักช่าง | L5: เงินงบประมาณ
A6: 2 | B6: ลป52004/531 | C6: เครื่องปรับอากาศแบบแยกส่วน ชนิดตั้งพื้นหรือแขวนขนาด 31,124 บีทียู | D6: ครุภัณฑ์สำนักงาน | E6: 420-58-0202 | F6: 28 | G6: ก.ย. | H6: 2558 | I6: 36400 | J6: สำนักปลัดเทศบาล | K6: ส่วนการโยธา สำนักช่าง | L6: เงินงบประมาณ
A7: 3 | B7: ลป52004/531 | C7: เครื่องปรับอากาศแบบแยกส่วน ชนิดตั้งพื้นหรือแขวนขนาด 31,124 บีทียู | D7: ครุภัณฑ์สำนักงาน | E7: 420-58-0202 | F7: 28 | G7: ก.ย. | H7: 2558 | I7: 36400 | J7: สำนักปลัดเทศบาล | K7: ส่วนการโยธา สำนักช่าง | L7: เงินงบประมาณ
A8: 4 | B8: ลป52004/531 | C8: เครื่องปรับอากาศแบบแยกส่วน ชนิดตั้งพื้นหรือแขวนขนาด 31,124 บีทียู | D8: ครุภัณฑ์สำนักงาน | E8: 420-58-0202 | F8: 28 | G8: ก.ย. | H8: 2558 | I8: 36400 | J8: สำนักปลัดเทศบาล | K8: ส่วนการโยธา สำนักช่าง | L8: เงินงบประมาณ
A9: 5 | B9: ลป52006/018 | C9: เครื่องปรับอากาศแบบฝังฝ้าเพดาน FCU | D9: ครุภัณฑ์สำนักงาน | E9: 420-67-0469 | F9: 21 | G9: 12 | H9: 2566 | I9: 79277.4 | J9: งานธุรการ สป. (อาคารศูนย์เยาวชน โฮงละกอน) | K9: สำนักการศึกษา | L9: เงินงบประมาณ
A10: 6 | B10: ลป52006/018 | C10: เครื่องปรับอากาศแบบฝังฝ้าเพดาน FCU | D10: ครุภัณฑ์สำนักงาน | E10: 420-67-0470 | F10: 21 | G10: 12 | H10: 2566 | I10: 79277.4 | J10: งานธุรการ สป. (อาคารศูนย์เยาวชน โฮงละกอน) | K10: สำนักการศึกษา | L10: เงินงบประมาณ
A11: 7 | B11: ลป52006/018 | C11: เครื่องปรับอากาศแบบฝังฝ้าเพดาน FCU | D11: ครุภัณฑ์สำนักงาน | E11: 420-67-0471 | F11: 21 | G11: 12 | H11: 2566 | I11: 79277.4 | J11: งานธุรการ สป. (อาคารศูนย์เยาวชน โฮงละกอน) | K11: สำนักการศึกษา | L11: เงินงบประมาณ
A12: 8 | B12: ลป52006/018 | C12: เครื่องปรับอากาศแบบฝังฝ้าเพดาน FCU | D12: ครุภัณฑ์สำนักงาน | E12: 420-67-0472 | F12: 21 | G12: 12 | H12: 2566 | I12: 79277.4 | J12: งานธุรการ สป. (อาคารศูนย์เยาวชน โฮงละกอน) | K12: สำนักการศึกษา | L12: เงินงบประมาณ
A13: 9 | B13: ลป52006/018 | C13: เครื่องปรับอากาศแบบฝังฝ้าเพดาน FCU | D13: ครุภัณฑ์สำนักงาน | E13: 420-67-0473 | F13: 21 | G13: 12 | H13: 2566 | I13: 79277.4 | J13: งานธุรการ สป. (อาคารศูนย์เยาวชน โฮงละกอน) | K13: สำนักการศึกษา | L13: เงินงบประมาณ
A14: 10 | B14: ลป52006/018 | C14: เครื่องปรับอากาศแบบฝังฝ้าเพดาน FCU | D14: ครุภัณฑ์สำนักงาน | E14: 420-67-0474 | F14: 21 | G14: 12 | H14: 2566 | I14: 79277.4 | J14: งานธุรการ สป. (อาคารศูนย์เยาวชน โฮงละกอน) | K14: สำนักการศึกษา | L14: เงินงบประมาณ
A15: 11 | B15: ลป52006/018 | C15: เครื่องปรับอากาศแบบฝังฝ้าเพดาน FCU | D15: ครุภัณฑ์สำนักงาน | E15: 420-67-0475 | F15: 21 | G15: 12 | H15: 2566 | I15: 79277.4 | J15: งานธุรการ สป. (อาคารศูนย์เยาวชน โฮงละกอน) | K15: สำนักการศึกษา | L15: เงินงบประมาณ
A16: 12 | B16: ลป52006/018 | C16: เครื่องปรับอากาศแบบฝังฝ้าเพดาน FCU | D16: ครุภัณฑ์สำนักงาน | E16: 420-67-0476 | F16: 21 | G16: 12 | H16: 2566 | I16: 79277.4 | J16: งานธุรการ สป. (อาคารศูนย์เยาวชน โฮงละกอน) | K16: สำนักการศึกษา | L16: เงินงบประมาณ
A17: 13 | B17: ลป52006/018 | C17: เครื่องปรับอากาศแบบฝังฝ้าเพดาน FCU | D17: ครุภัณฑ์สำนักงาน | E17: 081-67-0041 | F17: 21 | G17: 12 | H17: 2566 | I17: 1712 | J17: งานธุรการ สป. (อาคารศูนย์เยาวชน โฮงละกอน) | K17: สำนักการศึกษา | L17: เงินงบประมาณ
A18: 14 | B18: ลป52006/018 | C18: เครื่องปรับอากาศแบบฝังฝ้าเพดาน FCU | D18: ครุภัณฑ์สำนักงาน | E18: 081-67-0042 | F18: 21 | G18: 12 | H18: 2566 | I18: 1712 | J18: งานธุรการ สป. (อาคารศูนย์เยาวชน โฮงละกอน) | K18: สำนักการศึกษา | L18: เงินงบประมาณ
A19: 15 | B19: ลป52006/018 | C19: เครื่องปรับอากาศแบบฝังฝ้าเพดาน FCU | D19: ครุภัณฑ์สำนักงาน | E19: 081-67-0038 | F19: 21 | G19: 12 | H19: 2566 | I19: 1619 | J19: งานธุรการ สป. (อาคารศูนย์เยาวชน โฮงละกอน) | K19: สำนักการศึกษา | L19: เงินงบประมาณ
A20: 16 | B20: ลป52006/018 | C20: เครื่องปรับอากาศแบบฝังฝ้าเพดาน FCU | D20: ครุภัณฑ์สำนักงาน | E20: 081-67-0039 | F20: 21 | G20: 12 | H20: 2566 | I20: 10400 | J20: งานธุรการ สป. (อาคารศูนย์เยาวชน โฮงละกอน) | K20: สำนักการศึกษา | L20: เงินงบประมาณ
... A52: 48 | B52: ลป52006/018 | C52: ไฟฉุกเฉิน Emergency LED | D52: ครุภัณฑ์ไฟฟ้าและวิทยุ | E52: 487-67-0053 | F52: 21 | G52: 12 | H52: 2566 | I52: 1520 | J52: งานธุรการ สป. (อาคารศูนย์เยาวชน โฮงละกอน) | K52: สำนักการศึกษา | L52: เงินงบประมาณ
A53: 49 | B53: ลป52004/493 | C53: รถยนต์กระบะ บธ9399 | D53: ครุภัณฑ์ยานพาหนะ | E53: 002-45-0053 | F53: 5 | G53: 7 | H53: 2545 | I53: 439800 | J53: งานศูนย์รถยนต์กลาง สำนักปลัด | K53: งานควบคุมอาคารและผังเมือง ส่วนการโยธา สำนักช่าง
A54: 50 | B54: ลป52009/752 | C54: คอมพิวเตอร์ (CPU) | D54: ครุภัณฑ์คอมพิวเตอร์ | E54: 416-51-0383 | F54: 29 | G54: 5 | H54: 2551 | I54: 23400 | J54: งานธุรการ สำนักปลัดเทศบาล | K54: งานธุรการ กองการเจ้าหน้าที่
A55: 51 | B55: ลป52009/752 | C55: คอมพิวเตอร์ (CPU) | D55: ครุภัณฑ์คอมพิวเตอร์ | E55: 416-51-0486 | H55: =G55:H59 -> 0 | J55: งานธุรการ สำนักปลัดเทศบาล | K55: งานธุรการ กองการเจ้าหน้าที่
A56: 52 | B56: ลป52009/428 | C56: คอมพิวเตอร์ (CPU) | D56: ครุภัณฑ์คอมพิวเตอร์ | E56: 416-51-0367 | F56: 29 | G56: 4 | H56: 2551 | I56: 23400 | J56: งานธุรการ สำนักปลัดเทศบาล | K56: งานธุรการ กองการเจ้าหน้าที่ | L56: เงินงบประมาณ
A57: 53 | B57: ลป52009/428 | C57: คอมพิวเตอร์ (CPU) | D57: ครุภัณฑ์คอมพิวเตอร์ | E57: 416-51-0473 | F57: 29 | G57: 4 | H57: 2551 | I57: 11600 | J57: งานธุรการ สำนักปลัดเทศบาล | K57: งานธุรการ กองการเจ้าหน้าที่ | L57: เงินงบประมาณ
A58: 54 | B58: ลแ52003/1322 | C58: ลู่วิ่งไฟฟ้า ยี่ฮ้อ Bolzen | D58: ครุภัณฑ์กีฬา | E58: 806-61-0024 | F58: 12 | G58: 7 | H58: 2561 | I58: 40000 | J58: งานป้องกันบรรเทาสาธารณภัย | K58: กองสาธารณสุขและสิ่งแวดล้อม | L58: เงินงบประมาณค้างจ่าย
A59: 55 | B59: ลแ52003/1322 | C59: จักรยานปั่น ยี่ฮ้อ Engineer | D59: ครุภัณฑ์กีฬา | E59: 806-61-0032 | F59: 12 | G59: 7 | H59: 2561 | I59: 14000 | J59: งานป้องกันบรรเทาสาธารณภัย | K59: กองสาธารณสุขและสิ่งแวดล้อม | L59: เงินงบประมาณค้างจ่าย
A60: 56 | B60: ลแ52003/1322 | C60: จักรยานปั่น ยี่ฮ้อ Engineer | D60: ครุภัณฑ์กีฬา | E60: 806-61-0029 | F60: 12 | G60: 7 | H60: 2561 | I60: 14000 | J60: งานรักษาความสงบเรียบร้อย | K60: กองสาธารณสุขและสิ่งแวดล้อม | L60: เงินงบประมาณค้างจ่าย
A61: 57 | B61: ลป.52001/78 | C61: เครื่องปรับอากาศ ยี่ห้อ คูลลสแคว์ ขนาด 25,000 บีทียู | D61: ครุภัณฑ์สำนักงาน | E61: 420-59-0257 | F61: 1 | G61: 2 | H61: 2558 | I61: 27000 | J61: สำนักปลัดเทศบาล | K61: สำนักช่าง | L61: เงินรายได้
A62: 58 | B62: ลป.52001/78 | C62: เครื่องปรับอากาศ ยี่ห้อ คูลลสแคว์ ขนาด 25,000 บีทียู | D62: ครุภัณฑ์สำนักงาน | E62: 420-59-0258 | F62: 1 | G62: 2 | H62: 2558 | I62: 27000 | J62: สำนักปลัดเทศบาล | K62: สำนักช่าง | L62: เงินรายได้
A63: 59 | B63: ลป.52001/78 | C63: เครื่องคอมพิวเตอร์ CPU HP COMPAQ DX 2700 | D63: ครุภัณฑ์สำนักงาน | E63: 420-40-0156 | F63: 17 | G63: 2 | H63: 2540 | I63: 30000 | J63: งานป้องกันและบรรเทาสาธารณภัย | K63: กองยุทธศาสตร์ | L63: เงินรายได้
A64: 60 | B64: ลป.52001/78 | C64: จอคอมพิวเตอร์ | D64: ครุภัณฑ์สำนักงาน | E64: 420-40-0160 | F64: 17 | G64: 2 | H64: 2540 | I64: 30000 | J64: งานป้องกันและบรรเทาสาธารณภัย | K64: กองยุทธศาสตร์ | L64: เงินรายได้
I65: =SUM(I5:I64) -> 3280415
A69: รายละเอียดครุภัณฑ์ของสำนักปลัดเทศบาล (โอนออก)
A72: ลำดับที่ | B72: เลขที่หนังสือ | C72: รายการ | D72: หมวดครุภัณฑ์ | E72: รหัสครุภัณฑ์ | F72: วัน | G72: เดือน | H72: ปี | I72: ราคาที่ได้มา | J72: หน่วยงาน | K72: โอนให้ | L72: แหล่งที่มา
A73: 1 | B73: ลป.52001 ทท/782 | C73: เครื่องปรับอากาศแบบแยกส่วนชนิดแขวน 9,000 BTU | E73: 420-54-0154 | F73: 19 | G73: 1 | H73: 2554 | I73: 23831 | J73: งานส่งเสริมการท่องเที่ยว สำนักปลัดเทศบาล | K73: สำนักการศึกษา
A74: 2 | B74: ลป.52001 ทท/782 | C74: เครื่องปรับอากาศแบบแยกส่วนชนิดแขวน 9,000 BTU | E74: 420-54-0155 | F74: 19 | G74: 1 | H74: 2554 | I74: 23831 | J74: งานส่งเสริมการท่องเที่ยว สำนักปลัดเทศบาล | K74: สำนักการศึกษา
A75: 3 | B75: ลป.52001 ทท/782 | C75: เครื่องปรับอากาศแบบแยกส่วนชนิดแขวน 9,000 BTU | E75: 420-54-0156 | F75: 19 | G75: 1 | H75: 2554 | I75: 23831 | J75: งานส่งเสริมการท่องเที่ยว สำนักปลัดเทศบาล | K75: สำนักการศึกษา
A76: 4 | B76: ลป.52001 ทท/782 | C76: เครื่องปรับอากาศแบบแยกส่วนชนิดแขวน 9,000 BTU | E76: 420-54-0157 | F76: 19 | G76: 1 | H76: 2554 | I76: 23831 | J76: งานส่งเสริมการท่องเที่ยว สำนักปลัดเทศบาล | K76: สำนักการศึกษา
A77: 5 | B77: ลป.52001 ทท/782 | C77: เครื่องปรับอากาศแบบแยกส่วนชนิดแขวน 24,000 BTU | E77: 420-54-0158 | F77: 19 | G77: 1 | H77: 2554 | I77: 35420 | J77: งานส่งเสริมการท่องเที่ยว สำนักปลัดเทศบาล | K77: สำนักการศึกษา
A78: 6 | B78: ลป.52001 ทท/782 | C78: เครื่องปรับอากาศแบบแยกส่วนชนิดแขวน 25,000 BTU | E78: 420-54-0159 | F78: 19 | G78: 1 | H78: 2554 | I78: 36000 | J78: งานส่งเสริมการท่องเที่ยว สำนักปลัดเทศบาล | K78: สำนักการศึกษา
...

Sheet ครุภัณฑ์ใหม่2567 ต่ำกว่าเกณฑ์
A1: ลำดับ | B1: รหัสสินทรัพย์ | C1: *ชนิดสินทรัพย์ | D1: รายละเอียดสินทรัพย์ | E1: *วันที่ได้มา (วว/ดด/ปปปป) | H1: *ราคาสินทรัพย์ (ราคาทุน) (บาท) | I1: *ได้มาโดย | J1: สถานที่ตั้ง | K1: งานที่รับผิดชอบ | L1: หมายเหตุ
C2: ครุภัณฑ์สำนักงาน
C3: เก้าอี้ (401)
A4: 1 | B4: 401-67-9939 | C4: ครุภัณฑ์สำนักงาน | D4: เก้าอี้ผู้บริหาร ยี้ห้อ MONO รุ่น AR THUR/H | E4: 18 | F4: 1 | G4: 2567 | H4: 5500 | I4: ซื้อ/จ้าง | J4: สำนักปลัด | K4: งานบริหารทั่วไป | L4: 52003/252
A5: 2 | B5: 401-67-9940 | C5: ครุภัณฑ์สำนักงาน | D5: เก้าอี้อเนกประสงค์ ยี่ห้อ TK รุ่น LK-16 | E5: 18 | F5: 1 | G5: 2567 | H5: 1100 | I5: ซื้อ/จ้าง | J5: สำนักปลัด | K5: งานบริหารทั่วไป | L5: 52003/252
A6: 3 | B6: 401-67-9941 | C6: ครุภัณฑ์สำนักงาน | D6: เก้าอี้อเนกประสงค์ ยี่ห้อ TK รุ่น LK-16 | E6: 18 | F6: 1 | G6: 2567 | H6: 1100 | I6: ซื้อ/จ้าง | J6: สำนักปลัด | K6: งานบริหารทั่วไป | L6: 52003/252
A7: 4 | B7: 401-67-9942 | C7: ครุภัณฑ์สำนักงาน | D7: เก้าอี้อเนกประสงค์ ยี่ห้อ TK รุ่น LK-16 | E7: 18 | F7: 1 | G7: 2567 | H7: 1100 | I7: ซื้อ/จ้าง | J7: สำนักปลัด | K7: งานบริหารทั่วไป | L7: 52003/252
A8: 5 | B8: 401-67-9943 | C8: ครุภัณฑ์สำนักงาน | D8: เก้าอี้อเนกประสงค์ ยี่ห้อ TK รุ่น LK-16 | E8: 18 | F8: 1 | G8: 2567 | H8: 1100 | I8: ซื้อ/จ้าง | J8: สำนักปลัด | K8: งานบริหารทั่วไป | L8: 52003/252
A9: 6 | B9: 401-67-9944 | C9: ครุภัณฑ์สำนักงาน | D9: เก้าอี้อเนกประสงค์ ยี่ห้อ TK รุ่น LK-16 | E9: 18 | F9: 1 | G9: 2567 | H9: 1100 | I9: ซื้อ/จ้าง | J9: สำนักปลัด | K9: งานบริหารทั่วไป | L9: 52003/252
A10: 7 | B10: 401-67-9945 | C10: ครุภัณฑ์สำนักงาน | D10: เก้าอี้อเนกประสงค์ ยี่ห้อ TK รุ่น LK-16 | E10: 18 | F10: 1 | G10: 2567 | H10: 1100 | I10: ซื้อ/จ้าง | J10: สำนักปลัด | K10: งานบริหารทั่วไป | L10: 52003/252
A11: 8 | B11: 401-67-9946 | C11: ครุภัณฑ์สำนักงาน | D11: เก้าอี้อเนกประสงค์ ยี่ห้อ TK รุ่น LK-16 | E11: 18 | F11: 1 | G11: 2567 | H11: 1100 | I11: ซื้อ/จ้าง | J11: สำนักปลัด | K11: งานบริหารทั่วไป | L11: 52003/252
A12: 9 | B12: 401-67-9947 | C12: ครุภัณฑ์สำนักงาน | D12: เก้าอี้อเนกประสงค์ ยี่ห้อ TK รุ่น LK-16 | E12: 18 | F12: 1 | G12: 2567 | H12: 1100 | I12: ซื้อ/จ้าง | J12: สำนักปลัด | K12: งานบริหารทั่วไป | L12: 52003/252
A13: 10 | B13: 401-67-9948 | C13: ครุภัณฑ์สำนักงาน | D13: เก้าอี้อเนกประสงค์ ยี่ห้อ TK รุ่น LK-16 | E13: 18 | F13: 1 | G13: 2567 | H13: 1100 | I13: ซื้อ/จ้าง | J13: สำนักปลัด | K13: งานบริหารทั่วไป | L13: 52003/252
A14: 11 | B14: 401-67-9949 | C14: ครุภัณฑ์สำนักงาน | D14: เก้าอี้อเนกประสงค์ ยี่ห้อ TK รุ่น LK-16 | E14: 18 | F14: 1 | G14: 2567 | H14: 1100 | I14: ซื้อ/จ้าง | J14: สำนักปลัด | K14: งานบริหารทั่วไป | L14: 52003/252
A15: 12 | B15: 401-67-9950 | C15: ครุภัณฑ์สำนักงาน | D15: เก้าอี้อเนกประสงค์ ยี่ห้อ TK รุ่น LK-16 | E15: 18 | F15: 1 | G15: 2567 | H15: 1100 | I15: ซื้อ/จ้าง | J15: สำนักปลัด | K15: งานบริหารทั่วไป | L15: 52003/252
... A105: 102 | B105: 401-67-10135 | C105: ครุภัณฑ์สำนักงาน | D105: เก้าอี้สำนักงาน Taiyo รุ่น CA555A สีดำ | E105: 26 | F105: 7 | G105: 2567 | H105: 3500 | I105: ซื้อ/จ้าง | J105: สำนักปลัดเทศบาล | K105: งานบริหารทั่วไป | L105: 52003/99
J106: 119000
C107: ตู้ (406)
A108: 1 | B108: 406-67-1470 | C108: ครุภัณฑ์สำนักงาน | D108: ตู้เหล็กแบบบานเลื่อนกระจก ขนาด120x40x88เซ็นติเมตร | E108: 23 | F108: 4 | G108: 2567 | H108: 4200 | I108: ซื้อ/จ้าง | J108: สำนักปลัดเทศบาล | K108: งานป้องกันและบรรเทาสาธารณภัย
A109: 2 | B109: 406-67-1471 | C109: ครุภัณฑ์สำนักงาน | D109: ตู้เหล็กแบบสองบาน ขนาด 920 x 460 x 1830 เซ็นติเมตร | E109: 23 | F109: 4 | G109: 2567 | H109: 6000 | I109: ซื้อ/จ้าง | J109: สำนักปลัดเทศบาล | K109: งานป้องกันและบรรเทาสาธารณภัย
A110: 3 | B110: 406-66-1423 | C110: ครุภัณฑ์สำนักงาน | D110: ตู้เหล็กแบบ 2 บาน ยี่ห้อ TAIYO ครุภัณฑ์มากับโครงการปรับปรุง อาคาร B ตลาดเทศบาล 4 เพื่อเป็นอาคารเก็บพัสดุกลาง สัญญาจ้างก่อสร้าง เลขที่ 17/2566 ลว.17 ก.ค. 2566 มูลค่าก่อสร้างจำวนเงินทั้งสิ้น 2,484,000 บาท | E110: 15 | F110: 11 | G110: 2566 | H110: 5882 | I110: ซื้อ/จ้าง | J110: สำนักปลัดเทศบาล (งานทะเบียนราษฯ) | K110: งานบริหารทั่วไป
A111: 4 | B111: 406-66-1424 | C111: ครุภัณฑ์สำนักงาน | D111: ตู้เหล็กแบบ 2 บาน ยี่ห้อ TAIYO ครุภัณฑ์มากับโครงการปรับปรุง อาคาร B ตลาดเทศบาล 4 เพื่อเป็นอาคารเก็บพัสดุกลาง สัญญาจ้างก่อสร้าง เลขที่ 17/2566 ลว.17 ก.ค. 2566 มูลค่าก่อสร้างจำวนเงินทั้งสิ้น 2,484,000 บาท | E111: 15 | F111: 11 | G111: 2566 | H111: 5885 | I111: ซื้อ/จ้าง | J111: สำนักปลัดเทศบาล (งานทะเบียนราษฯ) | K111: งานบริหารทั่วไป
A112: 5 | B112: 406-66-1425 | C112: ครุภัณฑ์สำนักงาน | D112: ตู้เหล็กแบบ 2 บาน ยี่ห้อ TAIYO ครุภัณฑ์มากับโครงการปรับปรุง อาคาร B ตลาดเทศบาล 4 เพื่อเป็นอาคารเก็บพัสดุกลาง สัญญาจ้างก่อสร้าง เลขที่ 17/2566 ลว.17 ก.ค. 2566 มูลค่าก่อสร้างจำวนเงินทั้งสิ้น 2,484,000 บาท | E112: 15 | F112: 11 | G112: 2566 | H112: 5885 | I112: ซื้อ/จ้าง | J112: สำนักปลัดเทศบาล (งานทะเบียนราษฯ) | K112: งานบริหารทั่วไป
A113: 6 | B113: 406-66-1426 | C113: ครุภัณฑ์สำนักงาน | D113: ตู้เหล็กแบบ 2 บาน ยี่ห้อ TAIYO ครุภัณฑ์มากับโครงการปรับปรุง อาคาร B ตลาดเทศบาล 4 เพื่อเป็นอาคารเก็บพัสดุกลาง สัญญาจ้างก่อสร้าง เลขที่ 17/2566 ลว.17 ก.ค. 2566 มูลค่าก่อสร้างจำวนเงินทั้งสิ้น 2,484,000 บาท | E113: 15 | F113: 11 | G113: 2566 | H113: 5885 | I113: ซื้อ/จ้าง | J113: สำนักปลัดเทศบาล (งานทะเบียนราษฯ) | K113: งานบริหารทั่วไป
A114: 7 | B114: 406-66-1427 | C114: ครุภัณฑ์สำนักงาน | D114: ตู้เหล็กแบบ 2 บาน ยี่ห้อ TAIYO ครุภัณฑ์มากับโครงการปรับปรุง อาคาร B ตลาดเทศบาล 4 เพื่อเป็นอาคารเก็บพัสดุกลาง สัญญาจ้างก่อสร้าง เลขที่ 17/2566 ลว.17 ก.ค. 2566 มูลค่าก่อสร้างจำวนเงินทั้งสิ้น 2,484,000 บาท | E114: 15 | F114: 11 | G114: 2566 | H114: 5885 | I114: ซื้อ/จ้าง | J114: สำนักปลัดเทศบาล (งานทะเบียนราษฯ) | K114: งานบริหารทั่วไป
A115: 8 | B115: 406-66-1428 | C115: ครุภัณฑ์สำนักงาน | D115: ตู้เหล็กแบบ 2 บาน ยี่ห้อ TAIYO ครุภัณฑ์มากับโครงการปรับปรุง อาคาร B ตลาดเทศบาล 4 เพื่อเป็นอาคารเก็บพัสดุกลาง สัญญาจ้างก่อสร้าง เลขที่ 17/2566 ลว.17 ก.ค. 2566 มูลค่าก่อสร้างจำวนเงินทั้งสิ้น 2,484,000 บาท | E115: 15 | F115: 11 | G115: 2566 | H115: 5885 | I115: ซื้อ/จ้าง | J115: สำนักปลัดเทศบาล (งานทะเบียนราษฯ) | K115: งานบริหารทั่วไป
A116: 9 | B116: 406-66-1429 | C116: ครุภัณฑ์สำนักงาน | D116: ตู้เหล็กแบบ 2 บาน ยี่ห้อ TAIYO ครุภัณฑ์มากับโครงการปรับปรุง อาคาร B ตลาดเทศบาล 4 เพื่อเป็นอาคารเก็บพัสดุกลาง สัญญาจ้างก่อสร้าง เลขที่ 17/2566 ลว.17 ก.ค. 2566 มูลค่าก่อสร้างจำวนเงินทั้งสิ้น 2,484,000 บาท | E116: 15 | F116: 11 | G116: 2566 | H116: 5885 | I116: ซื้อ/จ้าง | J116: สำนักปลัดเทศบาล (งานทะเบียนราษฯ) | K116: งานบริหารทั่วไป
A117: 10 | B117: 406-66-1430 | C117: ครุภัณฑ์สำนักงาน | D117: ตู้เหล็กแบบ 2 บาน ยี่ห้อ TAIYO ครุภัณฑ์มากับโครงการปรับปรุง อาคาร B ตลาดเทศบาล 4 เพื่อเป็นอาคารเก็บพัสดุกลาง สัญญาจ้างก่อสร้าง เลขที่ 17/2566 ลว.17 ก.ค. 2566 มูลค่าก่อสร้างจำวนเงินทั้งสิ้น 2,484,000 บาท | E117: 15 | F117: 11 | G117: 2566 | H117: 5885 | I117: ซื้อ/จ้าง | J117: สำนักปลัดเทศบาล (งานทะเบียนราษฯ) | K117: งานบริหารทั่วไป
A118: 11 | B118: 406-66-1431 | C118: ครุภัณฑ์สำนักงาน | D118: ตู้เหล็กแบบ 2 บาน ยี่ห้อ TAIYO ครุภัณฑ์มากับโครงการปรับปรุง อาคาร B ตลาดเทศบาล 4 เพื่อเป็นอาคารเก็บพัสดุกลาง สัญญาจ้างก่อสร้าง เลขที่ 17/2566 ลว.17 ก.ค. 2566 มูลค่าก่อสร้างจำวนเงินทั้งสิ้น 2,484,000 บาท | E118: 15 | F118: 11 | G118: 2566 | H118: 5885 | I118: ซื้อ/จ้าง | J118: สำนักปลัดเทศบาล (งานทะเบียนราษฯ) | K118: งานบริหารทั่วไป
A119: 12 | B119: 406-66-1432 | C119: ครุภัณฑ์สำนักงาน | D119: ตู้เหล็กแบบ 2 บาน ยี่ห้อ TAIYO ครุภัณฑ์มากับโครงการปรับปรุง อาคาร B ตลาดเทศบาล 4 เพื่อเป็นอาคารเก็บพัสดุกลาง สัญญาจ้างก่อสร้าง เลขที่ 17/2566 ลว.17 ก.ค. 2566 มูลค่าก่อสร้างจำวนเงินทั้งสิ้น 2,484,000 บาท | E119: 15 | F119: 11 | G119: 2566 | H119: 5885 | I119: ซื้อ/จ้าง | J119: สำนักปลัดเทศบาล (งานทะเบียนราษฯ) | K119: งานบริหารทั่วไป
... A125: 18 | B125: 406-66-1438 | C125: ครุภัณฑ์สำนักงาน | D125: ตู้เหล็กแบบ 2 บาน ยี่ห้อ TAIYO ครุภัณฑ์มากับโครงการปรับปรุง อาคาร B ตลาดเทศบาล 4 เพื่อเป็นอาคารเก็บพัสดุกลาง สัญญาจ้างก่อสร้าง เลขที่ 17/2566 ลว.17 ก.ค. 2566 มูลค่าก่อสร้างจำวนเงินทั้งสิ้น 2,484,000 บาท | E125: 15 | F125: 11 | G125: 2566 | H125: 5885 | I125: ซื้อ/จ้าง | J125: สำนักปลัดเทศบาล (งานทะเบียนราษฯ) | K125: งานบริหารทั่วไป
A126: 19 | B126: 406-67-1463 | C126: ครุภัณฑ์สำนักงาน | D126: ตู้ล็อกเกอร์ 18 ช่อง ยี่ห้อ TAIYO รุ่น LK-018 | E126: 18 | F126: 1 | G126: 2567 | H126: 8000 | I126: ซื้อ/จ้าง | J126: สำนักปลัด | K126: งานบริหารทั่วไป | L126: 52003/252
A127: 20 | B127: 406-67-1464 | C127: ครุภัณฑ์สำนักงาน | D127: ตู้เหล็กบานเลื่อนกระจก ยี่ห้อ TAIYO รุ่น R-025 | E127: 18 | F127: 1 | G127: 2567 | H127: 5000 | I127: ซื้อ/จ้าง | J127: สำนักปลัด | K127: งานบริหารทั่วไป | L127: 52003/252
J128: 117357
C129: โต๊ะ (400)
A130: 1 | B130: 481-66-0061 | C130: ครุภัณฑ์สำนักงาน | D130: โต๊ะหมู่บูชา 1 ชุด 9 ตัว | E130: 10 | F130: 11 | G130: 2566 | H130: 8500 | I130: ซื้อ/จ้าง | J130: สำนักปลัดเทศบาล | K130: งานบริหารทั่วไป | L130: 52003/113
A131: 2 | B131: 400-67-6969 | C131: ครุภัณฑ์สำนักงาน | D131: โต๊ะทำงานเหล็ก พร้อมกระจก ยี่ห้อ TAIYO รุ่น TTD-50 | E131: 18 | F131: 1 | G131: 2567 | H131: 8500 | I131: ซื้อ/จ้าง | J131: สำนักปลัด | K131: งานบริหารทั่วไป | L131: 52003/252
A132: 3 | B132: 400-67-7519 | C132: ครุภัณฑ์สำนักงาน | D132: โต๊ะวางคอมพิวเตอร์ ยี่ห้อ ITM | E132: 26 | F132: 7 | G132: 2567 | H132: 7300 | I132: ซื้อ/จ้าง | J132: สำนักปลัดเทศบาล | K132: งานบริหารทั่วไป | L132: 52003/99
J133: 24300
J134: =SUM(J4:J133) -> 260657
...

Sheet โอนอาคาร2567
A1: รายละเอียดอาคารของสำนักปลัดเทศบาล (รับโอน)
A3: ลำดับที่ | B3: เลขที่หนังสือ | C3: รายการ | D3: หมวดครุภัณฑ์ | E3: รหัสครุภัณฑ์ | F3: วัน | G3: เดือน | H3: ปี | I3: ราคาที่ได้มา | J3: หน่วยงาน | K3: ได้มาจาก | L3: แหล่งที่มา
B4: ลป 52006/018 | C4: อาคารศูนย์นันทนาการสร้างสรรค์ (โฮงละกอน) | D4: อาคาร | E4: 013-21-0001 | I4: 3002864 | J4: งานธุรการ ฝ่ายบริหารงานทั่วไป สำนักปลัดเทศบาล | K4: สำนักการศึกษา
A38: รายละเอียดอาคารของสำนักปลัดเทศบาล (โอนออก)
A40: ลำดับที่ | B40: เลขที่หนังสือ | C40: รายการ | D40: หมวดครุภัณฑ์ | E40: รหัสครุภัณฑ์ | F40: วัน | G40: เดือน | H40: ปี | I40: ราคาที่ได้มา | J40: หน่วยงาน | K40: โอนให้ | L40: แหล่งที่มา

Sheet แบบกข.
A1: งบทรัพย์สินเทศบาลนครลำปาง
A3: ณ กันยายน 2567
A4: ประเภททรัพย์สิน | B4: รหัสพัสดุ | C4: ครุภัณฑ์ | E4: ครุภัณฑ์ต่ำกว่าเกณฑ์ (วัสดุ)
C5: จำนวนรายการ | D5: จำนวนเงินที่ได้มา | E5: จำนวนรายการ | F5: จำนวนเงินที่ได้มา
A6: ก. อสังหาริมทรัพย์
A7: 1. ที่ดิน
A8: 2. อาคารและโรงเรียน | C8: =อาคาร!A16 -> 6 | D8: =อาคาร!E16 -> 14661018
A9: 3. สิ่งก่อสร้างอื่น
A10: 3.1 สิ่งปลูกสร้าง
A11: 3.2 ตลาด
A12: 3.3 โรงเรียน
A13: อาคารเรียน
A14: อาคารโรงพละศึกษา
A15: อาคารโรงฝึกงาน
A16: สถานที่ดื่มน้ำยึดติดกับพื้นดิน
A17: 3.4 ฌาปนสถาน
A18: 3.5 บ่อหมักสิ่งปฏิกูล
A19: 3.6 เตาเผาขยะ
A20: 3.7 หอถังระบบน้ำบาดาล
A21: 3.8 หอนาฬิกา | C21: =สิ่งปลูกสร้าง!A9 -> 1 | D21: =สิ่งปลูกสร้าง!E9 -> 152000
A22: 3.9 ป้ายประชาสัมพันธ์ | C22: =สิ่งปลูกสร้าง!A118 -> 106 | D22: =สิ่งปลูกสร้าง!E118 -> 459830
A23: 3.10 สระว่ายน้ำ
A24: 3.11 สะพาน
A25: 3.12 รั้ว
A26: 3.13 อื่น ๆ
A27: 3.13.1 หอกระจายข่าว
A28: 3.13.2 ก่อสร้างห้องน้ำสำหรับผู้พิการ | C28: =สิ่งปลูกสร้าง!A121 -> 1 | D28: =สิ่งปลูกสร้าง!E121 -> 199500
A29: 3.13.3 ก่อสร้างศาลพระภูมิ | C29: =สิ่งปลูกสร้าง!A124 -> 1 | D29: =สิ่งปลูกสร้าง!E124 -> 299000
A30: 3.13.4 ป้ายแสดงประวัติ | C30: =สิ่งปลูกสร้าง!A138 -> 12 | D30: =สิ่งปลูกสร้าง!E138 -> 146541
A31: 3.13.5 รั้วบริเวณด้านทิศตะวันออกอาคารดับเพลิง | C31: =สิ่งปลูกสร้าง!A141 -> 1 | D31: =สิ่งปลูกสร้าง!E141 -> 30000
A32: 3.13.6 โรงจอดรถเทศบาล | C32: =สิ่งปลูกสร้าง!A144 -> 1 | D32: =สิ่งปลูกสร้าง!E144 -> 9150
A33: 3.13.7 ก่อสร้างโรงจอดรถยนต์ | C33: =สิ่งปลูกสร้าง!A147 -> 1 | D33: =สิ่งปลูกสร้าง!E147 -> 476000
A34: 3.13.8 ติดตั้งเสาสัญญาณวิทยุสื่อสาร | C34: =สิ่งปลูกสร้าง!A150 -> 1 | D34: =สิ่งปลูกสร้าง!E150 -> 80900.73
A35: รวมอสังหาริมทรัพย์ | C35: =C34+C33+C32+C31+C30+C29+C28+C22+C21+C8 -> 131 | D35: =D34+D33+D32+D31+D30+D29+D28+D22+D21+D8 -> 16513940 | E35: =SUM(F3) -> 0
A37: ข. สังหาริมทรัพย์
A38: 1. ครุภัณฑ์สำนักงาน
A39: ป้ายปิดประกาศ | C39: =สำนักงาน!A40 -> 31 | D39: =สำนักงาน!E40 -> 472051.91
A40: โต๊ะ | C40: =สำนักงาน!A274 -> 227 | D40: =สำนักงาน!E274 -> 1163306.1 | E40: ='ส่งคลัง (ต)'!A24 -> 14 | F40: ='ส่งคลัง (ต)'!E24 -> 57260
A41: เก้าอี้ | C41: =สำนักงาน!A764 -> 487 | D41: =สำนักงาน!E764 -> 879613.6 | E41: ='ส่งคลัง (ต)'!A146 -> 118 | F41: ='ส่งคลัง (ต)'!E146 -> 152760
A42: ม้านั่ง
...

Sheet อาคาร
A1: รายละเอียดสิ่งปลูกสร้าง สำนักปลัดเทศบาล
A2: ณ ตุลาคม 2566
A4: ลำดับ | B4: รายการ | C4: รหัสครุภัณฑ์ | D4: วัน เดือน ปี | E4: ราคาที่ได้มา | F4: สภาพครุภัณฑ์
A5: ที่ | D5: ที่ได้มา | F5: สถานที่ใช้งาน | G5: ใช้ได้ | H5: ชำรุด | I5: เสื่อม | J5: สูญหาย | K5: เก็บ | L5: หมดความ | M5: หมายเหตุ
I6: สภาพ | K6: ไว้นาน | L6: จำเป็น
B7: อสังหาริมทรัพย์
A8: 1 | B8: อาคารหอปูมละกอน | C8: 005-94-0001 | D8: 5 ม.ค. 2494 | E8: 440000 | F8: งานส่งเสริมการท่องเที่ยว สำนักปลัดเทศบาล | G8: / | M8: ลป52006/1074 รับโอนมาจากฝ่ายบริหารงานทั่วไป สำนักการศึกษา
A9: 2 | B9: อาคารหอปูมละกอน (ปรับปรุงต่อเติมห้องทำงาน) | C9: 005-94-0001 | D9: 5 ก.ค.47 | E9: 200000 | F9: งานส่งเสริมการท่องเที่ยว สำนักปลัดเทศบาล | G9: / | M9: ลป52006/1074 รับโอนมาจากฝ่ายบริหารงานทั่วไป สำนักการศึกษา
A10: 3 | B10: อาคารหอปูมละกอน (ปรับปรุงอาคารเป็นพิพิธภัณฑ์) | C10: 005-94-0001 | D10: 4 ม.ค. 54 | E10: 7925000 | F10: งานส่งเสริมการท่องเที่ยว สำนักปลัดเทศบาล | G10: / | M10: ลป52006/1074 รับโอนมาจากฝ่ายบริหารงานทั่วไป สำนักการศึกษา
A11: 4 | B11: อาคารหอปูมละกอน (ก่อสร้างร้านถ่ายรูป อาคารหอปูมละกอน) | C11: 005-94-0001 | D11: 5 ต.ค. 54 | E11: 90290 | F11: งานส่งเสริมการท่องเที่ยว สำนักปลัดเทศบาล | G11: / | M11: ลป52006/1074 รับโอนมาจากฝ่ายบริหารงานทั่วไป สำนักการศึกษา
A12: 5 | B12: อาคารศูนย์นันทนาการสร้างสรรค์ (โฮงละกอน) | C12: 013-21-0001 | E12: 3002864 | F12: งานธุรการ สำนักปลัดเทศบาล | G12: / | M12: ลป 52006/018 ลงวันที่ 7 พฤษภาคม 2567 รับโอนมาจาก สำนักการศึกษา
A13: 6 | B13: อาคารศูนย์นันทนาการสร้างสรรค์ (โฮงละกอน) | C13: 013-21-0001 | E13: 3002864 | F13: งานธุรการ สำนักปลัดเทศบาล | G13: / | M13: ลป 52006/018 รับโอนมาจาก สำนักการศึกษา
A14: 6 | D14: รวม | E14: =SUM(E8:E13) -> 14661018
A16: 6 | D16: รวมทั้งสิ้น | E16: =E14 -> 14661018

Sheet สิ่งปลูกสร้าง
A1: รายละเอียดสิ่งปลูกสร้าง สำนักปลัดเทศบาล
A2: ณ ตุลาคม 2566
A4: ลำดับ | B4: รายการ | C4: รหัสครุภัณฑ์ | D4: วัน เดือน ปี | E4: ราคาที่ได้มา | F4: สภาพครุภัณฑ์
A5: ที่ | D5: ที่ได้มา | F5: สถานที่ใช้งาน | G5: ใช้ได้ | H5: ชำรุด | I5: เสื่อม | J5: สูญหาย | K5: เก็บ | L5: หมดความ | M5: หมายเหตุ
I6: สภาพ | K6: ไว้นาน | L6: จำเป็น
B7: อสังหาริมทรัพย์
A8: 1 | B8: หอนาฬิกา | C8: 183-00-0001 | D8: 1 ม.ค. 2500 | E8: 152000 | F8: สำนักปลัดฯ | G8: /
A9: 1 | E9: =SUM(E8) -> 152000
B11: ป้าย
A12: 1 | B12: ป้ายชี้ทางสถานที่สำคัญ (ก่อนถึงร้านแสงฟ้า) | C12: 185-48-0023 | D12: 17708 | E12: 1828.3 | F12: งานท่องเที่ยว | G12: /
A13: 2 | B13: ป้ายชี้ทางสถานที่สำคัญ (หน้าวัดสวนดอก) | C13: 185-48-0024 | D13: 17708 | E13: 1828.3 | F13: งานท่องเที่ยว | G13: /
A14: 3 | B14: ป้ายชี้ทางสถานที่สำคัญ (หน้าห้างทองช้างสวัสดิ์) | C14: 185-48-0025 | D14: 17708 | E14: 1828.3 | F14: งานท่องเที่ยว | G14: /
A15: 4 | B15: ป้ายชี้ทางสถานที่สำคัญ (ก่อนถึงวัดท่ามะโอ) | C15: 185-48-0026 | D15: 17708 | E15: 1828.3 | F15: งานท่องเที่ยว | G15: /
A16: 5 | B16: ป้ายชี้ทางสถานที่สำคัญ (ก่อนถึงวัดท่ามะโอ) | C16: 185-48-0027 | D16: 17708 | E16: 1828.3 | F16: งานท่องเที่ยว | G16: /
A17: 6 | B17: ป้ายชี้ทางสถานที่สำคัญ (เลยวัดประตูต้นผึ้ง) | C17: 185-48-0028 | D17: 17708 | E17: 1828.3 | F17: งานท่องเที่ยว | G17: /
A18: 7 | B18: ป้ายชี้ทางสถานที่สำคัญ (เลยวัดประตูต้นผึ้ง) | C18: 185-48-0029 | D18: 17708 | E18: 1828.3 | F18: งานท่องเที่ยว | G18: /
A19: 8 | B19: ป้ายชี้ทางสถานที่สำคัญ (ตรงข้ามแขวงป่าไม้เดิม) | C19: 185-48-0030 | D19: 17708 | E19: 1828.3 | F19: งานท่องเที่ยว | G19: /
A20: 9 | B20: ป้ายชี้ทางสถานที่สำคัญ (ตรงข้ามแขวงป่าไม้เดิม) | C20: 185-48-0031 | D20: 17708 | E20: 1828.3 | F20: งานท่องเที่ยว | G20: /
A21: 10 | B21: ป้ายชี้ทางสถานที่สำคัญ (ตรงข้ามสวนประตูเวียง) | C21: 185-48-0032 | D21: 17708 | E21: 1828.3 | F21: งานท่องเที่ยว | G21: /
A22: 11 | B22: ป้ายชี้ทางสถานที่สำคัญ (ตรงข้ามสวนประตูเวียง) | C22: 185-48-0033 | D22: 17708 | E22: 1828.3 | F22: งานท่องเที่ยว | G22: /
A23: 12 | B23: ป้ายชี้ทางสถานที่สำคัญ (ก่อนถึงร้านรสเจ็บ) | C23: 185-48-0034 | D23: 17708 | E23: 1828.3 | F23: งานท่องเที่ยว | G23: /
... A117: 106 | B117: ป้ายข้อมูลสถานที่ท่องเที่ยวเชิงอนุรักษ์ (บ้านเสานัก) | C117: 185-60-0137 | D117: 22010 | E117: 46166 | F117: งานท่องเที่ยว | G117: /
A118: 106 | E118: =SUM(E12:E117) -> 459830
A120: 1 | B120: ก่อสร้างห้องน้ำสำหรับผู้พิการฯ บริเวณอาคารทะเบียนราษฎรฯ ขนาด 6 ตรม. | C120: 187-60-0010 | D120: 21890 | E120: 199500 | F120: งานธุรการ | G120: /
A121: 1 | E121: =SUM(E120) -> 199500
A123: 1 | B123: ก่อสร้างศาลพระภูมิ | C123: 240-60-0003 | D123: 241074 | E123: 299000 | F123: งานธุรการ | G123: /
A124: 1 | E124: =SUM(E123) -> 299000
A126: 1 | B126: ป้ายแสดงประวัติจังหวัดลำปาง (วัดพระแก้วดอนเต้า) | C126: 273-45-0001 | D126: 16784 | E126: 9812.4 | F126: งานท่องเที่ยว | G126: /
A127: 2 | B127: ป้ายแสดงประวัติจังหวัดลำปาง (วัดป่าฝาง) | C127: 273-45-0002 | D127: 16784 | E127: 9812.4 | F127: งานท่องเที่ยว | G127: /
A128: 3 | B128: ป้ายแสดงประวัติจังหวัดลำปาง (วัดปงสนุก) | C128: 273-45-0003 | D128: 16784 | E128: 9812.4 | F128: งานท่องเที่ยว | G128: /
A129: 4 | B129: ป้ายแสดงประวัติจังหวัดลำปาง (บ้านเสานัก) | C129: 273-45-0004 | D129: 16784 | E129: 9812.4 | F129: งานท่องเที่ยว | G129: /
A130: 5 | B130: ป้ายแสดงประวัติจังหวัดลำปาง (อนุสาวรีย์พ่อเจ้าทิพย์ช้าง) | C130: 273-45-0005 | D130: 16784 | E130: 9812.4 | F130: งานท่องเที่ยว | G130: /
A131: 6 | B131: ป้ายแสดงประวัติจังหวัดลำปาง (กาดกองต้า) | C131: 273-45-0006 | D131: 16784 | E131: 9812.4 | F131: งานท่องเที่ยว | G131: /
A132: 7 | B132: ป้ายแสดงประวัติจังหวัดลำปาง (หลวงพ่อดำ) | C132: 273-45-0007 | D132: 16784 | E132: 9812.4 | F132: งานท่องเที่ยว | G132: /
A133: 8 | B133: ป้ายแสดงประวัติจังหวัดลำปาง (ศาลเจ้าพ่อหลักเมือง) | C133: 273-45-0008 | D133: 16784 | E133: 9812.4 | F133: งานท่องเที่ยว | G133: /
A134: 9 | B134: ป้ายแสดงประวัติจังหวัดลำปาง (สวนเขลางค์) | C134: 273-45-0009 | D134: 16784 | E134: 9812.4 | F134: งานท่องเที่ยว | G134: /
A135: 10 | B135: ป้ายแสดงประวัติจังหวัดลำปาง (สวนห้าแยกฯ) | C135: 273-45-0010 | D135: 16784 | E135: 9812.4 | F135: งานท่องเที่ยว | G135: /
A136: 11 | B136: ป้ายแสดงประวัติจังหวัดลำปาง (สะพานรัษฎาภิเศก) | C136: 273-46-0011 | D136: 16735 | E136: 24208.5 | F136: งานท่องเที่ยว | G136: /
A137: 12 | B137: ป้ายแสดงประวัติจังหวัดลำปาง (วัดศรีรองเมือง) | C137: 273-46-0012 | D137: 16735 | E137: 24208.5 | F137: งานท่องเที่ยว | G137: /
A138: 12 | E138: =SUM(E126:E137) -> 146541
...

Sheet สำนักงาน
A1: รายละเอียดครุภัณฑ์ สำนักปลัดเทศบาล
A2: ณ กันยายน 2567
A4: ลำดับ | B4: รายการ | C4: รหัสครุภัณฑ์ | D4: วัน เดือน ปี | E4: ราคาที่ได้มา | F4: สภาพครุภัณฑ์
A5: ที่ | D5: ที่ได้มา | F5: สถานที่ใช้งาน | G5: ใช้ได้ | H5: ชำรุด | I5: เสื่อม | J5: สูญหาย | K5: เก็บ | L5: หมดความ | M5: หมายเหตุ
I6: สภาพ | K6: ไว้นาน | L6: จำเป็น
B7: ครุภัณฑ์สำนักงาน
B8: ป้ายสำหรับปิดประกาศ (081)
A9: 1 | B9: ป้ายสำหรับปิดประกาศ (ตามอาคารและหน้าห้องประชุม) | C9: 081-41-0002 | D9: 15247 | E9: 8000 | F9: งานธุรการ+สารบรรณ | G9: /
A10: 2 | B10: ป้ายสำหรับปิดประกาศ (ตามอาคาร) | C10: 081-41-0003 | D10: 15247 | E10: 8000 | F10: งานธุรการ+สารบรรณ | G10: /
A11: 3 | B11: ป้าย | C11: 081-41-0004 | D11: 15247 | E11: 8000 | F11: ฝ่ายกิจการสภา | G11: / | M11: หน้าห้องประชุมสภา
A12: 4 | B12: ป้ายสำหรับปิดประกาศ (ตามอาคาร) | C12: 081-41-0005 | D12: 15247 | E12: 8000 | F12: งานธุรการ+สารบรรณ | G12: /
A13: 5 | B13: ป้ายสำหรับปิดประกาศ (ตามอาคาร) | C13: 081-41-0006 | D13: 15247 | E13: 8000 | F13: งานธุรการ+สารบรรณ | G13: /
A14: 6 | B14: ป้ายสำหรับปิดประกาศ (ตามอาคาร) | C14: 081-41-0007 | D14: 15247 | E14: 8000 | F14: งานธุรการ+สารบรรณ | G14: /
A15: 7 | B15: ป้ายสแตนเลสลอยตัว (ตามอาคาร) | C15: 081-42-0008 | D15: 15382 | E15: 10000 | F15: งานธุรการ+สารบรรณ | G15: /
A16: 8 | B16: ป้ายสแตนเลสลอยตัว (สำนักปลัด) | C16: 081-42-0009 | D16: 15382 | E16: 10000 | F16: งานธุรการ+สารบรรณ | G16: /
A17: 9 | B17: ป้ายสแตนเลสลอยตัว (สำนักปลัด) | C17: 081-42-0010 | D17: 15382 | E17: 10000 | F17: งานธุรการ+สารบรรณ | G17: /
A18: 10 | B18: ป้ายสแตนเลสลอยตัว (สำนักปลัด) | C18: 081-42-0011 | D18: 15382 | E18: 10000 | F18: งานธุรการ+สารบรรณ | G18: /
A19: 11 | B19: ป้ายสแตนเลสลอยตัว (สำนักปลัด) | C19: 081-42-0012 | D19: 15382 | E19: 10000 | F19: งานธุรการ+สารบรรณ | G19: /
A20: 12 | B20: ป้ายสแตนเลสลอยตัว (สำนักปลัด) | C20: 081-42-0013 | D20: 15382 | E20: 10000 | F20: งานธุรการ+สารบรรณ | G20: /
A21: 13 | B21: ป้ายสแตนเลสลอยตัว (สำนักปลัด) | C21: 081-42-0014 | D21: 15382 | E21: 10000 | F21: งานธุรการ+สารบรรณ | G21: /
A22: 14 | B22: ป้ายบอกตำแหน่งอาคาร (สำนักปลัด) | C22: 081-42-0015 | D22: 15382 | E22: 10000 | F22: งานธุรการ+สารบรรณ | G22: /
A23: 15 | B23: ป้ายบอกตำแหน่งอาคาร (สำนักปลัด) | C23: 081-42-0016 | D23: 15382 | E23: 10000 | F23: งานธุรการ+สารบรรณ | G23: /
A24: 16 | B24: ป้ายบอกตำแหน่งอาคาร (สำนักปลัด) | C24: 081-42-0017 | D24: 15382 | E24: 10000 | F24: งานธุรการ+สารบรรณ | G24: /
A25: 17 | B25: ป้ายทางออก Exit Sign Slimeline แบบไฟ LED | C25: 081-67-0041 | D25: 24462 | E25: 1712 | F25: งานธุรการ สป. | G25: / | M25: (อาคารศูนย์เยาวชน โฮงละกอน)
A26: 18 | B26: ป้ายทางออก Exit Sign Slimeline แบบไฟ LED | C26: 081-67-0042 | D26: 24462 | E26: 1712 | F26: งานธุรการ สป. | G26: / | M26: (อาคารศูนย์เยาวชน โฮงละกอน)
A27: 19 | B27: ป้ายทางออก Exit Sign Slimeline แบบไฟ LED | C27: 081-67-0038 | D27: 24462 | E27: 1619 | F27: งานธุรการ สป. | G27: / | M27: (อาคารศูนย์เยาวชน โฮงละกอน)
A28: 20 | B28: ป้ายทางออก Exit Sign Slimeline แบบไฟ LED | C28: 081-67-0039 | D28: 24462 | E28: 10400 | F28: งานธุรการ สป. | G28: / | M28: (อาคารศูนย์เยาวชน โฮงละกอน)
A29: 21 | B29: ป้ายทางออก Exit Sign Slimeline แบบไฟ LED | C29: 081-67-0040 | D29: 24462 | E29: 10400 | F29: งานธุรการ สป. | G29: / | M29: (อาคารศูนย์เยาวชน โฮงละกอน)
A30: 22 | B30: ป้ายทางออก Exit Sign Slimeline แบบไฟ LED | C30: 081-67-0043 | D30: 24462 | E30: 10400 | F30: งานธุรการ สป. | G30: / | M30: (อาคารศูนย์เยาวชน โฮงละกอน)
A31: 23 | B31: ป้ายทางออก Exit Sign Slimeline แบบไฟ LED | C31: 081-67-0044 | D31: 24462 | E31: 10400 | F31: งานธุรการ สป. | G31: / | M31: (อาคารศูนย์เยาวชน โฮงละกอน)
A32: 24 | B32: ป้ายทางออก Exit Sign Slimeline แบบไฟ LED | C32: 081-67-0045 | D32: 24462 | E32: 1691 | F32: งานธุรการ สป. | G32: / | M32: (อาคารศูนย์เยาวชน โฮงละกอน)
A33: 25 | B33: ป้ายทางออก Exit Sign Slimeline แบบไฟ LED | C33: 081-67-0046 | D33: 24462 | E33: 1712 | F33: งานธุรการ สป. | G33: / | M33: (อาคารศูนย์เยาวชน โฮงละกอน)
A34: 26 | B34: ป้ายทางออก Exit Sign Slimeline แบบไฟ LED | C34: 081-67-0047 | D34: 24462 | E34: 10400 | F34: งานธุรการ สป. | G34: / | M34: (อาคารศูนย์เยาวชน โฮงละกอน)
A35: 27 | B35: ป้ายทางออก Exit Sign Slimeline แบบไฟ LED | C35: 081-67-0048 | D35: 24462 | E35: 10400 | F35: งานธุรการ สป. | G35: / | M35: (อาคารศูนย์เยาวชน โฮงละกอน)
A36: 28 | B36: ป้ายทางออก Exit Sign Slimeline แบบไฟ LED | C36: 081-67-0049 | D36: 24462 | E36: 70433.82 | F36: งานธุรการ สป. | G36: / | M36: (อาคารศูนย์เยาวชน โฮงละกอน)
... A39: 31 | B39: ป้ายทางออก Exit Sign Slimeline แบบไฟ LED | C39: 081-67-0052 | D39: 24462 | E39: 49035.6 | F39: งานธุรการ สป. | G39: / | M39: (อาคารศูนย์เยาวชน โฮงละกอน)
A40: 31 | D40: รวม | E40: =SUM(E9:E39) -> 472051.91
B43: โต๊ะ (400)
A44: 1 | B44: โต๊ะตั้งเครื่องพิมพ์ดีด(ห้องราชาวดี) | C44: 400-19-0153 | D44: 43470 | E44: 700 | F44: งานธุรการ+สารบรรณ | G44: /
A45: 2 | B45: โต๊ะทำงาน | C45: 400-19-0154 | D45: 43546 | E45: 2000 | F45: งานเลขา ฯ | G45: / | M45: ณัฐพัชร์ฯ
...

Sheet ยานพาหนะฯ
A1: รายละเอียดครุภัณฑ์ สำนักปลัดเทศบาล
A2: ณ กันยายน 2566
A4: ลำดับ | B4: รายการ | C4: รหัสครุภัณฑ์ | D4: วัน เดือน ปี | E4: ราคาที่ได้มา | F4: สภาพครุภัณฑ์
A5: ที่ | D5: ที่ได้มา | F5: สถานที่ใช้งาน | G5: ใช้ได้ | H5: ชำรุด | I5: เสื่อม | J5: สูญหาย | K5: เก็บ | L5: หมดความ | M5: หมายเหตุ
I6: สภาพ | K6: ไว้นาน | L6: จำเป็น
B7: ครุภัณฑ์ยานพาหนะและขนส่ง
B8: (002)
A9: 1 | B9: รถยนต์กะบะปิ๊กอัพ นิสสัน สีขาว เครื่องยนต์ดีเซล | C9: 002-32-0022 | D9: 12008 | E9: 599000 | F9: งานป้องกันฯ | G9: / | M9: งานป้องกัน หน่วย 2
B10: หมายเลขเครื่องยนต์ TD 25-T00811 เลขตัวถัง RGD21- | M10: เบอร์ 2
B11: B07920 4 สูบ 2494 ซีซี ทะเบียน ลป บ 7840 | M11: กระบะปิ๊กอัพ
A12: 2 | B12: รถยนต์กะบะปิ๊กอัพ นิสสัน สีขาว เครื่องยนต์เบนซิน | C12: 002-37-0031 | D12: 13809 | E12: 350000 | F12: งานป้องกันฯ | G12: / | M12: งานป้องกัน หน่วย 1
B13: หมายเลขเครื่องยนต์ Z16-T32787 4 สูบ 1595 ซีซี | M13: เบอร์ 3
B14: 2 เพลา 4 ล้อ แบบ CGD21SFU1%DX ทะเบียน ลป | M14: กระบะปิ๊กอัพ
B15: ลม 5242
A16: 3 | B16: รถบรรทุกกระบะบรรทุก 2 ตอน (ศูนย์รถยนต์กลาง) | C16: 002-39-0035 | D16: 14606 | E16: 525000 | F16: งานธุรการ+สารบรรณ | G16: /
A17: 4 | B17: รถยนต์กระบะปิ๊กอัพ ยี่ห้อมาสด้า สีแดง 2500 ลักลี่ | C17: 002-42-0047 | D17: 15699 | E17: 450000 | F17: งานป้องกันฯ | G17: / | M17: งานป้องกัน หน่วย 1
B18: แบบ Fighter เครื่องยนต์ดีเซล หมายเลขเครื่องยนต์ | M18: เบอร์ 4
B19: WLAT138145 หมายเลขตัวถังรถ MM8UNDD3100 | M19: กระบะปิ๊กอัพ
B20: 121095 2 เพลา 96 แรงม้า ทะเบียน ลป บท 9904
A21: 5 | B21: รถยนต์สายตรวจ TOYOTA (สีทอง) ทะเบียน กง 2609 ลป. | C21: 002-45-0054 | D21: 16770 | E21: 750000 | F21: งานเทศกิจ | G21: / | M21: ไพทันฯ
A22: 6 | B22: รถยนต์ปิคอัพ TOYOTA (สีน้ำตาล เทา) ทะเบียน กง 2608 ลป. | C22: 002-45-0055 | D22: 16770 | E22: 750000 | F22: งานรักษาความสงบฯ | G22: / | M22: อำนาจฯ
A23: 7 | B23: รถยนต์กระบะ บธ9399 | C23: 002-45-0053 | D23: 235710 | E23: 439800 | F23: งานศูนย์รถยนต์กลาง สำนักปลัด | G23: / | M23: ลป52004/493 โอนจากงานควบคุมอาคารและผังเมือง ส่วนการโยธา สำนักช่าง
A24: 7 | E24: =SUM(E9:E23) -> 3863800
B25: (004)
A26: 1** | B26: รถยนต์ดับเพลิง ยี่ห้ออีซูซุ ชนิดมีถังน้ำในตัว 6 ล้อ 145 | C26: 004-25-0008 | D26: 45838 | E26: 1109836 | F26: งานป้องกันฯ | I26: /
B27: แรงม้า เครื่องยนต์ดีเซล หมายเลขเครื่องยนต์ 6BB1-219563
B28: หมายเลขตัวถังรถ 3406314 (ลป น 7016) #10
A29: 2** | B29: รถยนต์ดับเพลิง ยี่ห้ออีซูซุ ชนิดมีถังน้ำในตัว 6 ล้อ 160 | C29: 004-35-0010 | D29: 13112 | E29: 1142774 | F29: งานป้องกันฯ | I29: /
B30: แรงม้า เครื่องยนต์ดีเซล หมายเลขเครื่องยนต์ 6D14-722751
B31: หมายเลขตัวถังรถ FK415F-A31059 (ลป น 7740)
B32: #15 | F32: =+F32:J38 -> 0
A33: 3 | B33: รถยนต์ดับเพลิงชนิดมีบันได้เลื่อนอัตโนมัติ ยี่ห้อเมอศซี- | C33: 004-35-0011 | D33: 12845 | E33: 14450000 | F33: งานป้องกันฯ | G33: / | M33: งานป้องกัน หน่วย 1
B34: เดสเบนซ์ รุ่น 1422252 (RHD) เครื่องยนต์ดีเซล 218 แรงม้า | M34: เบอร์ 17
B35: พร้อมติดตั้งเครื่องสูบน้ำดับเพลิง ยี่ห้อ ZIGLER รุ่น Ed 16/8
B36: 2M หมายเลขเครื่องยนต์ 441-60520611695 ทะเบียน
B37: ลป ผ 6905 (หน่วย 1)
A38: 4** | B38: รถยนต์ดับเพลิง ยี่ห้อมิตซูบิชิ ชนิดมีถังน้ำในตัว 6 ล้อ | C38: 004-37-0012 | D38: 13872 | E38: 1142774 | F38: งานป้องกันฯ | I38: /
B39: 160 แรงม้า จุน้ำ 2,000 ลิตร เครื่องยนต์ดีเซล แบบ
B40: FK415FFREDH1 เลขเครื่อง 6D14-735088 เลขตัวถัง
B41: FK415F-A3247 6 สูบ สีแดง พร้อมอุปกรณ์ เลขทะเบียน
...

Sheet การเกษตร
A1: รายละเอียดครุภัณฑ์ สำนักปลัดเทศบาล
A2: ณ กันยายน 2567
A4: ลำดับ | B4: รายการ | C4: รหัสครุภัณฑ์ | D4: วัน เดือน ปี | E4: ราคาที่ได้มา | F4: สภาพครุภัณฑ์
A5: ที่ | D5: ที่ได้มา | F5: สถานที่ใช้งาน | G5: ใช้ได้ | H5: ชำรุด | I5: เสื่อม | J5: สูญหาย | K5: เก็บ | L5: หมดความ | M5: หมายเหตุ
I6: สภาพ | K6: ไว้นาน | L6: จำเป็น
B7: ครุภัณฑ์การเกษตร
B8: เครื่องสูบน้ำ (055)
A9: 1 | B9: ปั้มแช่ไดรโว่ | C9: 055-46-0103 | D9: 17069 | E9: 4500 | F9: งานป้องกันฯ | G9: /
A10: 2 | B10: เครื่องสูบน้ำฮอนด้า WB 20 XT TR | C10: 055-48-0122 | D10: 17806 | E10: 9650 | F10: งานป้องกันฯ | G10: / | M10: งานป้องกัน หน่วย 2 เบอร์ 32
B11: เครื่องยนต์เบนซินขนาด 2 นิ้ว
A12: 3 | B12: เครื่องสูบน้ำฮอนด้า WB 20 XT TR | C12: 055-48-0124 | D12: 17806 | E12: 9650 | F12: งานป้องกันฯ | G12: /
B13: เครื่องยนต์เบนซินขนาด 2 นิ้ว
A14: 4 | B14: เครื่องสูบน้ำฮอนด้า WB 20 XT TR | C14: 055-48-0125 | D14: 17806 | E14: 9650 | F14: งานป้องกันฯ | G14: / | M14: งานป้องกัน หน่วย 1 เบอร์ 35
B15: เครื่องยนต์เบนซินขนาด 2 นิ้ว
A16: 5 | B16: เครื่องป๊มน้ำ ยี่ห้อมิตซูบิซิ รุ่น WP-255 Q2 มอร์เตอร์ 250 W | C16: 055-51-0134 | D16: 238042 | E16: 10000 | F16: งานป้องกันฯ | G16: /
A17: 6 | B17: เครื่องสูบน้ำไดโว่ ยี่ห้อมิตซูบิซิ | C17: 055-54-0170 | D17: 19854 | E17: 6800 | F17: งานป้องกันฯ | G17: /
A18: 7 | B18: เครื่องปั๊มน้ำอัตโนมัติ (ถังกลม) (อาคาร 2) 300 วัตต์ | C18: 055-64-0250 | D18: 23581 | E18: 8500 | F18: ธุรการ | G18: /
A19: 8 | B19: เครื่องปั๊มน้ำอัตโนมัติ (ถังกลม) (อาคาร 2) 300 วัตต์ | C19: 055-64-0251 | D19: 23581 | E19: 8500 | F19: ธุรการ | G19: /
A20: 9 | B20: เครื่องปั๊มน้ำอัตโนมัติ (ถังกลม) (อาคาร 7 ชั้น 4) 150 วัตต์ | C20: 055-64-0252 | D20: 23588 | E20: 5800 | F20: ธุรการ | G20: /
A21: 10 | B21: เครื่องสูบน้ำ (ไดโว่) ชนิดปั๊มแช่จุ่มใต้น้ำ 250 วัตต์ | C21: 055-64-0254 | D21: 23620 | E21: 7300 | F21: งานป้องกันฯ | G21: / | M21: งานป้องกัน หน่วย 1
A22: 11 | B22: เครื่องสูบน้ำ (ไดโว่) ชนิดปั๊มแช่จุ่มใต้น้ำ 250 วัตต์ | C22: 055-64-0255 | D22: 23620 | E22: 7300 | F22: งานป้องกันฯ | G22: / | M22: งานป้องกัน หน่วย 1
A23: 12 | B23: เครื่องสูบน้ำ (ไดโว่) ชนิดปั๊มแช่จุ่มใต้น้ำ 250 วัตต์ | C23: 055-64-0256 | D23: 23620 | E23: 7300 | F23: งานป้องกันฯ | G23: / | M23: งานป้องกัน หน่วย 1
A24: 13 | B24: เครื่องสูบน้ำ (ไดโว่) ชนิดปั๊มแช่จุ่มใต้น้ำ 250 วัตต์ | C24: 055-64-0257 | D24: 23620 | E24: 7300 | F24: งานป้องกันฯ | G24: / | M24: งานป้องกัน หน่วย 1
A25: 14 | B25: เครื่องสูบน้ำ (ไดโว่) ชนิดปั๊มแช่จุ่มใต้น้ำ 250 วัตต์ | C25: 055-64-0258 | D25: 23620 | E25: 7300 | F25: งานป้องกันฯ | G25: / | M25: งานป้องกัน หน่วย 1
A26: 15 | B26: เครื่องสูบน้ำ (แบบหอยโข่ง) สูบน้ำได้ 1000 ลิตรต่อนาที | C26: 055-64-0259 | D26: 23620 | E26: 8400 | F26: งานป้องกันฯ | G26: / | M26: งานป้องกัน หน่วย 1
B27: 5 แรงม้า ปริมาตรกระบอกสูบ 163 ซีซี
A28: 16 | B28: เครื่องสูบน้ำ (แบบหอยโข่ง) สูบน้ำได้ 1000 ลิตรต่อนาที | C28: 055-64-0260 | D28: 23620 | E28: 8400 | F28: งานป้องกันฯ | G28: / | M28: งานป้องกัน หน่วย 1
B29: 5 แรงม้า ปริมาตรกระบอกสูบ 163 ซีซี
A30: 17 | B30: เครื่องสูบน้ำ (แบบหอยโข่ง) สูบน้ำได้ 1000 ลิตรต่อนาที | C30: 055-64-0261 | D30: 23620 | E30: 8400 | F30: งานป้องกันฯ | G30: / | M30: งานป้องกัน หน่วย 1
B31: 5 แรงม้า ปริมาตรกระบอกสูบ 163 ซีซี
A32: 18 | B32: เครื่องสูบน้ำ (แบบหอยโข่ง) สูบน้ำได้ 1000 ลิตรต่อนาที | C32: 055-64-0262 | D32: 23620 | E32: 8400 | F32: งานป้องกันฯ | G32: / | M32: งานป้องกัน หน่วย 1
B33: 5 แรงม้า ปริมาตรกระบอกสูบ 163 ซีซี
A34: 19 | B34: เครื่องสูบน้ำ (แบบหอยโข่ง) สูบน้ำได้ 1000 ลิตรต่อนาที | C34: 055-64-0263 | D34: 23620 | E34: 8400 | F34: งานป้องกันฯ | G34: / | M34: งานป้องกัน หน่วย 1
B35: 5 แรงม้า ปริมาตรกระบอกสูบ 163 ซีซี
A36: 20 | B36: เครื่องปั๊มน้ำ (หอยโข่ง) (อาคาร 7 ชั้น 1) 220 โวลต์ | C36: 055-64-0264 | D36: 23623 | E36: 8000 | F36: ธุรการ | G36: /
A37: 20 | D37: รวม | E37: =SUM(E9:E36) -> 159550
B38: เลื่อยโซ่ยนต์ (068)
A39: 1 | B39: เลื่อยโซ่ยนต์ เครื่องยนต์เบนซิน 2 จังหวะ สูบเดียว | C39: 068-64-0048 | D39: 23607 | E39: 14800 | F39: งานป้องกันฯ | G39: /
B40: ขนาด 1.5 แรงม้า บาร์โซ่ไม่น้อยกว่า 12 นิ้ว ระบบ
B41: สตาร์ทเครื่องแบบเชือกดึงสตาร์ทมือ
...

Sheet ไฟฟ้าและวิทยุ
A1: รายละเอียดครุภัณฑ์ สำนักปลัดเทศบาล
A2: ณ กันยายน 2567
A4: ลำดับ | B4: รายการ | C4: รหัสครุภัณฑ์ | D4: วัน เดือน ปี | E4: ราคาที่ได้มา | F4: สภาพครุภัณฑ์
A5: ที่ | D5: ที่ได้มา | F5: สถานที่ใช้งาน | G5: ใช้ได้ | H5: ชำรุด | I5: เสื่อม | J5: สูญหาย | K5: เก็บ | L5: หมดความ | M5: หมายเหตุ
I6: สภาพ | K6: ไว้นาน | L6: จำเป็น
B7: ครุภัณฑ์ไฟฟ้าและวิทยุ
B8: ชุดไฟส่องสว่างเคลื่อนที่ (082)
A9: 1 | B9: โคมไฟหลอดทัลฮาโลท์ | C9: 082-38-0537 | D9: 13980 | E9: 13800 | F9: งานธุรการ+สารบรรณ | G9: / | M9: แจ้งว่าอยู่ที่งานป้องกัน
A10: 2 | B10: โคมไฟหลอดทัลฮาโลท์ | C10: 082-38-0538 | D10: 13980 | E10: 13800 | F10: งานธุรการ+สารบรรณ | G10: / | M10: แจ้งว่าอยู่ที่งานป้องกัน
A11: 3 | B11: โคมไฟหลอดทัลฮาโลท์ | C11: 082-38-0539 | D11: 13980 | E11: 13800 | F11: งานธุรการ+สารบรรณ | G11: / | M11: แจ้งว่าอยู่ที่งานป้องกัน
A12: 4 | B12: โคมไฟหลอดทัลฮาโลท์ | C12: 082-38-0540 | D12: 13980 | E12: 13800 | F12: งานธุรการ+สารบรรณ | G12: / | M12: แจ้งว่าอยู่ที่งานป้องกัน
A13: 5 | B13: ชุดไฟส่องสว่างเคลื่อนที่ | C13: 082-61-1751 | D13: 22361 | E13: 269640 | F13: งานป้องกันฯ | G13: / | M13: งานป้องกัน หน่วย 1 (รถเบอร์ 19)
A14: 5 | D14: รวม | E14: =SUM(E9:E13) -> 324840
B15: เครื่องควบคุมและจ่ายกระแสไฟ (430)
A16: 1 | B16: เครื่องควบคุมและจ่ายกระแสไฟ | C16: 430-51-0001 | D16: 18851 | E16: 50000 | F16: งานธุรการ+สารบรรณ | G16: /
A17: 2 | B17: ชุดควบคุมระบบภาพ | C17: 430-57-0005 | D17: 240148 | E17: 21100.4 | F17: งานธุรการ+สารบรรณ | G17: /
A18: 3 | B18: เครื่องผสมสัญญาณเสียง 16 ช่อง | C18: 430-57-0006 | D18: 240148 | E18: 39504.4 | F18: งานธุรการ+สารบรรณ | G18: /
A19: 4 | B19: Sequence Controller (local) | C19: 430-54-0007 | D19: 1 ม.ค. 54 | E19: 35000 | F19: งานท่องเที่ยว | G19: / | M19: (โอนมาจาก) ฝ่ายบริหารงานทั่วไป สำนักการศึกษา
A20: 4 | D20: รวม | E20: =SUM(E16:E19) -> 145604.8
B22: กล้องวงจรปิด (454)
A23: 1 | B23: อุปกรณ์บันทึกภาพผ่านเครือข่าย | C23: 454-59-0073 | D23: 21735 | E23: 383471 | F23: งานเทศกิจ | L23: / | M23: งานรักษาความสงบ(เทศกิจ)
A24: 2 | B24: จอแสดงผล | C24: 454-59-0085 | D24: 21735 | E24: 11770 | F24: งานเทศกิจ | G24: / | M24: งานรักษาความสงบ(เทศกิจ)
A25: 2 | D25: รวม | E25: =SUM(E23:E24) -> 395241
B26: เครื่องถอดแถบบันทึกเสียง(455)
A27: 1 | B27: เครื่องเล่นและบันทึก DVD (ห้องประชุมราชพฤกษ์) | C27: 455-53-0056 | D27: 19428 | E27: 3000 | F27: งานธุรการ+สารบรรณ | G27: /
A28: 2 | B28: เครื่องเล่นและบันทึกเสียงแบบดิจิตอล | C28: 455-57-0061 | D28: 20834 | E28: 6500 | F28: ฝ่ายกิจการสภา | G28: /
A29: 3 | B29: PM 3 Player Whith controller (local) (ชุดตลาด) | C29: 455-54-0003 | D29: 1 ม.ค. 54 | E29: 20000 | F29: งานท่องเที่ยว | G29: / | M29: (โอนมาจาก) ฝ่ายบริหารงานทั่วไป สำนักการศึกษา
A30: 4 | B30: PM 3 Player Whith controller (local) | C30: 455-54-0005 | D30: 1 ม.ค. 54 | E30: 20000 | F30: งานท่องเที่ยว | G30: / | M30: (โอนมาจาก) ฝ่ายบริหารงานทั่วไป สำนักการศึกษา
A31: 4 | D31: รวม | E31: =SUM(E27:E30) -> 49500
B32: ไมค์ประชุม (458)
A33: 1 | B33: ไมโครโฟนชุดประชุม (ห้องประชุมสภา) | C33: 458-37-0080 | D33: 13788 | E33: 16075 | F33: ฝ่ายกิจการสภา | G33: /
A34: 2 | B34: ไมโครโฟนชุดประชุม (ห้องประชุมสภา) | C34: 458-37-0081 | D34: 13788 | E34: 16075 | F34: ฝ่ายกิจการสภา | G34: /
A35: 3 | B35: ไมโครโฟนชุดประชุม (ห้องประชุมสภา) | C35: 458-37-0082 | D35: 13788 | E35: 16075 | F35: ฝ่ายกิจการสภา | G35: /
A36: 4 | B36: ไมโครโฟนชุดประชุม (ห้องประชุมสภา) | C36: 458-37-0083 | D36: 13788 | E36: 16075 | F36: ฝ่ายกิจการสภา | G36: /
A37: 5 | B37: ไมโครโฟนชุดประชุม (ห้องประชุมสภา) | C37: 458-37-0084 | D37: 13788 | E37: 16075 | F37: ฝ่ายกิจการสภา | G37: /
A38: 6 | B38: ไมโครโฟนชุดประชุม (ห้องประชุมสภา) | C38: 458-37-0085 | D38: 13788 | E38: 16075 | F38: ฝ่ายกิจการสภา | G38: /
A39: 7 | B39: ไมค์ประชุม (ห้องประชุมราชาวดี) | C39: 458-48-0126 | D39: 17875 | E39: 2700 | F39: งานธุรการ+สารบรรณ | G39: /
A40: 8 | B40: ไมค์ประชุม (ห้องประชุมราชาวดี) | C40: 458-48-0127 | D40: 17875 | E40: 2700 | F40: งานธุรการ+สารบรรณ | G40: /
A41: 9 | B41: ไมค์ประชุม (ห้องประชุมราชาวดี) | C41: 458-48-0128 | D41: 17875 | E41: 2700 | F41: งานธุรการ+สารบรรณ | G41: /
A42: 10 | B42: ไมค์ประชุม (ห้องประชุมราชาวดี) | C42: 458-48-0129 | D42: 17875 | E42: 2700 | F42: งานธุรการ+สารบรรณ | G42: /
...

Sheet โฆษณา
A1: รายละเอียดครุภัณฑ์ สำนักปลัดเทศบาล
A2: ณ กันยายน 2567
A4: ลำดับ | B4: รายการ | C4: รหัสครุภัณฑ์ | D4: วัน เดือน ปี | E4: ราคาที่ได้มา | F4: สภาพครุภัณฑ์
A5: ที่ | D5: ที่ได้มา | F5: สถานที่ใช้งาน | G5: ใช้ได้ | H5: ชำรุด | I5: เสื่อม | J5: สูญหาย | K5: เก็บ | L5: หมดความ | M5: หมายเหตุ
I6: สภาพ | K6: ไว้นาน | L6: จำเป็น
B7: ครุภัณฑ์โฆษณาและเผยแพร่
B8: จอภาพ (444)
A9: 1 | B9: จอภาพ | C9: 444-41-0011 | D9: 14981 | E9: 0 | F9: งานธุรการ+สารบรรณ | G9: /
A10: 2 | B10: จอภาพ | C10: 444-41-0012 | D10: 14981 | E10: 0 | F10: งานธุรการ+สารบรรณ | G10: /
A11: 3 | B11: จอรับภาพ (งานบริหารทั่งไป) | C11: 444-48-0014 | D11: 17832 | E11: 0 | F11: งานธุรการ+สารบรรณ | G11: /
A12: 4 | B12: จอรับภาพ | C12: 444-51-0015 | D12: 18851 | E12: 14000 | F12: งานธุรการ+สารบรรณ | G12: /
A13: 5 | B13: จอรับภาพมอนิเตอร์ไฟฟ้า (ห้องประชุมราชาวดี) | C13: 444-54-0017 | D13: 18850 | E13: 37700 | F13: งานธุรการ+สารบรรณ | G13: / | M13: ห้องประชุมราชาวดี
A14: 6 | B14: จอรับภาพมอนิเตอร์ไฟฟ้า (ชัยพกฤ) | C14: 444-62-0036 | D14: 22761 | E14: 9500 | F14: งานธุรการ+สารบรรณ | G14: / | M14: ห้องชัยพกฤษ์
A15: 6 | D15: รวม | E15: =SUM(E9:E14) -> 61200
B17: เครื่องฉายภาพโปรเจกเตอร์ (447)
A18: 1 | B18: เครื่องฉายมัลติมีเดียโปรเจคเตอร์ (งานธุรการ วรพงษ์ มาลัย) | C18: 447-59-0025 | D18: 21544 | E18: 65000 | F18: งานธุรการ+สารบรรณ | G18: / | M18: สำรองห้องประชุมราชาวดี
A19: 2 | B19: เครื่องฉายมัลติมีเดียโปรเจคเตอร์ (งานธุรการ วรพงษ์ มาลัย) | C19: 447-62-0039 | D19: 22761 | E19: 42000 | F19: งานธุรการ+สารบรรณ | G19: / | M19: ห้องชัยพกฤษ์
A20: 3 | B20: เครื่องมัลติมีเดียโปรเจคเตอร์ Panasonic LCD รุ่น PT-MZ880 | C20: 447-65-0051 | D20: 242943 | E20: 475000 | F20: งานบริหารทั่วไป | G20: / | M20: ห้องประชุมราชาวดี
A21: 3 | D21: รวม | E21: =SUM(E18:E20) -> 582000
B23: เครื่องเล่นสื่อ (448)
A24: 1 | B24: เครื่องเล่นสื่อโสต สำหรับชุดเจ้าเมืองและตำนาน | C24: 448-59-0015 | D24: 25 พ.ย. 58 | E24: 30000 | F24: งานรท่องเที่ยว | G24: / | M24: (โอนมาจาก) ฝ่ายบริหารงานทั่วไป สำนักการศึกษา
A25: 2 | B25: จอสัมผัส ขนาด 27 นิ้ว ชุดมัลติมีเดียสำหรับลงคำ | C25: 448-59-0016 | D25: 25 พ.ย. 58 | E25: 59990 | F25: งานรท่องเที่ยว | G25: / | M25: (โอนมาจาก) ฝ่ายบริหารงานทั่วไป สำนักการศึกษา
A26: 3 | B26: เครื่องควบคุมลำดับ ชุดมัลติมีเดียสำหรับลงคำปฎิญาณ | C26: 448-59-0017 | D26: 25 พ.ย. 58 | E26: 30000 | F26: งานรท่องเที่ยว | G26: / | M26: (โอนมาจาก) ฝ่ายบริหารงานทั่วไป สำนักการศึกษา
A27: 4 | B27: เครื่องควบคุมลำดับ ชุดมัลติมีเดียสำหรับลงคำปฎิญาณ | C27: 448-59-0018 | D27: 25 พ.ย. 58 | E27: 37000 | F27: งานรท่องเที่ยว | G27: / | M27: หอปูม ชั้น2 (โอนมาจาก) ฝ่ายบริหารงานทั่วไป สำนักการศึกษา
A28: 4 | D28: รวม | E28: =SUM(E24:E27) -> 156990
B30: กล้องถ่ายรูป (452)
A31: 1 | B31: กล้องถ่ายภาพ ระบบดิจิตอล | C31: 452-64-0090 | D31: 23581 | E31: 18990 | F31: งานท่องเที่ยว | G31: / | M31: ท่องเที่ยว
A32: 1 | D32: รวม | E32: =SUM(E31) -> 18990
B34: อุปกรณ์บันทึกภาพฯ (454)
A35: 1 | B35: อุปกรณ์บันทึกภาพผ่านเครือข่าย | C35: 454-59-0106 | D35: 21863 | E35: 139956 | F35: งานธุรการ+สารบรรณ | G35: /
A36: 2 | B36: อุปกรณ์บันทึกภาพผ่านเครือข่าย | C36: 454-59-0107 | D36: 21863 | E36: 155957 | F36: งานธุรการ+สารบรรณ | G36: /
A37: 2 | D37: รวม | E37: =SUM(E35:E36) -> 295913
B39: โทรทัศน์สี (456)
A40: 1 | B40: โทรทัศน์สี | C40: 456-36-0012 | D40: 13263 | E40: 11000 | F40: งานธุรการ+สารบรรณ | G40: /
A41: 2 | B41: โทรทัศน์สี ยี่ห้อ พานาโซนิค twin topdome | C41: 456-41-0021 | D41: 15234 | E41: 15000 | F41: งานเลขา ฯ | G41: /
A42: 3 | B42: จอ LCD (ห้องราชพฤกษ์) | C42: 456-51-0053 | D42: 18851 | E42: 27000 | F42: งานธุรการ+สารบรรณ | G42: / | M42: เก็บไว้ที่ห้องราชาวดีชั้น4
A43: 4 | B43: จอ LCD (ห้องราชพฤกษ์) | C43: 456-51-0055 | D43: 18851 | E43: 64500 | F43: งานธุรการ+สารบรรณ | G43: / | M43: เก็บไว้ที่ห้องราชาวดีชั้น4
A44: 5 | B44: จอ LCD (ห้องราชพฤกษ์) | C44: 456-51-0056 | D44: 18851 | E44: 64500 | F44: งานธุรการ+สารบรรณ | G44: / | M44: เก็บไว้ที่ห้องราชาวดีชั้น4
A45: 6 | B45: เครื่องสลับสัญญาณคอมพิวเตอร์ (ห้องราชพฤกษ์) | C45: 456-51-0059 | D45: 18851 | E45: 36200 | F45: งานธุรการ+สารบรรณ | G45: / | M45: เก็บไว้ที่ห้องราชาวดีชั้น4
A46: 7 | B46: เครื่องสลับสัญญาณเสียง (ห้องราชพฤกษ์) | C46: 456-51-0060 | D46: 18851 | E46: 23500 | F46: งานธุรการ+สารบรรณ | G46: / | M46: เก็บไว้ที่ห้องราชาวดีชั้น4
...

Sheet วิทยาศาสตร์
A1: รายละเอียดครุภัณฑ์ สำนักปลัดเทศบาล
A2: ณ กันยายน 2567
A4: ลำดับ | B4: รายการ | C4: รหัสครุภัณฑ์ | D4: วัน เดือน ปี | E4: ราคาที่ได้มา | F4: สภาพครุภัณฑ์
A5: ที่ | D5: ที่ได้มา | F5: สถานที่ใช้งาน | G5: ใช้ได้ | H5: ชำรุด | I5: เสื่อม | J5: สูญหาย | K5: เก็บ | L5: หมดความ | M5: หมายเหตุ
I6: สภาพ | K6: ไว้นาน | L6: จำเป็น
B7: ครุภัณฑ์วิทยาศาสตร์
B8: เครื่องช่วยหายใจ (264)
A9: 1 | B9: เครื่องช่วยหายใจแบบอัดอากาศ | C9: 264-51-0014 | D9: 18836 | E9: 100000 | F9: งานป้องกันฯ | G9: /
A10: 2 | B10: เครื่องช่วยหายใจแบบอัดอากาศ | C10: 264-51-0015 | D10: 18836 | E10: 100000 | F10: งานป้องกันฯ | G10: /
A11: 3 | B11: เครื่องช่วยหายใจแบบอัดอากาศ | C11: 264-51-0016 | D11: 18836 | E11: 100000 | F11: งานป้องกันฯ | G11: /
A12: 4 | B12: เครื่องช่วยหายใจแบบอัดอากาศ | C12: 264-51-0017 | D12: 18836 | E12: 100000 | F12: งานป้องกันฯ | G12: /
A13: 5 | B13: เครื่องช่วยหายใจแบบอัดอากาศ | C13: 264-52-0018 | D13: 19197 | E13: 104860 | F13: งานป้องกันฯ | G13: /
A14: 6 | B14: เครื่องช่วยหายใจแบบอัดอากาศ | C14: 264-52-0019 | D14: 19197 | E14: 104860 | F14: งานป้องกันฯ | G14: /
A15: 7 | B15: เครื่องช่วยหายใจแบบอัดอากาศ | C15: 264-52-0020 | D15: 19197 | E15: 104860 | F15: งานป้องกันฯ | G15: /
A16: 8 | B16: เครื่องช่วยหายใจแบบอัดอากาศ | C16: 264-52-0021 | D16: 19197 | E16: 104860 | F16: งานป้องกันฯ | G16: /
A17: 8 | D17: รวม | E17: =SUM(E9:E16) -> 819440
B18: ครุภัณฑ์วิทยาศาสตร์และการแพทย์
B19: เครื่องวัดอุณหภูมิ (298)
A20: 1 | B20: เครื่องวัดอุณหภูมิ ชนิดไม่สัมผัส (มือถือ) | C20: 298-63-0011 | D20: 23171 | E20: 2500 | F20: งานท่องเที่ยว | G20: / | M20: ถนนสายวัฒนธรรม(รับโอนจากสาธารณสุข)
A21: 2 | B21: เครื่องวัดอุณหภูมิ ชนิดไม่สัมผัส (มือถือ) | C21: 298-63-0012 | D21: 23171 | E21: 2500 | F21: สารบรรณ | G21: /
A22: 3 | B22: เครื่องวัดอุณหภูมิ ชนิดไม่สัมผัส (มือถือ) | C22: 298-63-0030 | D22: 23171 | E22: 2500 | F22: งานท่องเที่ยว | G22: / | M22: ถนนสายวัฒนธรรม(รับโอนจากสาธารณสุข)
A23: 4 | B23: เครื่องวัดอุณหภูมิ ชนิดไม่สัมผัส (มือถือ) | C23: 298-63-0031 | D23: 23171 | E23: 2500 | F23: งานท่องเที่ยว | G23: / | M23: ถนนสายวัฒนธรรม(รับโอนจากสาธารณสุข)
A24: 5 | B24: เครื่องวัดอุณหภูมิ ชนิดไม่สัมผัส (มือถือ) | C24: 298-63-0032 | D24: 23171 | E24: 2500 | F24: งานท่องเที่ยว | G24: / | M24: ถนนสายวัฒนธรรม(รับโอนจากสาธารณสุข)
A25: 6 | B25: เครื่องวัดอุณหภูมิระบบอินฟราเรดทางหน้าผาก | C25: 298-64-0049 | D25: 23405 | E25: 2195 | F25: ธุรการ | G25: /
B26: (ใช้งานกลางแจ้งและในอาคารพร้อมขาตั้ง,ADAPTER)
A27: 7 | B27: เครื่องวัดอุณหภูมิระบบอินฟราเรดทางหน้าผาก | C27: 298-64-0050 | D27: 23405 | E27: 2195 | F27: งานทะเบียนฯ | G27: /
B28: (ใช้งานกลางแจ้งและในอาคารพร้อมขาตั้ง,ADAPTER)
A29: 8 | B29: เครื่องวัดอุณหภูมิอินฟราเรด | C29: 298-65-0078 | D29: 242887 | E29: 1720 | F29: งานป้องกันฯ | G29: / | M29: งานป้องกัน หน่วย 1
