Workbook
Name BT_FLAG: [1]RECEIVE_TYPE!$D$2:$D$3
Name CATEGORY: [1]ASSET_CATEGORY!$A$2:$A$9
Name DEPRE: [1]CONFIG!$C$2:$C$3
Name DISPLAY: [1]CONFIG!$B$2:$B$3
Name EXPENSE_JOB_NAME: [1]EXPENSE_JOB!$B$2:$B$37
Name GETBY: [1]RECEIVE_TYPE!$B$2:$B$5

Sheet งบทรัพย์สิน 67
A1: งบทรัพย์สิน
A2: สำนักการศึกษา
A3: ณ วันที่ 30 กันยายน 2567
B4: ประเภททรัพย์สิน | C4: จำนวน | D4: งบประมาณ (บาท) | E4: หมายเหตุ
B5: ครุภัณฑ์สำนักงาน | C5: =สำนักงาน!A870 -> 865 | D5: =สำนักงาน!F871 -> 12530512
B6: ครุภัณฑ์ยานพาหนะและขนส่ง | C6: =ยานพาหนะ!A6 -> 1 | D6: =ยานพาหนะ!F7 -> 50000
B7: ครุภัณฑ์ไฟฟ้าและวิทยุ | C7: =ไฟฟ้าและวิทยุ!A180 -> 175 | D7: =ไฟฟ้าและวิทยุ!F181 -> 3035818.4
B8: ครุภัณฑ์โฆษณาและเผยแพร่ | C8: =โฆษณา!A51 -> 46 | D8: =โฆษณา!F52 -> 4061756.1
B9: ครุภัณฑ์การเกษตร | C9: =การเกษตร!A8 -> 3 | D9: =การเกษตร!F9 -> 46650
B10: ครุภัณฑ์โรงงาน | C10: =โรงงาน!A7 -> 2 | D10: =โรงงาน!F8 -> 7200
B11: ครุภัณฑ์ก่อสร้าง | C11: =ก่อสร้าง!A6 -> 1 | D11: =ก่อสร้าง!F7 -> 3600
B12: ครุภัณฑ์สำรวจ | C12: - | D12: -
B13: ครุภัณฑ์วิทยาศาสตร์และการแพทย์ | C13: =วิทยาศาสตร์!A17 -> 12 | D13: =วิทยาศาสตร์!F18 -> 83170
B14: ครุภัณฑ์คอมพิวเตอร์ | C14: =คอมพิวเตอร์!A295 -> 290 | D14: =คอมพิวเตอร์!F296 -> 6001896.5
B15: ครุภัณฑ์การศึกษา | C15: =การศึกษา!A10 -> 5 | D15: =การศึกษา!F11 -> 130000
B16: ครุภัณฑ์งานบ้านงานครัว | C16: =งานบ้าน!A50 -> 45 | D16: =งานบ้าน!F51 -> 500556
B17: ครุภัณฑ์กีฬา | C17: =กีฬา!A282 -> 277 | D17: =กีฬา!F283 -> 24048741
B18: ครุภัณฑ์ดนตรีและนาฎศิลป์ | C18: - | D18: -
B19: ครุภัณฑ์อื่น | C19: =อื่นๆ!A16 -> 11 | D19: =อื่นๆ!F17 -> 982556
B20: รวม | C20: =SUM(C5:C19) -> 1733 | D20: =SUM(D5:D19) -> 51482456

Sheet ต่ำกว่าเกณฑ์67
A1: ทะเบียนรายงานผลการตรวจนับครุภัณฑ์ (ต่ำกว่าเกณฑ์) ประจำปี 2567
A2: ( ณ วันที่ 30 กันยายน 2567)
A3: ลำดับที่ | B3: รายการ | C3: หมายเลขครุภัณฑ์ | D3: วัน เดือน ปี ที่ได้มา | E3: ราคาที่ได้มา | F3: สถานที่ใช้งาน | G3: สภาพครุภัณฑ์ | M3: หมายเหตุ
G4: ใช้ได้ | H4: ชำรุด | I4: เสื่อม สภาพ | J4: สูญหาย | K4: เก็บไว้นาน | L4: หมดความจำเป็น
A7: =ROW()-ROW($A$7)+1 -> 1 | B7: ชุดโต๊ะทำงานเข้ามุม ขนาด 1.20 เมตร | C7: 400-55-0012 | D7: 20142 | E7: 3200 | F7: สำนักศึกษา ชั้น 2 | G7: √ | M7: หน.พิมพร ชั้น2 | N7: =SUM(E7:E36) -> 84311.305
A8: =ROW()-ROW($A$7)+1 -> 2 | B8: โต๊ะคอมพิวเตอร์ ขนาด 120X60X75 ซม. | C8: 400-55-0013 | D8: 20142 | E8: 4990 | F8: สำนักศึกษา ชั้น 2 | G8: √ | M8: หน.พิมพร ชั้น2
A9: =ROW()-ROW($A$7)+1 -> 3 | B9: โต๊ะทำงาน ขนาด 60 X120 ซม. | C9: 400-55-0024 | D9: 20225 | E9: 3200 | F9: สำนักศึกษา ชั้น 2 | H9: √ | M9: ธีรนันท์
A10: =ROW()-ROW($A$7)+1 -> 4 | B10: โต๊ะทำงาน ขนาด 60 X120 ซม. | C10: 400-55-0025 | D10: 20225 | E10: 3200 | F10: สำนักศึกษา ชั้น 2 | H10: √ | M10: ชัชวาลย์
A11: =ROW()-ROW($A$7)+1 -> 5 | B11: โต๊ะทำงาน ขนาด 60 X120 ซม. | C11: 400-55-0014 | D11: 20163 | E11: 3200 | F11: สำนักศึกษา ชั้น 2 | G11: √ | M11: วิภาดา
A12: =ROW()-ROW($A$7)+1 -> 6 | B12: โต๊ะคอมพิวเตอร์ ขนาด 120X60X75 ซม. | C12: 400-55-0028 | D12: 16 พ.ค. 55 | E12: 3200 | F12: สำนักศึกษา ชั้น 3 | G12: √ | M12: อาคารอเนกประสงค์ | N12: ไปศูนย์เยาวชน | O12: เดิม พี่อ้อ
A13: =ROW()-ROW($A$7)+1 -> 7 | B13: โต๊ะคอมพิวเตอร์ ขนาด 120X60X75 ซม. | C13: 400-55-0029 | D13: 16 พ.ค. 55 | E13: 3200 | F13: สำนักศึกษา ชั้น 3 | H13: √ | M13: ขวัญภิรมย์
A14: =ROW()-ROW($A$7)+1 -> 8 | B14: โต๊ะคอมพิวเตอร์ ขนาด 120X60X75 ซม. | C14: 400-55-0030 | D14: 16 พ.ค. 55 | E14: 3200 | F14: สำนักศึกษา ชั้น 2 | G14: √ | M14: พิมล
A15: =ROW()-ROW($A$7)+1 -> 9 | B15: โต๊ะคอมพิวเตอร์ ขนาด 120X60X75 ซม. | C15: 400-55-0031 | D15: 16 พ.ค. 55 | E15: 3200 | F15: สำนักศึกษา ชั้น 2 | G15: √ | M15: สิริพร
A16: =ROW()-ROW($A$7)+1 -> 10 | B16: โต๊ะคอมพิวเตอร์ ขนาด 80X60X75 ซม. | C16: 400-55-0032 | D16: 16 พ.ค. 55 | E16: 1500 | F16: สำนักศึกษา ชั้น 2 | G16: √ | M16: นริศรา
A17: =ROW()-ROW($A$7)+1 -> 11 | B17: โต๊ะคอมพิวเตอร์ ขนาด 80X60X75 ซม. | C17: 400-55-0033 | D17: 16 พ.ค. 55 | E17: 1500 | F17: สำนักศึกษา ชั้น 3 | G17: √ | M17: กนกวรรณ
A18: =ROW()-ROW($A$7)+1 -> 12 | B18: โต๊ะทำงาน ขนาด 80 X660X75 ซม. | C18: 400-55-0061 | D18: 4 ก.ย. 55 | E18: 5000 | F18: ห้อง ผอ.สำนัก | G18: √ | M18: ห้อง ผอ.สำนัก
A19: =ROW()-ROW($A$7)+1 -> 13 | B19: โต๊ะไม้วางอุปกรณ์ ขนาด 60X120X45 ซม. | C19: 400-55-0062 | D19: 4 ก.ย. 55 | E19: 2000 | F19: ห้อง ผอ.สำนัก | G19: √ | M19: ห้อง ผอ.สำนัก
A20: =ROW()-ROW($A$7)+1 -> 14 | B20: โต๊ะไม้วางอุปกรณ์ ขนาด 60 X120X45 ซม. | C20: 400-55-0063 | D20: 4 ก.ย. 55 | E20: 2000 | F20: ห้อง ผอ.สำนัก | G20: √ | M20: ห้อง ผอ.สำนัก
A21: =ROW()-ROW($A$7)+1 -> 15 | B21: โต๊ะกลางชุดรับแขกไม้สัก ขนาด 45 X53X45 ซม. | C21: 400-55-0064 | D21: 4 ก.ย. 55 | E21: 3500 | F21: ห้อง ผอ.สำนัก | G21: √ | M21: ห้อง ผอ.สำนัก
A22: =ROW()-ROW($A$7)+1 -> 16 | B22: โต๊ะคอมพิวเตอร์ ขนาด 80X60X75 ซม. | C22: 400-56-0084 | D22: 24 มิ.ย.56 | E22: 1800 | F22: สำนักศึกษา ชั้น 2 | G22: √ | M22: ข้างพิมล
A23: =ROW()-ROW($A$7)+1 -> 17 | B23: โต๊ะคอมพิวเตอร์ ขนาด 80X60X75 ซม. | C23: 400-56-0085 | D23: 24 มิ.ย.56 | E23: 1800 | F23: สำนักศึกษา ชั้น 2 | G23: √ | M23: ธีรนันท์
A24: =ROW()-ROW($A$7)+1 -> 18 | B24: โต๊ะคอมพิวเตอร์ ขนาด 80X60X75 ซม. | C24: 400-56-0086 | D24: 24 มิ.ย.56 | E24: 1800 | F24: สำนักศึกษา ชั้น 2 | G24: √ | M24: กันต์กนิษฐ์
A25: =ROW()-ROW($A$7)+1 -> 19 | B25: โต๊ะคอมพิวเตอร์ ขนาด 80X60X75 ซม. | C25: 400-56-0087 | D25: 24 มิ.ย.56 | E25: 1800 | F25: สำนักศึกษา ชั้น 3 | G25: √ | M25: กฤตาณัฐ
... A35: =ROW()-ROW($A$7)+1 -> 29 | B35: โต๊ะประชุมขนาด 150X60X75 ซม. | C35: 400-56-0121 | D35: 6 ก.ย.56 | E35: 2900 | F35: สำนักศึกษา ชั้น 3 | G35: √ | M35: เบญจมาภรณ์
A36: =ROW()-ROW($A$7)+1 -> 30 | B36: โต๊ะคอมพิวเตอร์สีน้ำตาล | C36: 400-58-0253 (ต) | D36: 240470 | E36: 2421.3054 | F36: สำนักศึกษา ชั้น 2 | G36: √ | M36: ภัทราภรณ์
A37: =ROW()-ROW($A$7)+1 -> 31 | B37: เก้าอี้ทำงานพนักพิงตาข่าย | C37: 401-55-0024 | D37: 15 มี.ค.55 | E37: 2000 | F37: สำนักศึกษา ชั้น 2 | G37: √ | M37: ธีรนันท์ | N37: เดิมติ๊กตอนนี้แอปเปิ้ล | O37: =SUM(E37:E45) -> 24900
A38: =ROW()-ROW($A$7)+1 -> 32 | B38: เก้าอี้ปรับระดับเอนได้ | C38: 401-55-0178 | D38: 22ก.พ.55 | E38: 4500 | F38: สำนักศึกษา ชั้น 2 | G38: √ | M38: ห้องประชุมชั้น3
A39: =ROW()-ROW($A$7)+1 -> 33 | B39: เก้าอี้ทำงานพนักพิงตาข่าย | C39: 401-55-0036 | D39: 16 พ.ค.55 | E39: 2000 | F39: สำนักศึกษา ชั้น 2 | G39: √ | M39: พิมพร | N39: เหลือใช้
A40: =ROW()-ROW($A$7)+1 -> 34 | B40: เก้าอี้กลมพลาสติก | C40: 401-55-0181 | D40: 16 พ.ค.55 | E40: 200 | F40: สำนักศึกษา ชั้น 3 | G40: √ | M40: ชั้น3
A41: =ROW()-ROW($A$7)+1 -> 35 | B41: เก้าอี้กลมพลาสติก | C41: 401-55-0183 | D41: 16 พ.ค.55 | E41: 200 | F41: สำนักศึกษา ชั้น 3 | G41: √ | M41: ชั้น3
A42: =ROW()-ROW($A$7)+1 -> 36 | B42: เก้าอี้ทำงานพนักพิงตาข่าย | C42: 401-55-0034 | D42: 16 พ.ค.55 | E42: 2000 | F42: สำนักศึกษา ชั้น 2 | G42: √ | M42: เบญจมาภรณ์ | N42: เหลือใช้
A43: =ROW()-ROW($A$7)+1 -> 37 | B43: เก้าอี้โซฟารับแขกไม้สักบุฟองน้ำชนิดเดียว | C43: 401-55-0172 | D43: 4 ก.ย.55 | E43: 4500 | F43: ห้อง ผอ.สำนักฯ | G43: √ | M43: ห้อง ผอ.สำนักฯ
A44: =ROW()-ROW($A$7)+1 -> 38 | B44: เก้าอี้โซฟารับแขกไม้สักบุฟองน้ำชนิดเดียว | C44: 401-55-0173 | D44: 4 ก.ย.55 | E44: 4500 | F44: ห้อง ผอ.สำนักฯ | G44: √ | M44: ห้อง ผอ.สำนักฯ
A45: =ROW()-ROW($A$7)+1 -> 39 | B45: เก้าอี้นวมมีพนักพิงล้อเลื่อน | C45: 401-55-0174 | D45: 4 ก.ย.55 | E45: 5000 | F45: ห้อง ผอ.สำนักฯ | G45: √ | M45: ห้อง ผอ.สำนักฯ
A46: =ROW()-ROW($A$7)+1 -> 40 | B46: ชั้นวาง 4 ชั้น มีบานเปิด | C46: 404-55-0009 | D46: 1 พ.ย.54 | E46: 4500 | F46: สำนักศึกษา ชั้น 3 | G46: √ | M46: นัทธ์หทัย ชั้น 3 | N46: หอปูมละกอน
A47: =ROW()-ROW($A$7)+1 -> 41 | B47: กล่องเอนกประสงค์ 3 ชั้น ใส่เอกสาร 42X78X30 | C47: 404-55-0010 | D47: 16 พ.ค.55 | E47: 350 | F47: สำนักศึกษา ชั้น 2 | G47: √ | M47: ณัญธิดา | N47: =SUM(E47:E54) -> 2800
A48: =ROW()-ROW($A$7)+1 -> 42 | B48: กล่องเอนกประสงค์ 3 ชั้น ใส่เอกสาร 42X78X30 | C48: 404-55-0011 | D48: 16 พ.ค.55 | E48: 350 | F48: สำนักศึกษา ชั้น 3 | G48: √ | M48: ณัญธิดา
A49: =ROW()-ROW($A$7)+1 -> 43 | B49: กล่องเอนกประสงค์ 3 ชั้น ใส่เอกสาร 42X78X30 | C49: 404-55-0012 | D49: 16 พ.ค.55 | E49: 350 | F49: สำนักศึกษา ชั้น 2 | G49: √ | M49: ณัญธิดา
A50: =ROW()-ROW($A$7)+1 -> 44 | B50: กล่องเอนกประสงค์ 3 ชั้น ใส่เอกสาร 42X78X30 | C50: 404-55-0013 | D50: 16 พ.ค.55 | E50: 350 | F50: สำนักศึกษา ชั้น 2 | G50: √ | M50: ณัญธิดา
A51: =ROW()-ROW($A$7)+1 -> 45 | B51: กล่องเอนกประสงค์ 3 ชั้น ใส่เอกสาร 42X78X30 | C51: 404-55-0014 | D51: 16 พ.ค.55 | E51: 350 | F51: สำนักศึกษา ชั้น 2 | G51: √ | M51: ณัญธิดา
...

Sheet งบ67
A1: งบทรัพย์สินเทศบาลนครลำปาง
A2: หน่วยงาน สำนักการศึกษา เทศบาลนครลำปาง
A3: ณ วันที่ 30 กันยายน 2567
A4: ประเภททรัพย์สิน | B4: รหัสพัสดุ | C4: ครุภัณฑ์ (ปกติ) | E4: ครุภัณฑ์ต่ำกว่าเกณฑ์ (วัสดุ)
C5: จำนวนรายการ | D5: จำนวนเงินที่ได้มา | E5: จำนวนรายการ | F5: จำนวนเงินที่ได้มา
A6: ก. อสังหาริมทรัพย์
A7: 1. ที่ดิน | B7: 001
A8: 2. อาคารและโรงเรียน | B8: 040 | C8: 21 | D8: 50888357
A9: 3. สิ่งก่อสร้างอื่น
A10: 3.1 สิ่งปลูกสร้าง | B10: 040 | C10: 5 | D10: 896034.59
A11: 3.2 โรงเรียน
A12: อาคารหอมุด | B12: 010
A13: อาคารโรงพละศึกษา
A14: อาคารโรงอาหาร | B14: 042
A15: 3.3 อาคารห้องน้ำ ห้องส้วม | B15: 045
A16: 3.4 บ้านพักข้าราชการท้องถิ่น | B16: 090
A17: 3.5 สาธารณูปโภค
A18: ระบบปะปา | B18: 109
A19: ระบบไฟฟ้า | B19: 110
A20: ถังบำบัดน้ำเสีย | B20: 112
A21: 3.6 สะพาน | B21: 150
A22: 3.7 ทางระบายน้ำ | B22: 188
A23: 3.8 สระน้ำ | B23: 257
A24: 3.9 รั้ว กำแพง | B24: 277
A25: 3.10 อื่นๆ
A26: 3.12.1 หอกระจายข่าว | B26: 271
A27: รวมอสังหาริมทรัพย์ | C27: =SUM(C7:C26) -> 26 | D27: =SUM(D7:D26) -> 51784392
A44: ข.สังหาริมทรัพย์
A45: 1. ครุภัณฑ์สำนักงาน | G45: =SUM(D46:D92) -> 12530512
A46: ป้ายปิดประกาศ | B46: 081 | C46: 19 | D46: =สำนักงาน!O24 -> 320145.87
A47: โต๊ะ | B47: 400 | C47: 163 | D47: =สำนักงาน!O870 -> 641565.7 | E47: 30 | F47: =ต่ำกว่าเกณฑ์67!N7 -> 84311.305 | G47: =SUM(C46:C92) -> 865
A48: เก้าอี้ | B48: 401 | C48: 317 | D48: =สำนักงาน!O499 -> 764261.99 | E48: 9 | F48: =ต่ำกว่าเกณฑ์67!O37 -> 24900
A49: ม้านั่ง | B49: 402 | C49: 12 | D49: =สำนักงาน!O511 -> 73000
A50: ชุดรับแขก | B50: 403 | C50: 12 | D50: =สำนักงาน!O523 -> 143240
A51: ชั้นวางของ | B51: 404 | C51: 56 | D51: =สำนักงาน!O579 -> 358380 | E51: 1 | F51: =4500 -> 4500
A52: กล่องเอนกประสงค์ | B52: 404 | E52: 8 | F52: =ต่ำกว่าเกณฑ์67!N47 -> 2800
A53: โพเดียม แท่นกล่าวรายงาน | B53: 405 | C53: 2 | D53: =สำนักงาน!O580 -> 54000
A54: ตู้ | B54: 406 | C54: 103 | D54: =สำนักงาน!O582 -> 564624.66 | E54: 13 | F54: =ต่ำกว่าเกณฑ์67!N55 -> 46000
A55: กระดาน, ไวท์บอร์ด,บอร์ดนิทรรศการ | B55: 407 | C55: 67 | D55: =สำนักงาน!O751 -> 8460612
A56: นาฬิกา | B56: 408
...

Sheet สำนักงาน
A1: ทะเบียนรายงานผลการตรวจนับครุภัณฑ์ของสำนักการศึกษา ประจำปี 2567
A2: ณ วันที่ 30 กันยายน 2567 (เทศบัญญัติ)
A3: ครุภัณฑ์สำนักงาน
A4: ลำดับที่ | B4: รายการ | C4: หมายเลข E-laas | D4: หมายเลขครุภัณฑ์ | E4: วัน เดือน ปี ที่ได้มา | F4: ราคาที่ได้มา | G4: สถานที่ใช้งาน | H4: สภาพครุภัณฑ์
H5: ใช้ได้ | I5: ชำรุด | J5: เสื่อมสภาพ | K5: สูญหาย | L5: เก็บไว้นาน | M5: หมดความจำเป็น | N5: หมายเหตุ
A6: =ROW()-ROW(สำนักงาน!$A$6)+1 -> 1 | B6: ป้ายตัวหนังสือแผ่นทองเหลืองหนาไม่น้อยกว่า 0.7 มม กัดกรด 1 สี รองฐานป้าย MDF หนาไม่น้อยกว่า 8 มม. | C6: 401-631012-00293 | D6: 081-63-0019 | E6: 30 มี.ค. 63 | F6: 4815 | G6: งานพิพิธภัณฑ์ (มิวเซียม) | H6: √ | N6: ห้องอเนกประสงค์
A7: =ROW()-ROW(สำนักงาน!$A$6)+1 -> 2 | B7: ป้ายตัวหนังสือแผ่นทองเหลืองหนาไม่น้อยกว่า 0.7 มม กัดกรด 1 สี รองฐานป้าย MDF หนาไม่น้อยกว่า 8 มม. | C7: 401-631012-00294 | D7: 081-63-0020 | E7: 30 มี.ค. 63 | F7: 4815 | G7: งานพิพิธภัณฑ์ (มิวเซียม) | H7: √ | N7: ห้องน้ำชายปีกซ้าย
A8: =ROW()-ROW(สำนักงาน!$A$6)+1 -> 3 | B8: ป้ายตัวหนังสือแผ่นทองเหลืองหนาไม่น้อยกว่า 0.7 มม กัดกรด 1 สี รองฐานป้าย MDF หนาไม่น้อยกว่า 8 มม. | C8: 401-631012-00295 | D8: 081-63-0021 | E8: 30 มี.ค. 63 | F8: 5136 | G8: งานพิพิธภัณฑ์ (มิวเซียม) | H8: √ | N8: ห้องน้ำหญิงปีกซ้าย
A9: =ROW()-ROW(สำนักงาน!$A$6)+1 -> 4 | B9: ป้ายตัวหนังสือแผ่นทองเหลืองหนาไม่น้อยกว่า 0.7 มม กัดกรด 1 สี รองฐานป้าย MDF หนาไม่น้อยกว่า 8 มม. | C9: 401-631012-00296 | D9: 081-63-0022 | E9: 30 มี.ค. 63 | F9: 5136 | G9: งานพิพิธภัณฑ์ (มิวเซียม) | H9: √ | N9: ห้องนิทรรศการหมุนเวียน
A10: =ROW()-ROW(สำนักงาน!$A$6)+1 -> 5 | B10: ป้ายตัวหนังสือแผ่นทองเหลืองหนาไม่น้อยกว่า 0.7 มม กัดกรด 1 สี รองฐานป้าย MDF หนาไม่น้อยกว่า 8 มม. | C10: 401-631012-00297 | D10: 081-63-0023 | E10: 30 มี.ค. 63 | F10: 5136 | G10: งานพิพิธภัณฑ์ (มิวเซียม) | H10: √ | N10: ห้องสื่อมัลติมีเดีย
A11: =ROW()-ROW(สำนักงาน!$A$6)+1 -> 6 | B11: ป้ายตัวหนังสือแผ่นทองเหลืองหนาไม่น้อยกว่า 0.7 มม กัดกรด 1 สี รองฐานป้าย MDF หนาไม่น้อยกว่า 8 มม. | C11: 401-631012-00298 | D11: 081-63-0024 | E11: 30 มี.ค. 63 | F11: 5136 | G11: งานพิพิธภัณฑ์ (มิวเซียม) | H11: √ | N11: ห้องน้ำ
A12: =ROW()-ROW(สำนักงาน!$A$6)+1 -> 7 | B12: ป้ายตัวหนังสือแผ่นทองเหลืองหนาไม่น้อยกว่า 0.7 มม กัดกรด 1 สี รองฐานป้าย MDF หนาไม่น้อยกว่า 8 มม. | C12: 401-631012-00299 | D12: 081-63-0025 | E12: 30 มี.ค. 63 | F12: 5136 | G12: งานพิพิธภัณฑ์ (มิวเซียม) | H12: √ | N12: ห้องอเนกประสงค์
A13: =ROW()-ROW(สำนักงาน!$A$6)+1 -> 8 | B13: ป้ายตัวหนังสือแผ่นทองเหลืองหนาไม่น้อยกว่า 0.7 มม กัดกรด 1 สี รองฐานป้าย MDF หนาไม่น้อยกว่า 8 มม. | C13: 401-631012-00300 | D13: 081-63-0026 | E13: 30 มี.ค. 63 | F13: 5136 | G13: งานพิพิธภัณฑ์ (มิวเซียม) | H13: √ | N13: ห้องนิทรรศการถาวร
A14: =ROW()-ROW(สำนักงาน!$A$6)+1 -> 9 | B14: ป้ายตัวหนังสือแผ่นทองเหลืองหนาไม่น้อยกว่า 0.7 มม กัดกรด 1 สี รองฐานป้าย MDF หนาไม่น้อยกว่า 8 มม. | C14: 401-631012-00301 | D14: 081-63-0027 | E14: 30 มี.ค. 63 | F14: 5136 | G14: งานพิพิธภัณฑ์ (มิวเซียม) | H14: √ | N14: ห้องน้ำปีกขวาฝั่ง TK
A15: =ROW()-ROW(สำนักงาน!$A$6)+1 -> 10 | B15: ป้ายตัวหนังสือแผ่นทองเหลืองหนาไม่น้อยกว่า 0.7 มม กัดกรด 1 สี รองฐานป้าย MDF หนาไม่น้อยกว่า 8 มม. | C15: 401-631012-00302 | D15: 081-63-0028 | E15: 30 มี.ค. 63 | F15: 5136 | G15: งานพิพิธภัณฑ์ (มิวเซียม) | H15: √ | N15: ห้องประชุม
A16: =ROW()-ROW(สำนักงาน!$A$6)+1 -> 11 | B16: ป้ายตัวหนังสือแผ่นทองเหลืองหนาไม่น้อยกว่า 0.7 มม กัดกรด 1 สี รองฐานป้าย MDF หนาไม่น้อยกว่า 8 มม. | C16: 401-631012-00303 | D16: 081-63-0029 | E16: 30 มี.ค. 63 | F16: 5671 | G16: งานพิพิธภัณฑ์ (มิวเซียม) | H16: √ | N16: ห้องของที่ระลึก
A17: =ROW()-ROW(สำนักงาน!$A$6)+1 -> 12 | B17: ป้ายตัวหนังสือแผ่นทองเหลืองหนาไม่น้อยกว่า 0.7 มม กัดกรด 1 สี รองฐานป้าย MDF หนาไม่น้อยกว่า 8 มม. | C17: 401-631012-00304 | D17: 081-63-0030 | E17: 30 มี.ค. 63 | F17: 6206 | G17: งานพิพิธภัณฑ์ (มิวเซียม) | H17: √ | N17: ระหว่างทางเดินชั้น 1
... A22: =ROW()-ROW(สำนักงาน!$A$6)+1 -> 17 | B22: ป้ายประชาสัมพันธ์ตารางการแสดงอะคริลิคใส ขนาดไม่น้อยกว่า 31x39 ซม. หนาไม่น้อยกว่า 5 มม ประกบพร้อมน็อตโชว์สีน้ำเงิน | C22: 401-631012-00309 | D22: 081-63-0035 | E22: 30 มี.ค. 63 | F22: 1070 | G22: งานพิพิธภัณฑ์ (มิวเซียม) | H22: √ | N22: หน้าประตูทางเข้ามิวเซียม
A23: =ROW()-ROW(สำนักงาน!$A$6)+1 -> 18 | B23: ป้ายบอกเวลาเปิด-ปิดสแตนเลสกรดสีเงิน ขนาดไม่น้อยกว่า 40x30 ซม. หนาไม่น้อยกว่า 0.70 ซม กัดกรด 1 สี ยืดน็อต โชว์สีเงิน 4 ตัว | C23: 401-631012-00310 | D23: 081-63-0036 | E23: 30 มี.ค. 63 | F23: 5029 | G23: งานพิพิธภัณฑ์ (มิวเซียม) | H23: √
A24: =ROW()-ROW(สำนักงาน!$A$6)+1 -> 19 | B24: โครงสร้างสำหรับยืดป้ายพร้อมวัสดุหุ้ม | C24: 401-631012-00288 | D24: 081-63-0037 | E24: 28 เม.ย. 63 | F24: 242035.87 | G24: งานพิพิธภัณฑ์(มิวเซียม) | H24: √ | O24: =SUM(F6:F24) -> 320145.87
A25: =ROW()-ROW(สำนักงาน!$A$6)+1 -> 20 | B25: โต๊ะทำงานระดับ 1-2 | C25: 401-310301-00002 | D25: 400-31-1760 | E25: 11383 | F25: 1200 | G25: สำนักการศึกษา ชั้น 3 | J25: √ | N25: หน้าห้องผอ.สุ
A26: =ROW()-ROW(สำนักงาน!$A$6)+1 -> 21 | B26: โต๊ะวางเครื่องคอมพิวเตอร์ | C26: 401-400106-00001 | D26: 400-40-3285 | E26: 14616 | F26: 3500 | G26: สำนักการศึกษา ชั้น 3 | H26: √ | N26: ขวัญภิรมย์
A27: =ROW()-ROW(สำนักงาน!$A$6)+1 -> 22 | B27: โต๊ะวางคอมพิวเตอร์ | C27: 410-451001-00001 | D27: 400-45-3330 | E27: 16711 | F27: 8200 | G27: สำนักการศึกษา ชั้น 3 | J27: √ | N27: สิริรัตนา
A28: =ROW()-ROW(สำนักงาน!$A$6)+1 -> 23 | B28: โต๊ะทำงาน | C28: 401-460222-00002 | D28: 400-46-5360 | E28: 16855 | F28: 2300 | G28: สำนักการศึกษา | H28: √ | N28: ผอ.นก
A29: =ROW()-ROW(สำนักงาน!$A$6)+1 -> 24 | B29: โต๊ะพิมพ์ดีดยาว | C29: 401-460222-00003 | D29: 400-46-5362 | E29: 16855 | F29: 3500 | G29: สำนักการศึกษา ชั้น 3 | H29: √ | N29: พี่โฉม ถ่ายเอกสาร
A30: =ROW()-ROW(สำนักงาน!$A$6)+1 -> 25 | B30: โต๊ะพิมพ์ดีดยาว | C30: 401-460222-00004 | D30: 400-46-5363 | E30: 16855 | F30: 3500 | G30: สำนักการศึกษา ชั้น 3 | H30: √ | N30: พี่โฉม ถ่ายเอกสาร
A31: =ROW()-ROW(สำนักงาน!$A$6)+1 -> 26 | B31: โต๊ะทำงานเจ้าหน้าที่ DH 042 B | C31: 401-460930-00001 | D31: 400-46-5397 | E31: 17075 | F31: 8600 | G31: ห้องสมุดประชาชน | H31: √
A32: =ROW()-ROW(สำนักงาน!$A$6)+1 -> 27 | B32: โต๊ะทำงานเจ้าหน้าที่ DH 042 B | C32: 401-460930-00002 | D32: 400-46-5398 | E32: 17075 | F32: 8600 | G32: ห้องสมุดประชาชน | H32: √
A33: =ROW()-ROW(สำนักงาน!$A$6)+1 -> 28 | B33: โต๊ะทำงานเจ้าหน้าที่ DH 042 B | C33: 401-640128-00001 | D33: 400-46-5399 | E33: 17075 | F33: 8600 | G33: ห้องสมุดประชาชน | H33: √
A34: =ROW()-ROW(สำนักงาน!$A$6)+1 -> 29 | B34: โต๊ะนั่งดื่มทรงกลม | C34: 401-530131-00003 | D34: 400-53-0001 | E34: 31 ม.ค. 53 | F34: 3500 | G34: หอสมุดประชาชน | H34: √
A35: =ROW()-ROW(สำนักงาน!$A$6)+1 -> 30 | B35: โต๊ะกลางทรงสามเหลี่ยม | C35: 401-530131-00004 | D35: 400-53-0004 | E35: 31 ม.ค. 53 | F35: 6000 | G35: หอสมุดประชาชน | H35: √
A36: =ROW()-ROW(สำนักงาน!$A$6)+1 -> 31 | B36: โต๊ะกลางทรงสามเหลี่ยม | C36: 401-530131-00005 | D36: 400-53-0005 | E36: 31 ม.ค. 53 | F36: 6000 | G36: หอสมุดประชาชน | H36: √
A37: =ROW()-ROW(สำนักงาน!$A$6)+1 -> 32 | B37: ชุดโต๊ะสนามหินอ่อนลายดอกไม้+เก้าอี้ไม่มีพนักพิง 4 ตัว | C37: 401-580202-00002 | D37: 400-58-5959 | E37: 21218 | F37: 3006.7 | G37: หอสมุดประชาชน | H37: √
A38: =ROW()-ROW(สำนักงาน!$A$6)+1 -> 33 | B38: ชุดโต๊ะสนามหินอ่อนลายดอกไม้+เก้าอี้ไม่มีพนักพิง 4 ตัว | C38: 401-580202-00003 | D38: 400-58-5960 | E38: 21218 | F38: 3006.7 | G38: หอสมุดประชาชน | H38: √
A39: =ROW()-ROW(สำนักงาน!$A$6)+1 -> 34 | B39: ชุดโต๊ะสนามหินอ่อนลายดอกไม้+เก้าอี้ไม่มีพนักพิง 4 ตัว | C39: 401-580202-00004 | D39: 400-58-5961 | E39: 21218 | F39: 3006.7 | G39: หอสมุดประชาชน | H39: √
A40: =ROW()-ROW(สำนักงาน!$A$6)+1 -> 35 | B40: ชุดโต๊ะสนามหินอ่อนลายดอกไม้+เก้าอี้ไม่มีพนักพิง 4 ตัว | C40: 401-580202-00005 | D40: 400-58-5962 | E40: 21218 | F40: 3006.7 | G40: หอสมุดประชาชน | H40: √
A41: =ROW()-ROW(สำนักงาน!$A$6)+1 -> 36 | B41: ชุดโต๊ะสนามหินอ่อนลายดอกไม้+เก้าอี้ไม่มีพนักพิง 4 ตัว | C41: 401-580202-00006 | D41: 400-58-5963 | E41: 21218 | F41: 3006.7 | G41: หอสมุดประชาชน | H41: √
A42: =ROW()-ROW(สำนักงาน!$A$6)+1 -> 37 | B42: ชุดโต๊ะเหล็กชุบโครเมี่ยม+เก้าอี้มีพนักพิง 4 ตัว | C42: 401-580202-00007 | D42: 400-58-5952 | E42: 21218 | F42: 7029.9 | G42: หอสมุดประชาชน | H42: √
A43: =ROW()-ROW(สำนักงาน!$A$6)+1 -> 38 | B43: ชุดโต๊ะเหล็กชุบโครเมี่ยม+เก้าอี้มีพนักพิง 4 ตัว | C43: 401-580202-00008 | D43: 400-58-5964 | E43: 21218 | F43: 7029.9 | G43: หอสมุดประชาชน | H43: √
A44: =ROW()-ROW(สำนักงาน!$A$6)+1 -> 39 | B44: ชุดโต๊ะเหล็กชุบโครเมี่ยม+เก้าอี้มีพนักพิง 4 ตัว | C44: 401-580202-00009 | D44: 400-58-5965 | E44: 21218 | F44: 7029.9 | G44: หอสมุดประชาชน | H44: √
...

Sheet คอมพิวเตอร์
A1: ทะเบียนรายงานผลการตรวจนับครุภัณฑ์ของสำนักการศึกษา ประจำปี 2567
A2: ณ วันที่ 30 กันยายน 2567 (เทศบัญญัติ)
A3: ครุภัณฑ์คอมพิวเตอร์
A4: ลำดับที่ | B4: รายการ | C4: หมายเลข E-laas | D4: หมายเลขครุภัณฑ์ | E4: วัน เดือน ปี ที่ได้มา | F4: ราคาที่ได้มา | G4: สถานที่ใช้งาน | H4: สภาพครุภัณฑ์
H5: ใช้ได้ | I5: ชำรุด | J5: เสื่อมสภาพ | K5: สูญหาย | L5: เก็บไว้นาน | M5: หมดความจำเป็น | N5: หมายเหตุ
A6: =ROW()-ROW($A$6)+1 -> 1 | B6: คอมพิวเตอร์ (CPU) | C6: 410-640217-00001 | D6: 416-45-0168 | E6: 19 ก.ค. 45 | F6: 34975 | G6: สำนักการศึกษา ชั้น 3 | I6: √ | N6: ผู้ช่วยคอมฯ | O6: =F6+F10+F11+F12+F15+F16+F17+F18+F19+F20+F21+F22+F25+F26+F28+F29+F30+F31+F32+F33+F27+F48+F50+F51+F52+F53+F54+F55+F56+F57+F58+F59+F60+F62+F64+F66+F79+F80+F83+F84+F89+F91+F93+F95+F97+F113+F114+F115+F116+F117+F123+F135+F136+F137+F138+F139+F140+F141+F142+F143+F144+F145+F146+F147+F148+F149+F150+F151+F152+F167+F168+F176+F178+F180+F182+F184+F186+F208+F209+F212+F214+F216+F218+F220+F222+F224+F226+F228+F230+F259+F260+F262+F261+F263+F273+F275+F277+F280+F281+F282+F283+F284+F287+F288+F293 -> 2610513
A7: =ROW()-ROW($A$6)+1 -> 2 | B7: จอ LCD | C7: 410-501018-00027 | D7: 416-50-0352 | E7: 18 ต.ค. 50 | F7: 5000 | G7: สำนักการศึกษา ชั้น 2 | I7: √ | N7: วก. กิ๊บชั้น 2 | O7: =F7+F13+F14+F23+F24+F34+F35+F36+F37+F38+F39+F40+F41+F42+F45+F61+F63+F65+F77+F78+F81+F82+F88+F90+F92+F94+F96+F177+F179+F181+F183+F185+F187+F213+F215+F217+F219+F221+F223+F225+F227+F229+F231+F242+F243+F244+F245+F246 -> 175005
A8: =ROW()-ROW($A$6)+1 -> 3 | B8: เครื่องสำรองไฟลูกข่าย | C8: 410-510529-00073 | D8: 416-51-0417 | E8: 29 พ.ค. 51 | F8: 7000 | G8: สำนักการศึกษา ชั้น 2 | H8: √ | N8: วก.นิติรัฐ | O8: =F8+F44+F68+F69+F98+F99+F100+F101+F102+F122+F153+F154+F155+F156+F157+F158+F159+F160+F161+F162+F163+F164+F165+F166+F171+F172+F173+F174+F175+F188+F189+F190+F191+F192+F193+F194+F195+F196+F197+F198+F199+F200+F201+F232+F233+F234+F235+F236+F237+F238+F239+F240+F241+F247+F248+F249+F250+F251+F264+F265+F266+F267+F268+F289+F290+F291+F292 -> 395910
A9: =ROW()-ROW($A$6)+1 -> 4 | B9: เครื่องพิมพ์ HP ลูกข่าย | C9: 410-510529-00078 | D9: 416-51-0452 | E9: 29 พ.ค. 51 | F9: 6140 | G9: สำนักการศึกษา ชั้น 3 | I9: √ | N9: วก.นิติรัฐ | O9: =F9+F47+F46+F49+F67+F85+F86+F87+F103+F104+F119+F169+F170+F202+F203+F204+F205+F206+F207+F210+F211+F252+F253+F254+F255+F256+F269+F270+F271+F272+F279+F278+F285+F286 -> 242850
A10: =ROW()-ROW($A$6)+1 -> 5 | B10: เครื่องคอมพิวเตอร์ CPU | C10: 410-520701-00052 | D10: 416-52-0529 | E10: 1 ก.ค. 52 | F10: 34600 | G10: สำนักการศึกษา ชั้น 2 | I10: √ | N10: วก.นิติรัฐ
A11: =ROW()-ROW($A$6)+1 -> 6 | B11: เครื่องคอมพิวเตอร์ CPU | C11: 410-520701-00053 | D11: 416-52-0530 | E11: 1 ก.ค. 52 | F11: 34600 | G11: สำนักการศึกษา ชั้น 2 | H11: √ | N11: วก.ธนศวรรณ
A12: =ROW()-ROW($A$6)+1 -> 7 | B12: เครื่องคอมพิวเตอร์ CPU | C12: 410-520701-00054 | D12: 416-52-0531 | E12: 1 ก.ค. 52 | F12: 34600 | G12: สำนักการศึกษา ชั้น 2 | H12: √ | N12: พี่อ้อ วก.
A13: =ROW()-ROW($A$6)+1 -> 8 | B13: จอภาพ LCD 20 นิ้ว | C13: 410-520701-00055 | D13: 416-52-0541 | E13: 1 ก.ค. 52 | F13: 5300 | G13: สำนักการศึกษา ชั้น 2 | H13: √ | N13: นิติรัฐ
A14: =ROW()-ROW($A$6)+1 -> 9 | B14: จอภาพ LCD 20 นิ้ว | C14: 410-520701-00057 | D14: 416-52-0543 | E14: 1 ก.ค. 52 | F14: 5300 | G14: สำนักการศึกษา ชั้น 3 | H14: √ | N14: วก. พี่อ้อ
A15: =ROW()-ROW($A$6)+1 -> 10 | B15: เครื่องคอมพิวเตอร์ ยี่ห้อ Compag Atom | C15: 410-530216-00001 | D15: 416-53-0001 | E15: 16 ก.พ. 53 | F15: 13900 | G15: หอสมุดประชาชน | H15: √
A16: =ROW()-ROW($A$6)+1 -> 11 | B16: เครื่องคอมพิวเตอร์ ยี่ห้อ Compag Atom | C16: 410-530216-00005 | D16: 416-53-0005 | E16: 16 ก.พ. 53 | F16: 13900 | G16: หอสมุดประชาชน | H16: √
A17: =ROW()-ROW($A$6)+1 -> 12 | B17: เครื่องคอมพิวเตอร์ ยี่ห้อ Compag Atom | C17: 410-530216-00006 | D17: 416-53-0006 | E17: 16 ก.พ. 53 | F17: 13900 | G17: หอสมุดประชาชน | H17: √
A18: =ROW()-ROW($A$6)+1 -> 13 | B18: เครื่องคอมพิวเตอร์ ยี่ห้อ Compag Atom | C18: 410-530216-00007 | D18: 416-53-0007 | E18: 16 ก.พ. 53 | F18: 13900 | G18: หอสมุดประชาชน | H18: √
A19: =ROW()-ROW($A$6)+1 -> 14 | B19: เครื่องคอมพิวเตอร์ Set ประกอบ | C19: 410-530304-00010 | D19: 416-53-0018 | E19: 4 มี.ค. 53 | F19: 13900 | G19: หอสมุดประชาชน | H19: √
A20: =ROW()-ROW($A$6)+1 -> 15 | B20: เครื่องคอมพิวเตอร์ Set ประกอบ | C20: 410-530304-00016 | D20: 416-53-0024 | E20: 4 มี.ค. 53 | F20: 13900 | G20: หอสมุดประชาชน | H20: √
A21: =ROW()-ROW($A$6)+1 -> 16 | B21: เครื่องคอมพิวเตอร์ Set ประกอบ | C21: 410-530304-00019 | D21: 416-53-0027 | E21: 4 มี.ค. 53 | F21: 13900 | G21: หอสมุดประชาชน | H21: √
A22: =ROW()-ROW($A$6)+1 -> 17 | B22: คอมพิวเตอร์ Acer | C22: 410-630217-00001 | D22: 416-55-0698 | E22: 20311 | F22: 21900 | G22: สำนักการศึกษา ชั้น 2 | H22: √ | N22: วก.รัญญากร
A23: =ROW()-ROW($A$6)+1 -> 18 | B23: จอภาพ ACER | C23: 410-550810-00029 | D23: 416-55-0688 | E23: 20311 | F23: 6550 | G23: สำนักการศึกษา ชั้น 3 | H23: √ | N23: ณัฐธิดา | O23: คลังเป็นเครื่องสำรองไฟ
A24: =ROW()-ROW($A$6)+1 -> 19 | B24: จอภาพ Acer | C24: 410-550810-00028 | D24: 416-55-0687 | E24: 20311 | F24: 6550 | G24: สำนักการศึกษา ชั้น2 | I24: √ | N24: วก.นิติรัฐ | O24: คลังเป็นเครื่องสำรองไฟ
A25: =ROW()-ROW($A$6)+1 -> 20 | B25: คอมพิวเตอร์ ACER Veriton (CPU) | C25: 410-630217-00002 | D25: 416-55-0699 | E25: 20311 | F25: 21900 | G25: สำนักการศึกษา ชั้น 3 | H25: √ | N25: วก.นิติรัฐ
A26: =ROW()-ROW($A$6)+1 -> 21 | B26: (CPU) คอมพิวเตอร์ตั้งโต๊ะแม่ข่าย | C26: 410-580202-00001 | D26: 416-58-1705 | E26: 21218 | F26: 127540 | G26: หอสมุดประชาชน | H26: √
A27: =ROW()-ROW($A$6)+1 -> 22 | B27: เครื่องคอมพิวเตอร์สำหรับประมวลผล แบบที่ 2 | C27: 410-600607-00016 | D27: 416-60-1284 | E27: 7 มิ.ย. 60 | F27: 23800 | G27: มิวเซี่ยม(ลำปาง) | H27: √ | N27: อรทัย
A28: =ROW()-ROW($A$6)+1 -> 23 | B28: (CPU) เครื่องคอมพิวเตอร์ สำหรับประมวลผล แบบที่ 1 ขนาดไม่น้อยกว่า 18 นิ้ว | C28: 410-580521-00001 | D28: 416-58-1525 | E28: 21 พ.ค. 58 | F28: 10550 | G28: หอสมุดประชาชน | H28: √ | N28: นิมิตร
A29: =ROW()-ROW($A$6)+1 -> 24 | B29: (CPU) เครื่องคอมพิวเตอร์ สำหรับประมวลผล แบบที่ 1 ขนาดไม่น้อยกว่า 18 นิ้ว | C29: 410-580521-00002 | D29: 416-58-1526 | E29: 21 พ.ค. 58 | F29: 10550 | G29: หอสมุดประชาชน | H29: √
A30: =ROW()-ROW($A$6)+1 -> 25 | B30: (CPU) เครื่องคอมพิวเตอร์ สำหรับประมวลผล แบบที่ 1 ขนาดไม่น้อยกว่า 18 นิ้ว | C30: 410-580521-00004 | D30: 416-58-1528 | E30: 21 พ.ค. 58 | F30: 10550 | G30: หอสมุดประชาชน | H30: √
A31: =ROW()-ROW($A$6)+1 -> 26 | B31: (CPU) เครื่องคอมพิวเตอร์ สำหรับประมวลผล แบบที่ 1 ขนาดไม่น้อยกว่า 18 นิ้ว | C31: 410-580521-00006 | D31: 416-58-1530 | E31: 21 พ.ค. 58 | F31: 10550 | G31: หอสมุดประชาชน | H31: √
A32: =ROW()-ROW($A$6)+1 -> 27 | B32: (CPU) เครื่องคอมพิวเตอร์ สำหรับประมวลผล แบบที่ 1 ขนาดไม่น้อยกว่า 18 นิ้ว | C32: 410-580521-00009 | D32: 416-58-1533 | E32: 21 พ.ค. 58 | F32: 10550 | G32: หอสมุดประชาชน | H32: √
A33: =ROW()-ROW($A$6)+1 -> 28 | B33: (CPU) เครื่องคอมพิวเตอร์ สำหรับประมวลผล แบบที่ 1 ขนาดไม่น้อยกว่า 18 นิ้ว | C33: 410-580521-00010 | D33: 416-58-1534 | E33: 21 พ.ค. 58 | F33: 10550 | G33: หอสมุดประชาชน | H33: √
A34: =ROW()-ROW($A$6)+1 -> 29 | B34: (จอ) คอมพิวเตอร์ตั้งโต๊ะแม่ข่าย | C34: 410-580202-00002 | D34: 416-58-1894 | E34: 2 ก.พ. 58 | F34: 3000 | G34: หอสมุดประชาชน | H34: √
A35: =ROW()-ROW($A$6)+1 -> 30 | B35: (จอ) เครื่องคอมพิวเตอร์ สำหรับประมวลผล แบบที่ 1 (ขนาดไม่น้อยกว่า 18 นิ้ว) | C35: 410-580521-00011 | D35: 416-58-1895 | E35: 21 พ.ค. 58 | F35: 3000 | G35: หอสมุดประชาชน | I35: √
A36: =ROW()-ROW($A$6)+1 -> 31 | B36: (จอ) เครื่องคอมพิวเตอร์ สำหรับประมวลผล แบบที่ 1 (ขนาดไม่น้อยกว่า 18 นิ้ว) | C36: 410-580521-00013 | D36: 416-58-1897 | E36: 21 พ.ค. 58 | F36: 3000 | G36: หอสมุดประชาชน | I36: √
A37: =ROW()-ROW($A$6)+1 -> 32 | B37: (จอ) เครื่องคอมพิวเตอร์ สำหรับประมวลผล แบบที่ 1 (ขนาดไม่น้อยกว่า 18 นิ้ว) | C37: 410-580521-00014 | D37: 416-58-1898 | E37: 21 พ.ค. 58 | F37: 3000 | G37: หอสมุดประชาชน | I37: √
A38: =ROW()-ROW($A$6)+1 -> 33 | B38: (จอ) เครื่องคอมพิวเตอร์ สำหรับประมวลผล แบบที่ 1 (ขนาดไม่น้อยกว่า 18 นิ้ว) | C38: 410-580521-00015 | D38: 416-58-1899 | E38: 21 พ.ค. 58 | F38: 3000 | G38: หอสมุดประชาชน | H38: √
A39: =ROW()-ROW($A$6)+1 -> 34 | B39: (จอ) เครื่องคอมพิวเตอร์ สำหรับประมวลผล แบบที่ 1 (ขนาดไม่น้อยกว่า 18 นิ้ว) | C39: 410-580521-00016 | D39: 416-58-1900 | E39: 21 พ.ค. 58 | F39: 3000 | G39: หอสมุดประชาชน | I39: √
A40: =ROW()-ROW($A$6)+1 -> 35 | B40: (จอ) เครื่องคอมพิวเตอร์ สำหรับประมวลผล แบบที่ 1 (ขนาดไม่น้อยกว่า 18 นิ้ว) | C40: 410-580521-00017 | D40: 416-58-1901 | E40: 21 พ.ค. 58 | F40: 3000 | G40: หอสมุดประชาชน | I40: √
...

Sheet ไฟฟ้าและวิทยุ
A1: ทะเบียนรายงานผลการตรวจนับครุภัณฑ์ของสำนักการศึกษา ประจำปี 2567
A2: ณ วันที่ 30 กันยายน 2567 (เทศบัญญัติ)
A3: ครุภัณฑ์ไฟฟ้าและวิทยุ
A4: ลำดับที่ | B4: รายการ | C4: หมายเลข E-laas | D4: หมายเลขครุภัณฑ์ | E4: วัน เดือน ปี ที่ได้มา | F4: ราคาที่ได้มา | G4: สถานที่ใช้งาน | H4: สภาพครุภัณฑ์
H5: ใช้ได้ | I5: ชำรุด | J5: เสื่อมสภาพ | K5: สูญหาย | L5: เก็บไว้นาน | M5: หมดความจำเป็น | N5: หมายเหตุ
A6: =ROW()-ROW($A$6)+1 -> 1 | B6: Sequence Controller (local) | C6: 410-540119-00001 | D6: 430-54-0007 | E6: 19 ม.ค. 54 | F6: 35000 | G6: พิพิธภัณฑ์หอปูมละกอน | J6: √ | O6: =F6 -> 35000
A7: =ROW()-ROW($A$6)+1 -> 2 | B7: จอมอนิเตอร์ LED ขนาด 20 นิ้ว | C7: 404-580202-00011 | D7: 452-58-0020 | E7: 21218 | F7: 2996 | G7: หอสมุดประชาชน | H7: √ | O7: =F7 -> 2996
A8: =ROW()-ROW($A$6)+1 -> 3 | B8: กล้องวงจรปิด | C8: 404-580202-00003 | D8: 454-58-0012 | E8: 21218 | F8: 4194.4 | G8: หอสมุดประชาชน | H8: √ | O8: =SUM(F8:F39) -> 874555.2
A9: =ROW()-ROW($A$6)+1 -> 4 | B9: กล้องวงจรปิด | C9: 404-580202-00004 | D9: 454-58-0013 | E9: 21218 | F9: 4194.4 | G9: หอสมุดประชาชน | H9: √
A10: =ROW()-ROW($A$6)+1 -> 5 | B10: กล้องวงจรปิด | C10: 404-580202-00005 | D10: 454-58-0014 | E10: 21218 | F10: 4194.4 | G10: หอสมุดประชาชน | H10: √
A11: =ROW()-ROW($A$6)+1 -> 6 | B11: กล้องวงจรปิด | C11: 404-580202-00006 | D11: 454-58-0015 | E11: 21218 | F11: 4194.4 | G11: หอสมุดประชาชน | H11: √
A12: =ROW()-ROW($A$6)+1 -> 7 | B12: กล้องวงจรปิด | C12: 404-580202-00007 | D12: 454-58-0016 | E12: 21218 | F12: 4194.4 | G12: หอสมุดประชาชน | H12: √
A13: =ROW()-ROW($A$6)+1 -> 8 | B13: กล้องวงจรปิด | C13: 404-580202-00008 | D13: 454-58-0017 | E13: 21218 | F13: 4194.4 | G13: หอสมุดประชาชน | H13: √
A14: =ROW()-ROW($A$6)+1 -> 9 | B14: กล้องวงจรปิด | C14: 404-580202-00009 | D14: 454-58-0018 | E14: 21218 | F14: 4194.4 | G14: หอสมุดประชาชน | H14: √
A15: =ROW()-ROW($A$6)+1 -> 10 | B15: กล้องวงจรปิด | C15: 404-580202-00010 | D15: 454-58-0019 | E15: 21218 | F15: 4194.4 | G15: หอสมุดประชาชน | H15: √
A16: =ROW()-ROW($A$6)+1 -> 11 | B16: กล้องโทรทัศน์วงจรปิดชนิดเครือข่ายแบบปรับมุมมอง | C16: 403-640928-00001 | D16: 454-64-0145 | E16: 14 ก.ย. 64 | F16: 86500 | G16: มิวเซียมลำปาง | H16: √ | N16: โถงต้อนรับ
A17: =ROW()-ROW($A$6)+1 -> 12 | B17: กล้องโทรทัศน์วงจรปิดแบบมุมมองคงที่ | C17: 403-640928-00002 | D17: 454-64-0146 | E17: 14 ก.ย. 64 | F17: 28000 | G17: มิวเซียมลำปาง | I17: √ | N17: ระหว่างทางเดินมัลติมีเดีย
A18: =ROW()-ROW($A$6)+1 -> 13 | B18: กล้องโทรทัศน์วงจรปิดแบบมุมมองคงที่ | C18: 403-640928-00003 | D18: 454-64-0147 | E18: 14 ก.ย. 64 | F18: 28000 | G18: มิวเซียมลำปาง | H18: √ | N18: หน้าห้อง TK
A19: =ROW()-ROW($A$6)+1 -> 14 | B19: กล้องโทรทัศน์วงจรปิดแบบมุมมองคงที่ | C19: 403-640928-00004 | D19: 454-64-0148 | E19: 14 ก.ย. 64 | F19: 28000 | G19: มิวเซียมลำปาง | H19: √ | N19: ห้องของที่ระลึก
A20: =ROW()-ROW($A$6)+1 -> 15 | B20: กล้องโทรทัศน์วงจรปิดแบบมุมมองคงที่ | C20: 403-640928-00005 | D20: 454-64-0149 | E20: 14 ก.ย. 64 | F20: 28000 | G20: มิวเซียมลำปาง | H20: √ | N20: หน้าตึกมิวเซียม
A21: =ROW()-ROW($A$6)+1 -> 16 | B21: กล้องโทรทัศน์วงจรปิดแบบมุมมองคงที่ | C21: 403-640928-00006 | D21: 454-64-0150 | E21: 14 ก.ย. 64 | F21: 28000 | G21: มิวเซียมลำปาง | H21: √ | N21: นอกตึกมิวเซียม
A22: =ROW()-ROW($A$6)+1 -> 17 | B22: กล้องโทรทัศน์วงจรปิดแบบมุมมองคงที่ | C22: 403-640928-00007 | D22: 454-64-0151 | E22: 14 ก.ย. 64 | F22: 28000 | G22: มิวเซียมลำปาง | H22: √ | N22: หมุนเวียนท้องถิ่น
A23: =ROW()-ROW($A$6)+1 -> 18 | B23: กล้องโทรทัศน์วงจรปิดแบบมุมมองคงที่ | C23: 403-640928-00008 | D23: 454-64-0152 | E23: 14 ก.ย. 64 | F23: 28000 | G23: มิวเซียมลำปาง | H23: √ | N23: หน้าหมุนเวียนท้องถิ่น
A24: =ROW()-ROW($A$6)+1 -> 19 | B24: กล้องโทรทัศน์วงจรปิดแบบมุมมองคงที่ | C24: 403-640928-00009 | D24: 454-64-0153 | E24: 14 ก.ย. 64 | F24: 28000 | G24: มิวเซียมลำปาง | H24: √ | N24: ระหว่างทางเดินหมุนเวียน
A25: =ROW()-ROW($A$6)+1 -> 20 | B25: กล้องโทรทัศน์วงจรปิดแบบมุมมองคงที่ | C25: 403-640928-00010 | D25: 454-64-0154 | E25: 14 ก.ย. 64 | F25: 28000 | G25: มิวเซียมลำปาง | H25: √ | N25: นอกตึกมิวเซียม
A26: =ROW()-ROW($A$6)+1 -> 21 | B26: กล้องโทรทัศน์วงจรปิดแบบมุมมองคงที่ | C26: 403-640928-00011 | D26: 454-64-0155 | E26: 14 ก.ย. 64 | F26: 28000 | G26: มิวเซียมลำปาง | H26: √ | N26: นิทรรศการหมุนเวียน
A27: =ROW()-ROW($A$6)+1 -> 22 | B27: กล้องโทรทัศน์วงจรปิดแบบมุมมองคงที่ | C27: 403-640928-00012 | D27: 454-64-0156 | E27: 14 ก.ย. 64 | F27: 28000 | G27: มิวเซียมลำปาง | H27: √ | N27: นิทรรศการหมุนเวียน
A28: =ROW()-ROW($A$6)+1 -> 23 | B28: กล้องโทรทัศน์วงจรปิดแบบมุมมองคงที่ | C28: 403-640928-00013 | D28: 454-64-0157 | E28: 14 ก.ย. 64 | F28: 28000 | G28: มิวเซียมลำปาง | H28: √ | N28: โถงต้อนรับ
A29: =ROW()-ROW($A$6)+1 -> 24 | B29: กล้องโทรทัศน์วงจรปิดแบบมุมมองคงที่ | C29: 403-640928-00014 | D29: 454-64-0158 | E29: 14 ก.ย. 64 | F29: 28000 | G29: มิวเซียมลำปาง | H29: √ | N29: ระหว่างทางเดิน ชั้น 2
... A39: =ROW()-ROW($A$6)+1 -> 34 | B39: อุปกรณ์กระจายสัญญาณแบบ POE | C39: 403-640928-00024 | D39: 454-64-0168 | E39: 14 ก.ย. 64 | F39: 49500 | G39: มิวเซียมลำปาง | H39: √ | N39: ห้องระบบ TK
A40: =ROW()-ROW($A$6)+1 -> 35 | B40: PM 3 Player With controller (local) (ชุดตลาดนานาชาติ) | C40: 403-540119-00001 | D40: 455-54-0003 | E40: 19 ม.ค. 54 | F40: 20000 | G40: พิพิธภัณฑ์หอปูมละกอน | J40: √ | O40: =SUM(F40:F42) -> 53910
A41: =ROW()-ROW($A$6)+1 -> 36 | B41: PM 3 Player With controller (local) | C41: 403-540119-00007 | D41: 455-54-0005 | E41: 19 ม.ค. 54 | F41: 20000 | G41: พิพิธภัณฑ์หอปูมละกอน | J41: √ | P41: เดิม 452 เปลี่ยนเป็น 454 เมื่อวันที่ 14 ม.ค. 63
A42: =ROW()-ROW($A$6)+1 -> 37 | B42: เครื่องเล่นมัลติมีเดีย PLAYER USB MP3 CD ยี่ห้อ NPE รุ่น UDP-3MX | C42: 403-670926-00032 | D42: 455-67-0064 | E42: 24676 | F42: 13910 | G42: งานกีฬาและนันทนาการ | H42: √ | N42: โฮงละกอน | O42: ******
A43: =ROW()-ROW($A$6)+1 -> 38 | B43: ชุดไมค์ลอย พร้อมตัวรับสัญญาณ | C43: 403-580202-00001 | D43: 458-58-0046 | E43: 2 ก.พ. 58 | F43: 1999.83 | G43: หอสมุดประชาชน | H43: √ | O43: =SUM(F43:F58) -> 63107.58
A44: =ROW()-ROW($A$6)+1 -> 39 | B44: ชุดไมค์ลอย พร้อมตัวรับสัญญาณ | C44: 403-580202-00002 | D44: 458-58-0047 | E44: 2 ก.พ. 58 | F44: 1999.83 | G44: หอสมุดประชาชน | H44: √
A45: =ROW()-ROW($A$6)+1 -> 40 | B45: ไมค์สาย | C45: 403-580202-00003 | D45: 458-58-0048 | E45: 2 ก.พ. 58 | F45: 800.36 | G45: หอสมุดประชาชน | H45: √
A46: =ROW()-ROW($A$6)+1 -> 41 | B46: ไมค์สาย | C46: 403-580202-00004 | D46: 458-58-0049 | E46: 2 ก.พ. 58 | F46: 800.36 | G46: หอสมุดประชาชน | H46: √
A47: =ROW()-ROW($A$6)+1 -> 42 | B47: ชุดไมค์ลอยพร้อมตัวรับสัญญาณ ยี่ห้อ NTS รุ่น SL-802 | C47: 403-62111-00302 | D47: 458-62-0194 | E47: 30 พ.ย. 61 | F47: 3745 | G47: มิวเซี่ยม(ลำปาง) | H47: √ | N47: โถงต้อนรับ
A48: =ROW()-ROW($A$6)+1 -> 43 | B48: ไมค์สายคุณภาพดี ยี่ห้อ NTS รุ่น B.58 จำนวน 2 อัน | C48: 403-62111-00303 | D48: 458-62-0195 | E48: 30 พ.ย. 61 | F48: 963 | G48: มิวเซี่ยม(ลำปาง) | H48: √ | N48: โถงต้อนรับ
A49: =ROW()-ROW($A$6)+1 -> 44 | B49: ชุดไมค์ลอย 2 ตัว พร้อมรับสัญญาณ | C49: 403-631012-00068 | D49: 458-63-0200 | E49: 30 มี.ค. 63 | F49: 3424 | G49: งานพิพิธภัณฑ์(มิวเซียม) | H49: √ | N49: ห้องสื่อมัลติมีเดีย
...

Sheet การศึกษา
A1: ทะเบียนรายงานผลการตรวจนับครุภัณฑ์ของสำนักการศึกษา ประจำปี 2567
A2: ณ วันที่ 30 กันยายน 2567 (เทศบัญญัติ)
A3: ครุภัณฑ์การศึกษา
A4: ลำดับที่ | B4: รายการ | C4: หมายเลข E-laas | D4: หมายเลขครุภัณฑ์ | E4: วัน เดือน ปี ที่ได้มา | F4: ราคาที่ได้มา | G4: สถานที่ใช้งาน | H4: สภาพครุภัณฑ์
H5: ใช้ได้ | I5: ชำรุด | J5: เสื่อมสภาพ | K5: สูญหาย | L5: เก็บไว้นาน | M5: หมดความจำเป็น | N5: หมายเหตุ
A6: =ROW()-ROW($A$6)+1 -> 1 | B6: หุ่นไฟเบอร์จำลองคนผู้ชาย แบบลอยตัว พร้อมเสื้อผ้า 1 ตัว | C6: 411-540119-00001 | D6: 500-54-0001 | E6: 19 ม.ค. 54 | F6: 53000 | G6: พิพิธภัณฑ์หอปูมละกอน | H6: √
A7: =ROW()-ROW($A$6)+1 -> 2 | B7: หุ่นไฟเบอร์จำลองเด็กผู้หญิงแบบลอยตัว พร้อมเสื้อผ้า 1 ตัว | C7: 411-540119-00002 | D7: 500-54-0002 | E7: 19 ม.ค. 54 | F7: 26000 | G7: พิพิธภัณฑ์หอปูมละกอน | H7: √
A8: =ROW()-ROW($A$6)+1 -> 3 | B8: เค้าโครงร่างแม่ค้าผู้หญิงแบบเต็มตัว | C8: 411-540119-00003 | D8: 500-54-0004 | E8: 19 ม.ค. 54 | F8: 6000 | G8: พิพิธภัณฑ์หอปูมละกอน | H8: √
A9: =ROW()-ROW($A$6)+1 -> 4 | B9: ตัวอย่างจำลองสินค้าเบ็ดเตล็ด | C9: 411-540119-00004 | D9: 500-54-0006 | E9: 19 ม.ค. 54 | F9: 35000 | G9: พิพิธภัณฑ์หอปูมละกอน | H9: √
A10: =ROW()-ROW($A$6)+1 -> 5 | B10: อุปกรณ์ตกแต่งในตลาด 1 ชุด | C10: 411-540119-00005 | D10: 500-54-0007 | E10: 19 ม.ค. 54 | F10: 10000 | G10: พิพิธภัณฑ์หอปูมละกอน | H10: √
B11: จำนวน 5 รายการ | F11: =SUBTOTAL(9,F6:F10) -> 130000

Sheet ยานพาหนะ
A1: ทะเบียนรายงานผลการตรวจนับครุภัณฑ์ของสำนักการศึกษา ประจำปี 2567
A2: ณ วันที่ 30 กันยายน 2567 (เทศบัญญัติ)
A3: ครุภัณฑ์ยานพาหนะและขนส่ง
A4: ลำดับที่ | B4: รายการ | C4: หมายเลข E-laas | D4: หมายเลขครุภัณฑ์ | E4: วัน เดือน ปี ที่ได้มา | F4: ราคาที่ได้มา | G4: สถานที่ใช้งาน | H4: สภาพครุภัณฑ์
H5: ใช้ได้ | I5: ชำรุด | J5: เสื่อมสภาพ | K5: สูญหาย | L5: เก็บไว้นาน | M5: หมดความจำเป็น | N5: หมายเหตุ
A6: =ROW()-ROW(อื่นๆ!$A$6)+1 -> 1 | B6: รถจักยานยนต์ HONDA SOOPY-I | C6: 402-660830-00001 | D6: 024-66-0112 | E6: 23 พ.ย. 65 | F6: 50000 | G6: สำนักการศึกษา เทศบาลนครลำปาง | H6: √
B7: จำนวน 1 รายการ | F7: =SUBTOTAL(9,F6:F6) -> 50000

Sheet งานบ้าน
A1: ทะเบียนรายงานผลการตรวจนับครุภัณฑ์ของสำนักการศึกษา ประจำปี 2567
A2: ณ วันที่ 30 กันยายน 2567 (เทศบัญญัติ)
A3: ครุภัณฑ์งานบ้านงานครัว
A4: ลำดับที่ | B4: รายการ | C4: หมายเลข E-laas | D4: หมายเลขครุภัณฑ์ | E4: วัน เดือน ปี ที่ได้มา | F4: ราคาที่ได้มา | G4: สถานที่ใช้งาน | H4: สภาพครุภัณฑ์
H5: ใช้ได้ | I5: ชำรุด | J5: เสื่อมสภาพ | K5: สูญหาย | L5: เก็บไว้นาน | M5: หมดความจำเป็น | N5: หมายเหตุ
A6: =ROW()-ROW(สำนักงาน!$A$6)+1 -> 1 | B6: ผ้าม่านหน้าต่าง 2 ชั้น พร้อมอุปกรณ์ สีครีม | C6: 412-62111-00017 | D6: 434-62-0039 | E6: 30 พ.ย. 61 | F6: 9416 | G6: มิวเซี่ยม(ลำปาง) | H6: √ | N6: ห้องประชุม | O6: =SUM(F6:F35) -> 382418
A7: =ROW()-ROW(สำนักงาน!$A$6)+1 -> 2 | B7: ผ้าม่านหน้าต่าง 2 ชั้น พร้อมอุปกรณ์ สีครีม | C7: 412-62111-00018 | D7: 434-62-0040 | E7: 30 พ.ย. 61 | F7: 9416 | G7: มิวเซี่ยม(ลำปาง) | H7: √ | N7: ห้องประชุม
A8: =ROW()-ROW(สำนักงาน!$A$6)+1 -> 3 | B8: ผ้าม่านหน้าต่าง 2 ชั้น พร้อมอุปกรณ์ สีครีม | C8: 412-62111-00019 | D8: 434-62-0041 | E8: 30 พ.ย. 61 | F8: 9416 | G8: มิวเซี่ยม(ลำปาง) | H8: √ | N8: ห้องอเนกประสงค์ ชั้น 2
A9: =ROW()-ROW(สำนักงาน!$A$6)+1 -> 4 | B9: ผ้าม่านหน้าต่าง 2 ชั้น พร้อมอุปกรณ์ สีครีม | C9: 412-62111-00020 | D9: 434-62-0042 | E9: 30 พ.ย. 61 | F9: 9416 | G9: มิวเซี่ยม(ลำปาง) | H9: √ | N9: ห้องละหมาด
A10: =ROW()-ROW(สำนักงาน!$A$6)+1 -> 5 | B10: ผ้าม่านหน้าต่าง 2 ชั้น พร้อมอุปกรณ์ สีครีม | C10: 412-62111-00021 | D10: 434-62-0043 | E10: 30 พ.ย. 61 | F10: 9416 | G10: มิวเซี่ยม(ลำปาง) | H10: √ | N10: ห้องสำนักงาน
A11: =ROW()-ROW(สำนักงาน!$A$6)+1 -> 6 | B11: ผ้าม่านหน้าต่าง 2 ชั้น พร้อมอุปกรณ์ สีครีม | C11: 412-62111-00022 | D11: 434-62-0044 | E11: 30 พ.ย. 61 | F11: 9416 | G11: มิวเซี่ยม(ลำปาง) | H11: √ | N11: ห้องสำนักงาน
A12: =ROW()-ROW(สำนักงาน!$A$6)+1 -> 7 | B12: ผ้าม่านหน้าต่าง 2 ชั้น พร้อมอุปกรณ์ สีครีม | C12: 412-62111-00023 | D12: 434-62-0045 | E12: 30 พ.ย. 61 | F12: 9416 | G12: มิวเซี่ยม(ลำปาง) | H12: √ | N12: ห้องสำนักงาน
A13: =ROW()-ROW(สำนักงาน!$A$6)+1 -> 8 | B13: ผ้าม่านหน้าต่าง 2 ชั้น พร้อมอุปกรณ์ สีครีม | C13: 412-62111-00024 | D13: 434-62-0046 | E13: 30 พ.ย. 61 | F13: 9416 | G13: มิวเซี่ยม(ลำปาง) | H13: √ | N13: ห้องเก็บของ
A14: =ROW()-ROW(สำนักงาน!$A$6)+1 -> 9 | B14: ผ้าม่านหน้าต่าง 2 ชั้น พร้อมอุปกรณ์ สีครีม | C14: 412-62111-00025 | D14: 434-62-0047 | E14: 30 พ.ย. 61 | F14: 9416 | G14: มิวเซี่ยม(ลำปาง) | H14: √ | N14: ห้องนิทรรศหมุนเวียนท้องถิ่น
A15: =ROW()-ROW(สำนักงาน!$A$6)+1 -> 10 | B15: ผ้าม่านหน้าต่าง 2 ชั้น พร้อมอุปกรณ์ สีครีม | C15: 412-62111-00026 | D15: 434-62-0048 | E15: 30 พ.ย. 61 | F15: 9416 | G15: มิวเซี่ยม(ลำปาง) | H15: √ | N15: ห้องนิทรรศหมุนเวียนท้องถิ่น
A16: =ROW()-ROW(สำนักงาน!$A$6)+1 -> 11 | B16: ผ้าม่านหน้าต่าง 2 ชั้น พร้อมอุปกรณ์ สีครีม | C16: 412-62111-00027 | D16: 434-62-0049 | E16: 30 พ.ย. 61 | F16: 9416 | G16: มิวเซี่ยม(ลำปาง) | H16: √ | N16: ห้องนิทรรศหมุนเวียนท้องถิ่น
A17: =ROW()-ROW(สำนักงาน!$A$6)+1 -> 12 | B17: ผ้าม่านหน้าต่าง 2 ชั้น พร้อมอุปกรณ์ สีครีม | C17: 412-62111-00028 | D17: 434-62-0050 | E17: 30 พ.ย. 61 | F17: 13482 | G17: มิวเซี่ยม(ลำปาง) | H17: √ | N17: ห้องนิทรรศหมุนเวียนท้องถิ่น
A18: =ROW()-ROW(สำนักงาน!$A$6)+1 -> 13 | B18: ผ้าม่านหน้าต่าง 2 ชั้น พร้อมอุปกรณ์ สีครีม | C18: 412-62111-00029 | D18: 434-62-0051 | E18: 30 พ.ย. 61 | F18: 9416 | G18: มิวเซี่ยม(ลำปาง) | H18: √ | N18: ห้องนิทรรศหมุนเวียนท้องถิ่น
... A35: =ROW()-ROW(สำนักงาน!$A$6)+1 -> 30 | B35: ผ้าม่านหลุยส์ 2 ชั้น พร้อมอุปกรณ์ สีครีม | C35: 412-62111-00046 | D35: 434-62-0068 | E35: 30 พ.ย. 61 | F35: 31993 | G35: มิวเซี่ยม(ลำปาง) | H35: √ | N35: ห้องอ่านหนังสือ TK
A36: =ROW()-ROW(สำนักงาน!$A$6)+1 -> 31 | B36: เครื่องทำน้ำร้อน - น้ำเย็น แบบตู้ตั้งพื้น ยี่ห้อชาร์ป | C36: 412-590208-00002 | D36: 439-59-0083 | E36: 21589 | F36: 5990 | G36: อุทยานการเรียนรู้ | H36: √ | O36: =SUM(F36:F40) -> 48690
A37: =ROW()-ROW(สำนักงาน!$A$6)+1 -> 32 | B37: ตู้ทำน้ำเย็นยี่ห้อ Sharp รุ่น 5B-C10 | C37: 412-600407-00001 | D37: 439-60-0084 | E37: 7 เม.ย. 60 | F37: 4350 | G37: มิวเซี่ยม(ลำปาง) | H37: √ | N37: ห้องเก็บของฝั่ง TK
A38: =ROW()-ROW(สำนักงาน!$A$6)+1 -> 33 | B38: ตู้ทำน้ำเย็นยี่ห้อ Sharp รุ่น 5B-C10 | C38: 412-600407-00002 | D38: 439-60-0085 | E38: 7 เม.ย. 60 | F38: 4350 | G38: มิวเซี่ยม(ลำปาง) | H38: √ | N38: โถงต้อนรับ
A39: =ROW()-ROW(สำนักงาน!$A$6)+1 -> 34 | B39: เครื่องทำน้ำเย็นแบบต่อท่อขนาด 2 ก๊อก ยี่ห้อ Standard | C39: 401-640927-00013 | D39: 439-64-0092 | E39: 9 ก.ย. 64 | F39: 17000 | G39: งานกีฬาและนันทนาการ | H39: √
A40: =ROW()-ROW(สำนักงาน!$A$6)+1 -> 35 | B40: เครื่องทำน้ำเย็นแบบต่อท่อขนาด 2 ก๊อก ยี่ห้อ Standard | C40: 401-640927-00014 | D40: 439-64-0093 | E40: 9 ก.ย. 64 | F40: 17000 | G40: งานกีฬาและนันทนาการ | H40: √
A41: =ROW()-ROW(สำนักงาน!$A$6)+1 -> 36 | B41: เตียงเหล็ก พร้อมที่นอน ขนาด 3.5 ฟุต และหมอนหนุน | C41: 412-640903-00063 | D41: 440-64-0108 | E41: 26 ส.ค. 64 | F41: 5200 | G41: งานกีฬาและนันทนาการ | H41: √ | O41: =SUM(F41:F42) -> 10400
A42: =ROW()-ROW(สำนักงาน!$A$6)+1 -> 37 | B42: เตียงเหล็ก พร้อมที่นอน ขนาด 3.5 ฟุต และหมอนหนุน | C42: 412-640903-00064 | D42: 440-64-0109 | E42: 26 ส.ค. 64 | F42: 5200 | G42: งานกีฬาและนันทนาการ | H42: √
A43: =ROW()-ROW(สำนักงาน!$A$6)+1 -> 38 | B43: เครื่องตัดหญ้าแบบข้ออ่อน | C43: 412-660830-00001 | D43: 441-66-0183 | E43: 28 ต.ค. 65 | F43: 10600 | G43: อุทยานการเรียนรู้ LK | H43: √
A44: =ROW()-ROW(สำนักงาน!$A$6)+1 -> 39 | B44: เครื่องกรองน้ำสแตนเลส | C44: 412-660905-00001 | D44: 701-66-0032 | E44: 24322 | F44: 3900 | G44: อาคารศูนย์กีฬาและนันทนาการ | H44: √ | O44: =SUM(F44:F45) -> 7800
A45: =ROW()-ROW(สำนักงาน!$A$6)+1 -> 40 | B45: เครื่องกรองน้ำสแตนเลส | C45: 412-660905-00002 | D45: 701-66-0033 | E45: 24322 | F45: 3900 | G45: อาคารศูนย์กีฬาและนันทนาการ | H45: √
A46: =ROW()-ROW(สำนักงาน!$A$6)+1 -> 41 | B46: ตู้เย็น | C46: 412-370127-00001 | D46: 703-37-0020 | E46: 13548 | F46: 5778 | G46: สำนักการศึกษา ชั้น 3 | H46: √ | N46: หน้าห้องน้ำ ชั้น 3 | O46: =SUM(F46:F50) -> 40648
A47: =ROW()-ROW(สำนักงาน!$A$6)+1 -> 42 | B47: ตู้เย็นแบบ 2 ประตู 7 คิว ยี่ห้อ Sumsung รุ่น RT20FGRVDSA | C47: 412-590208-00003 | D47: 703-59-0042 | E47: 8 ก.พ. 59 | F47: 9300 | G47: อุทยานการเรียนรู้ | H47: √
A48: =ROW()-ROW(สำนักงาน!$A$6)+1 -> 43 | B48: ตู้เย็นแบบ 2 ประตู ยี่ห้อ SHAPP | C48: 412-610220-00001 | D48: 703-61-0044 | E48: 20 ก.พ. 61 | F48: 8290 | G48: มิวเซี่ยม(ลำปาง) | H48: √ | N48: ห้องอเนกประสงค์ ชั้น 2
A49: =ROW()-ROW(สำนักงาน!$A$6)+1 -> 44 | B49: ตู้เย็นแบบ 2 ประตู ยี่ห้อ SHAPP | C49: 412-610220-00002 | D49: 703-61-0045 | E49: 20 ก.พ. 61 | F49: 8290 | G49: มิวเซี่ยม(ลำปาง) | H49: √ | N49: ห้องพยาบาล
A50: =ROW()-ROW(สำนักงาน!$A$6)+1 -> 45 | B50: ตู้เย็น 2 ประตู ขนาด 9.2 คิว ยี่ห้อ LG | C50: 412-640903-00062 | D50: 703-64-0046 | E50: 19 ส.ค. 64 | F50: 8990 | G50: งานกีฬาและนันทนาการ | H50: √
B51: จำนวน 45 รายการ | F51: =SUBTOTAL(9,F6:F50) -> 500556

Sheet โฆษณา
A1: ทะเบียนรายงานผลการตรวจนับครุภัณฑ์ของสำนักการศึกษา ประจำปี 2567
A2: ณ วันที่ 30 กันยายน 2567 (เทศบัญญัติ)
A3: ครุภัณฑ์โฆษณาและเผยแพร่
A4: ลำดับที่ | B4: รายการ | C4: หมายเลข E-laas | D4: หมายเลขครุภัณฑ์ | E4: วัน เดือน ปี ที่ได้มา | F4: ราคาที่ได้มา | G4: สถานที่ใช้งาน | H4: สภาพครุภัณฑ์
H5: ใช้ได้ | I5: ชำรุด | J5: เสื่อมสภาพ | K5: สูญหาย | L5: เก็บไว้นาน | M5: หมดความจำเป็น | N5: หมายเหตุ
A6: =ROW()-ROW(สำนักงาน!$A$6)+1 -> 1 | B6: จอรับภาพขนาด 100 นิ้ว ชนิดมอเตอร์ | C6: 404-530131-00003 | D6: 444-53-0001 | E6: 31 ม.ค. 53 | F6: 9500 | G6: หอสมุดประชาชน | H6: √ | O6: / | P6: =SUM(โฆษณา!F6:F11) -> 2273793.6
A7: =ROW()-ROW(สำนักงาน!$A$6)+1 -> 2 | B7: จอรับภาพ | C7: 404-580202-00001 | D7: 444-58-0024 | E7: 21218 | F7: 9999.15 | G7: หอสมุดประชาชน | H7: √ | O7: /
A8: =ROW()-ROW(สำนักงาน!$A$6)+1 -> 3 | B8: จอรับภาพชนิดมอเตอร์ไฟฟ้า ยี่ห้อ Screenboy | C8: 404-610305-00002 | D8: 444-61-0029 | E8: 5 มี.ค. 61 | F8: 19500 | G8: มิวเซี่ยม(ลำปาง) | H8: √ | N8: ห้องประชุมเล็ก | O8: /
A9: =ROW()-ROW(สำนักงาน!$A$6)+1 -> 4 | B9: ป้าย IndoorFullcolorScreen แบบ FrontService ชนิดหลอด | C9: 404-631012-00007 | D9: 444-63-0062 | E9: 30 มี.ค. 63 | F9: 1070000 | G9: งานพิพิธภัณฑ์(มิวเซียม) | H9: √ | N9: โถงต้อนรับ | O9: /
A10: =ROW()-ROW(สำนักงาน!$A$6)+1 -> 5 | B10: จอมอนิเตอร์ LED ขนาด 82" อุปกรณ์สับสัญญาณเสียง ชนิด 4 ช่อง งานเดินระบบสายสัญญาณภาพใช้สาย | C10: 404-631012-00008 | D10: 444-63-0061 | E10: 30 มี.ค. 63 | F10: 102559.5 | G10: งานพิพิธภัณฑ์(มิวเซียม) | H10: √ | N10: ห้องสื่อมัลติมีเดีย | O10: /
A11: =ROW()-ROW(สำนักงาน!$A$6)+1 -> 6 | B11: จอแสดงภาพ LED FULL COLOR DISPLAY | C11: 404-650815-00001 | D11: 444-65-0065 | E11: 6 ต.ค. 64 | F11: 1062235 | G11: มิวเซียมลำปาง | H11: √ | N11: ห้องมัลติมีเดีย | O11: /
A12: =ROW()-ROW(สำนักงาน!$A$6)+1 -> 7 | B12: โปรเจ็คเตอร์ | C12: 404-580202-00002 | D12: 446-58-0014 | E12: 21218 | F12: 44779.5 | G12: หอสมุดประชาชน | H12: √ | O12: /
A13: =ROW()-ROW(สำนักงาน!$A$6)+1 -> 8 | B13: เครื่องเล่นสื่อโสต สำหรับชุดเจ้าเมืองและตำนานนางสุชาดา | C13: 404-581125-00001 | D13: 448-59-0015 | E13: 21514 | F13: 30000 | G13: พิพิธภัณฑ์หอปูมละกอน | H13: √ | P13: แก้รหัส เป็น 448
A14: =ROW()-ROW(สำนักงาน!$A$6)+1 -> 9 | B14: จอสัมผัส ขนาด 27 นิ้ว ชุดมัลติมีเดียสำหรับลงคำปฎิญาณ | C14: 404-581125-00002 | D14: 448-59-0016 | E14: 21514 | F14: 59990 | G14: พิพิธภัณฑ์หอปูมละกอน | H14: √ | P14: แก้รหัส เป็น 448
A15: =ROW()-ROW(สำนักงาน!$A$6)+1 -> 10 | B15: เครื่องเล่นสื่อโสต สำหรับชุดมัลติเดียลงคำปฎิญาณ | C15: 404-581125-00003 | D15: 448-59-0017 | E15: 21514 | F15: 30000 | G15: พิพิธภัณฑ์หอปูมละกอน | H15: √ | O15: =SUM(F12:F15) -> 164769.5 | P15: แก้รหัส เป็น 448
A16: =ROW()-ROW(สำนักงาน!$A$6)+1 -> 11 | B16: เครื่องมัลติมีเดียโปรเจคเตอร์ ยี่ห้อ EPSON รุ่น EB-X04 | C16: 404-610305-00001 | D16: 447-61-0032 | E16: 5 มี.ค. 61 | F16: 23900 | G16: มิวเซี่ยม(ลำปาง) | H16: √ | N16: ห้องประชุมเล็ก | O16: /
A17: =ROW()-ROW(สำนักงาน!$A$6)+1 -> 12 | B17: เครื่องฉายภาพ Projector ยี่ห้อ NEC รุ่น PA-703 ความละเอียด 6200 ansilumens พร้อมเลนส์ พร้อมขาแขวน Projector | C17: 404-640903-00001 | D17: 447-64-0042 | E17: 29 ต.ค. 63 | F17: 108400 | G17: มิวเซียมลำปาง | H17: √ | N17: ห้องนิทรรศการถาวร ชั้น 2 | O17: =SUM(F16:F26) -> 636000
A18: =ROW()-ROW(สำนักงาน!$A$6)+1 -> 13 | B18: เครื่องฉายภาพ Projector ยี่ห้อ NEC รุ่น PA-703 ความละเอียด 6200 ansilumens พร้อมเลนส์ พร้อมขาแขวน Projector | C18: 404-640903-00002 | D18: 447-64-0043 | E18: 29 ต.ค. 63 | F18: 89800 | G18: มิวเซียมลำปาง | H18: √ | N18: ห้องนิทรรศการถาวร ชั้น 2 | O18: /
A19: =ROW()-ROW(สำนักงาน!$A$6)+1 -> 14 | B19: เครื่องฉายภาพ Projector ยี่ห้อ NEC รุ่น PA-703 ความละเอียด 6200 ansilumens พร้อมเลนส์ พร้อมขาแขวน Projector | C19: 404-640903-00003 | D19: 447-64-0044 | E19: 29 ต.ค. 63 | F19: 89800 | G19: มิวเซียมลำปาง | H19: √ | N19: ห้องนิทรรศการถาวร ชั้น 2 | O19: /
A20: =ROW()-ROW(สำนักงาน!$A$6)+1 -> 15 | B20: เครื่องฉายภาพ Projector ยี่ห้อ NEC รุ่น PA-703 ความละเอียด 6200 ansilumens พร้อมเลนส์ พร้อมขาแขวน Projector | C20: 404-640903-00004 | D20: 447-64-0045 | E20: 29 ต.ค. 63 | F20: 89800 | G20: มิวเซียมลำปาง | H20: √ | N20: ห้องนิทรรศการถาวร ชั้น 2 | O20: /
A21: =ROW()-ROW(สำนักงาน!$A$6)+1 -> 16 | B21: เครื่องฉายภาพ Projector ยี่ห้อ NEC รุ่น PA-703 ความละเอียด 6200 ansilumens พร้อมเลนส์ พร้อมขาแขวน Projector | C21: 404-640903-00005 | D21: 447-64-0046 | E21: 29 ต.ค. 63 | F21: 89800 | G21: มิวเซียมลำปาง | H21: √ | N21: ห้องนิทรรศการถาวร ชั้น 2 | O21: /
A22: =ROW()-ROW(สำนักงาน!$A$6)+1 -> 17 | B22: เครื่องมัลติมีเดียโปรเจคเตอร์ ระบบ XGA ขนาด 4000 ANSI Lumens | C22: 404-660830-00002 | D22: 447-66-0053 | E22: 24124 | F22: 28900 | G22: มิวเซียม ห้องนิทรรศการถาวร | H22: √ | N22: ห้องนิทรรศการถาวร ชั้น 2 | O22: /
A23: =ROW()-ROW(สำนักงาน!$A$6)+1 -> 18 | B23: เครื่องมัลติมีเดียโปรเจคเตอร์ ระบบ XGA ขนาด 4000 ANSI Lumens | C23: 404-660830-00003 | D23: 447-66-0054 | E23: 24124 | F23: 28900 | G23: มิวเซียม ห้องนิทรรศการถาวร | H23: √ | N23: ห้องนิทรรศการถาวร ชั้น 2 | O23: /
A24: =ROW()-ROW(สำนักงาน!$A$6)+1 -> 19 | B24: เครื่องมัลติมีเดียโปรเจคเตอร์ ระบบ XGA ขนาด 4000 ANSI Lumens | C24: 404-660830-00004 | D24: 447-66-0055 | E24: 24124 | F24: 28900 | G24: มิวเซียม ห้องนิทรรศการถาวร | H24: √ | N24: ห้องนิทรรศการถาวร ชั้น 2 | O24: /
A25: =ROW()-ROW(สำนักงาน!$A$6)+1 -> 20 | B25: เครื่องมัลติมีเดียโปรเจคเตอร์ ระบบ XGA ขนาด 4000 ANSI Lumens | C25: 404-660830-00005 | D25: 447-66-0056 | E25: 24124 | F25: 28900 | G25: มิวเซียม ห้องนิทรรศการถาวร | H25: √ | N25: ห้องนิทรรศการถาวร ชั้น 2 | O25: /
A26: =ROW()-ROW(สำนักงาน!$A$6)+1 -> 21 | B26: เครื่องมัลติมีเดียโปรเจคเตอร์ ระบบ XGA ขนาด 4000 ANSI Lumens | C26: 404-660830-00006 | D26: 447-66-0057 | E26: 24124 | F26: 28900 | G26: มิวเซียม ห้องนิทรรศการถาวร | H26: √ | N26: ห้องนิทรรศการถาวร ชั้น 2 | O26: /
A27: =ROW()-ROW(สำนักงาน!$A$6)+1 -> 22 | B27: เครื่องควบคุมลำดับ ชุดมัลติมีเดียสำหรับลงคำปฎิญาณ | C27: 404-581125-00004 | D27: 448-59-0018 | E27: 25 พ.ย. 58 | F27: 37000 | G27: พิพิธภัณฑ์หอปูมละกอน | J27: √
A28: =ROW()-ROW(ไฟฟ้าและวิทยุ!$A$6)+1 -> 23 | B28: กล้องถ่ายภาพนิ่งระบบดิจิตอล ยี่ห้อ CANNON | C28: 404-600515-00001 | D28: 452-60-0081 | E28: 15 พ.ค. 60 | F28: 8990 | G28: มิวเซี่ยม(ลำปาง) | H28: √ | O28: /
A29: =ROW()-ROW(สำนักงาน!$A$6)+1 -> 24 | B29: LCD TV 40 นิ้ว ระดับความละเอียดจอภาพ ไม่น้อยกว่า 1366 (ชุดเจ้าแม่สุชาดา) | C29: 404-540119-00001 | D29: 456-54-0002 | E29: 19 ม.ค. 54 | F29: 37383 | G29: พิพิธภัณฑ์หอปูมละกอน | H29: √
A30: =ROW()-ROW(สำนักงาน!$A$6)+1 -> 25 | B30: Support For Lcd TV 40 นิ้ว ขาประกอบ (ชุดเจ้าแม่สุชาดา) | C30: 404-540119-00002 | D30: 456-54-0001 | E30: 19 ม.ค. 54 | F30: 6500 | G30: พิพิธภัณฑ์หอปูมละกอน | H30: √
A31: =ROW()-ROW(สำนักงาน!$A$6)+1 -> 26 | B31: โทรทัศน์ LCD ยี่ห้อ SAMSUNG UA40EH5000 | C31: 404-560808-00001 | D31: 456-56-0043 | E31: 20675 | F31: 15000 | G31: สำนักการศึกษา ชั้น 2 | H31: √ | N31: ผอ.สำนัก | O31: /
A32: =ROW()-ROW(สำนักงาน!$A$6)+1 -> 27 | B32: ทีวี LED ขนาด 55 นิ้ว ยี่ห้อ SHARP รุ่น L4-55LE460X | C32: 404-590223-00002 | D32: 456-59-0074 | E32: 23 ก.พ. 59 | F32: 34500 | G32: อุทยานการเรียนรู้ | H32: √ | O32: /
A33: =ROW()-ROW(สำนักงาน!$A$6)+1 -> 28 | B33: LED TV ชนิดพิเศษ ขนาด 49 นิ้ว พร้อมกรอบจอ พร้อมขาแขวน LED TV | C33: 404-640903-00006 | D33: 456-64-0109 | E33: 29 ต.ค. 63 | F33: 62500 | G33: มิวเซียมลำปาง | H33: √ | N33: ห้องนิทรรศการถาวร ชั้น 2 | O33: /
A34: =ROW()-ROW(สำนักงาน!$A$6)+1 -> 29 | B34: LED TV ชนิดพิเศษ ขนาด 49 นิ้ว พร้อมกรอบจอ พร้อมขาแขวน LED TV | C34: 404-640903-00007 | D34: 456-64-0110 | E34: 29 ต.ค. 63 | F34: 62500 | G34: มิวเซียมลำปาง | H34: √ | N34: ห้องนิทรรศการถาวร ชั้น 2 | O34: /
A35: =ROW()-ROW(สำนักงาน!$A$6)+1 -> 30 | B35: LED TV ชนิดพิเศษ ขนาด 49 นิ้ว พร้อมกรอบจอ พร้อมขาแขวน LED TV | C35: 404-640903-00008 | D35: 456-64-0111 | E35: 29 ต.ค. 63 | F35: 62500 | G35: มิวเซียมลำปาง | H35: √ | N35: ห้องนิทรรศการถาวร ชั้น 2 | O35: /
A36: =ROW()-ROW(สำนักงาน!$A$6)+1 -> 31 | B36: LED TV ชนิดพิเศษ ขนาด 49 นิ้ว พร้อมกรอบจอ พร้อมขาแขวน LED TV | C36: 404-640903-00009 | D36: 456-64-0112 | E36: 29 ต.ค. 63 | F36: 62500 | G36: มิวเซียมลำปาง | H36: √ | N36: ห้องนิทรรศการถาวร ชั้น 2 | O36: /
A37: =ROW()-ROW(สำนักงาน!$A$6)+1 -> 32 | B37: LED TV ชนิดพิเศษ ขนาด 32 นิ้ว ยี่ห้อ SAMSUNG | C37: 404-640903-00010 | D37: 456-64-0113 | E37: 29 ต.ค. 63 | F37: 32100 | G37: มิวเซียมลำปาง | H37: √ | N37: ห้องนิทรรศการถาวร ชั้น 2 | O37: /
A38: =ROW()-ROW(สำนักงาน!$A$6)+1 -> 33 | B38: LED TV ชนิดพิเศษ ขนาด 32 นิ้ว ยี่ห้อ SAMSUNG | C38: 404-640903-00011 | D38: 456-64-0114 | E38: 29 ต.ค. 63 | F38: 32100 | G38: มิวเซียมลำปาง | H38: √ | N38: ห้องนิทรรศการถาวร ชั้น 2 | O38: /
A39: =ROW()-ROW(สำนักงาน!$A$6)+1 -> 34 | B39: LED TV ชนิดพิเศษ ขนาด 32 นิ้ว ยี่ห้อ SAMSUNG | C39: 404-640903-00012 | D39: 456-64-0115 | E39: 29 ต.ค. 63 | F39: 32100 | G39: มิวเซียมลำปาง | H39: √ | N39: ห้องนิทรรศการถาวร ชั้น 2 | O39: /
A40: =ROW()-ROW(สำนักงาน!$A$6)+1 -> 35 | B40: LED TV ชนิดพิเศษ ขนาด 32 นิ้ว ยี่ห้อ SAMSUNG | C40: 404-640903-00013 | D40: 456-64-0116 | E40: 29 ต.ค. 63 | F40: 32100 | G40: มิวเซียมลำปาง | H40: √ | N40: ห้องนิทรรศการถาวร ชั้น 2 | O40: /
...

Sheet การเกษตร
A1: ทะเบียนรายงานผลการตรวจนับครุภัณฑ์ของสำนักการศึกษา ประจำปี 2567
A2: ณ วันที่ 30 กันยายน 2567 (เทศบัญญัติ)
A3: ครุภัณฑ์การเกษตร
A4: ลำดับที่ | B4: รายการ | C4: หมายเลข E-laas | D4: หมายเลขครุภัณฑ์ | E4: วัน เดือน ปี ที่ได้มา | F4: ราคาที่ได้มา | G4: สถานที่ใช้งาน | H4: สภาพครุภัณฑ์
H5: ใช้ได้ | I5: ชำรุด | J5: เสื่อมสภาพ | K5: สูญหาย | L5: เก็บไว้นาน | M5: หมดความจำเป็น | N5: หมายเหตุ
A6: =ROW()-ROW($A$6)+1 -> 1 | B6: ปั๊มน้ำอัตโนมัติแบบแรงดันคงที่ กำลังไฟ 350 วัตต์ สีเหลือง ยี่ห้อ MITSUBISHI ELECTRIC | C6: 405-62111-00011 | D6: 055-62-0239 | E6: 14 ส.ค. 62 | F6: 7650 | G6: สำนักการศึกษา | H6: √ | N6: ถ่ายเอกสารพี่โฉม
A7: =ROW()-ROW($A$6)+1 -> 2 | B7: ปั๊มน้ำอัตโนมัติระบบอินเวอร์เตอร์แรงไฟฟ้า 380 โวล์ สีเหลือง ยี่ห้อ MITSUBISHI ELECTRIC | C7: 405-62111-00012 | D7: 055-62-0240 | E7: 14 ส.ค. 62 | F7: 28500 | G7: สำนักการศึกษา | H7: √ | N7: ชั้นลอย ดาดฟ้า
A8: =ROW()-ROW($A$6)+1 -> 3 | B8: เครื่องปั๊มน้ำอัตโนมัติ ขนาด 350 วัตต์ แรงดันคงที่ | C8: 405-640927-00001 | D8: 055-64-0265 | E8: 30 มิ.ย. 64 | F8: 10500 | G8: งานกีฬาและนันทนาการ | H8: √
B9: จำนวน 3 รายการ | F9: =SUBTOTAL(9,F6:F8) -> 46650

Sheet วิทยาศาสตร์
A1: ทะเบียนรายงานผลการตรวจนับครุภัณฑ์ของสำนักการศึกษา ประจำปี 2567
A2: ณ วันที่ 30 กันยายน 2567 (เทศบัญญัติ)
A3: ครุภัณฑ์วิทยาศาสตร์หรือการแพทย์
A4: ลำดับที่ | B4: รายการ | C4: หมายเลข E-laas | D4: หมายเลขครุภัณฑ์ | E4: วัน เดือน ปี ที่ได้มา | F4: ราคาที่ได้มา | G4: สถานที่ใช้งาน | H4: สภาพครุภัณฑ์
H5: ใช้ได้ | I5: ชำรุด | J5: เสื่อมสภาพ | K5: สูญหาย | L5: เก็บไว้นาน | M5: หมดความจำเป็น | N5: หมายเหตุ
A6: =ROW()-ROW(สำนักงาน!$A$6)+1 -> 1 | B6: ตู้สำหรับล้างและเก็บอุปกรณ์ทางการแพทย์โครงสร้าง เป็นไม้ปาติเกิ้ลบอร์ด หน้าตู้ปิดด้วยลามิเนตพร้อมอ่างน้ำ และก็อกขนาดลึก 0.60 ยาว 1.20 สูง 0.80 ซม. | C6: 409-631012-00003 | D6: 239-63-0016 | E6: 30 มี.ค. 63 | F6: 19260 | G6: งานพิพิธภัณฑ์ (มิวเซียม) | H6: √ | N6: ห้องพยาบาล | O6: =SUM(F6:F7) -> 42800
A7: =ROW()-ROW(สำนักงาน!$A$6)+1 -> 2 | B7: ตู้ทรงสูงสำหรับเก็บอุปกรณ์ทางวิทยาศาสตร์โครงสร้าง เป็นไม้ปาติเกิ้ลบอร์ด ขนาดลึก 0.50 ยาว 1.20 สูง 2 ม. | C7: 409-631012-00004 | D7: 239-63-0017 | E7: 30 มี.ค. 63 | F7: 23540 | G7: งานพิพิธภัณฑ์ (มิวเซียม) | H7: √ | N7: ห้องพยาบาล
A8: =ROW()-ROW(สำนักงาน!$A$6)+1 -> 3 | B8: เตียงผู้ป่วยไกร์มือหมุน เตียงขนาด 0.80x1.85 ม. สูง 0.55 พร้อมที่นอนกันน้ำ 4 ตอน หนา 8 ซม. ผ้าปูที่นอนพร้อมปลอกหมอน-หมอนใยมะพร้าวหุ้มหนังเทียม | C8: 409-631012-00002 | D8: 282-63-0032 | E8: 30 มี.ค. 63 | F8: 19260 | G8: งานพิพิธภัณฑ์ (มิวเซียม) | H8: √ | N8: ห้องพยาบาล
A9: =ROW()-ROW(สำนักงาน!$A$6)+1 -> 4 | B9: เครื่องวัดอุณหภูมิ ยี่ห้อ CIG LL,MO-T260 | C9: 409-631012-00012 | D9: 298-63-0015 | E9: 9 มิ.ย. 63 | F9: 2500 | G9: พิพิธภัณฑ์หอปูมละกอน | J9: √ | O9: =SUM(F9:F17) -> 21110 | P9: อยู่ในสำนักงาน
A10: =ROW()-ROW(สำนักงาน!$A$6)+1 -> 5 | B10: เครื่องวัดอุณหภูมิ ยี่ห้อ HOCO,YQ6 | C10: 409-631012-00019 | D10: 298-63-0022 | E10: 9 มิ.ย. 63 | F10: 2500 | G10: งานศาสนา | H10: √ | N10: รับโอนจากกองสาธารณสุข
A11: =ROW()-ROW(สำนักงาน!$A$6)+1 -> 6 | B11: เครื่องวัดอุณหภูมิ ยี่ห้อ HOCO,YQ6 | C11: 409-631012-00020 | D11: 298-63-0023 | E11: 9 มิ.ย. 63 | F11: 2500 | G11: งานศาสนา | H11: √ | N11: รับโอนจากกองสาธารณสุข
A12: =ROW()-ROW(สำนักงาน!$A$6)+1 -> 7 | B12: เครื่องวัดอุณหภูมิ ยี่ห้อ HOCO,YQ6 | C12: 409-631012-00025 | D12: 298-63-0028 | E12: 9 มิ.ย. 63 | F12: 2500 | G12: ธุรการสำนักศึกษา | I12: √ | N12: รับโอนจากกองสาธารณสุข
A13: =ROW()-ROW(สำนักงาน!$A$6)+1 -> 8 | B13: เครื่องวัดอุณหภูมิ ยี่ห้อ DT-8806C | C13: 409-631012-00011 | D13: 298-63-0014 | E13: 9 มิ.ย. 63 | F13: 2500 | G13: มิวเซียมลำปาง | H13: √ | N13: ห้องพยาบาล
A14: =ROW()-ROW(สำนักงาน!$A$6)+1 -> 9 | B14: เครื่องวัดอุณหภูมิ ยี่ห้อ HOCO,FD-01MD | C14: 409-631012-00014 | D14: 298-63-0017 | E14: 9 มิ.ย. 63 | F14: 2500 | G14: มิวเซียมลำปาง | H14: √ | N14: ห้องพยาบาล
A15: =ROW()-ROW(สำนักงาน!$A$6)+1 -> 10 | B15: เครื่องวัดอุณหภูมิระบบอินฟาเรดทางหน้าผาก ใช้งานกลางแจ้งและในอาคาร พร้อมขาตั้ง ADAPTER | C15: 409-640903-00019 | D15: 298-64-0056 | E15: 29 ม.ค. 64 | F15: 2195 | G15: มิวเซียมลำปาง | H15: √ | N15: ห้องพยาบาล
A16: =ROW()-ROW(สำนักงาน!$A$6)+1 -> 11 | B16: เครื่องวัดอุณหภูมิระบบอินฟาเรดทางหน้าผาก ใช้งานกลางแจ้งและในอาคาร พร้อมขาตั้ง ADAPTER | C16: 409-640903-00020 | D16: 298-64-0057 | E16: 29 ม.ค. 64 | F16: 2195 | G16: อุทยานการเรียนรู้ | H16: √
A17: =ROW()-ROW(สำนักงาน!$A$6)+1 -> 12 | B17: เครื่องวัดอุณหภูมิอินฟราเรดชนิดมีขาตั้ง ใช้พลังงานไฟฟ้า พร้อม Adapter ใช้ได้ทั้งภายนอกและภายในอาคาร | C17: 409-650815-00006 | D17: 298-65-0076 | E17: 23741 | F17: 1720 | G17: สำนักการศึกษา ชั้น 2 | H17: √ | N17: กนกวรรณ | O17: รับโอนจากกองสาธารณสุข
B18: จำนวน 12 รายการ | F18: =SUBTOTAL(9,F6:F17) -> 83170

Sheet ก่อสร้าง
A1: ทะเบียนรายงานผลการตรวจนับครุภัณฑ์ของสำนักการศึกษา ประจำปี 2567
A2: ณ วันที่ 30 กันยายน 2567 (เทศบัญญัติ)
A3: ครุภัณฑ์ก่อสร้าง
A4: ลำดับที่ | B4: รายการ | C4: หมายเลข E-laas | D4: หมายเลขครุภัณฑ์ | E4: วัน เดือน ปี ที่ได้มา | F4: ราคาที่ได้มา | G4: สถานที่ใช้งาน | H4: สภาพครุภัณฑ์
H5: ใช้ได้ | I5: ชำรุด | J5: เสื่อมสภาพ | K5: สูญหาย | L5: เก็บไว้นาน | M5: หมดความจำเป็น | N5: หมายเหตุ
A6: =ROW()-ROW(สำนักงาน!$A$6)+1 -> 1 | B6: รถเข็นสามล้อโครงเหล็ก | C6: 407-660903-00001 | D6: 005-66-0134 | E6: 21 ต.ค. 65 | F6: 3600 | G6: อุทยานการเรียนรู้ | H6: √
B7: จำนวน 1 รายการ | F7: =SUBTOTAL(9,F6) -> 3600

Sheet กีฬา
A1: ทะเบียนรายงานผลการตรวจนับครุภัณฑ์ของสำนักการศึกษา ประจำปี 2567
A2: ณ วันที่ 30 กันยายน 2567 (เทศบัญญัติ)
A3: ครุภัณฑ์กีฬา
A4: ลำดับที่ | B4: รายการ | C4: หมายเลข E-laas | D4: หมายเลขครุภัณฑ์ | E4: วัน เดือน ปี ที่ได้มา | F4: ราคาที่ได้มา | G4: สถานที่ใช้งาน | H4: สภาพครุภัณฑ์
H5: ใช้ได้ | I5: ชำรุด | J5: เสื่อมสภาพ | K5: สูญหาย | L5: เก็บไว้นาน | M5: หมดความจำเป็น | N5: หมายเหตุ
A6: =ROW()-ROW($A$6)+1 -> 1 | B6: แป้นบาสเกตบอล | C6: 413-640903-00001 | D6: 806-64-0101 | E6: 6 ม.ค. 63 | F6: 10593 | G6: งานกีฬาและนันทนาการ | I6: √ | N6: 806-63-0101 | O6: =F6+F7+F281 -> 39186
A7: =ROW()-ROW($A$6)+1 -> 2 | B7: แป้นบาสเกตบอล | C7: 413-640903-00002 | D7: 806-64-0102 | E7: 6 ม.ค. 63 | F7: 10593 | G7: งานกีฬาและนันทนาการ | I7: √ | N7: 806-63-0102
A8: =ROW()-ROW($A$6)+1 -> 3 | B8: โต๊ะเทเบิลเทนนิส พร้อมเสาตาข่าย รุ่น DNS-T-1223 25 MM | C8: 413-640903-00008 | D8: 803-64-0001 | E8: 31 ส.ค. 64 | F8: 15000 | G8: งานกีฬาและนันทนาการ | H8: √ | O8: =SUM(F8:F11) -> 60000
A9: =ROW()-ROW($A$6)+1 -> 4 | B9: โต๊ะเทเบิลเทนนิส พร้อมเสาตาข่าย รุ่น DNS-T-1223 25 MM | C9: 413-640903-00009 | D9: 803-64-0002 | E9: 31 ส.ค. 64 | F9: 15000 | G9: งานกีฬาและนันทนาการ | H9: √
A10: =ROW()-ROW($A$6)+1 -> 5 | B10: โต๊ะเทเบิลเทนนิส พร้อมเสาตาข่าย รุ่น DNS-T-1223 25 MM | C10: 413-640903-00010 | D10: 803-64-0003 | E10: 31 ส.ค. 64 | F10: 15000 | G10: งานกีฬาและนันทนาการ | H10: √
A11: =ROW()-ROW($A$6)+1 -> 6 | B11: โต๊ะเทเบิลเทนนิส พร้อมเสาตาข่าย รุ่น DNS-T-1223 25 MM | C11: 413-640903-00011 | D11: 803-64-0004 | E11: 31 ส.ค. 64 | F11: 15000 | G11: งานกีฬาและนันทนาการ | H11: √
A12: =ROW()-ROW($A$6)+1 -> 7 | B12: ประตูฟุตซอล 2 ประตู 3x2 เมตร พร้อมตาข่าย | C12: 413-640903-00012 | D12: 812-64-0001 | E12: 31 ส.ค. 64 | F12: 17000 | G12: งานกีฬาและนันทนาการ | H12: √
A13: =ROW()-ROW($A$6)+1 -> 8 | B13: เก้าอี้กรรมการกีฬา | C13: 413-640903-00013 | D13: 813-64-0001 | E13: 31 ส.ค. 64 | F13: 9500 | G13: งานกีฬาและนันทนาการ | H13: √ | O13: =F13+F14 -> 26500
A14: =ROW()-ROW($A$6)+1 -> 9 | B14: เก้าอี้กรรมการกีฬาวอลเลย์บอล | C14: 413-640927-00001 | D14: 813-64-0002 | E14: 14 ก.ย. 64 | F14: 17000 | G14: งานกีฬาและนันทนาการ | H14: √
A15: =ROW()-ROW($A$6)+1 -> 10 | B15: เครื่องเล่นสนามกลางแจ้ง ขนาดไม่น้อยกว่า 250x520x180 ซม. | C15: 413-650815-00001 | D15: 808-65-0020 | E15: 24 ธ.ค. 64 | F15: 677800 | G15: งานกีฬาและนันทนาการ | H15: √ | N15: สวนเขลางค์ | O15: =SUM(F15:F30) -> 5593400
A16: =ROW()-ROW($A$6)+1 -> 11 | B16: เครื่องเล่นสนามกลางแจ้ง ขนาดไม่น้อยกว่า 250x520x180 ซม. | C16: 413-650815-00002 | D16: 808-65-0021 | E16: 24 ธ.ค. 64 | F16: 677800 | G16: งานกีฬาและนันทนาการ | H16: √ | N16: สวนภิรมย์ธาร
A17: =ROW()-ROW($A$6)+1 -> 12 | B17: เครื่องเล่นสนามกลางแจ้ง ขนาดไม่น้อยกว่า 250x520x180 ซม. | C17: 413-650815-00003 | D17: 808-65-0022 | E17: 24 ธ.ค. 64 | F17: 677800 | G17: งานกีฬาและนันทนาการ | H17: √ | N17: สวนเวียงละกอน
A18: =ROW()-ROW($A$6)+1 -> 13 | B18: เครื่องเล่นชิงช้า 6 ที่นั่ง ขนาดไม่น้อยกว่า 120x180x180 ซม. | C18: 413-650815-00004 | D18: 808-65-0023 | E18: 24 ธ.ค. 64 | F18: 282600 | G18: งานกีฬาและนันทนาการ | H18: √ | N18: สวนเขลางค์
